Workbook

Sheet サマリー
A1: 売上ダッシュボード（週・月・半期・年間）
A3: ■ 入力項目（黄色セルのみ編集）
A4: 集計対象年 | B4: 2025
A5: 年度開始月 | B5: 11
A6: 本日の日付（自動） | B6: =TODAY() -> 46320
A7: 個人 週予算（1人あたり） | B7: 250000
A8: 個人 月予算（1人あたり） | B8: 1000000
A9: JET業務 単価（1件） | B9: 25000
A10: JONE200 単価 | B10: 7241
A11: JONE100 単価（未定の場合は0） | B11: 4379
A12: YTS 単価（1件） | B12: 30000
A14: 年度開始日 | B14: =DATE(B4,B5,1) -> 45962
A15: チーム週予算（個人×2） | B15: =B7*2 -> 500000
A16: チーム月予算（個人×2） | B16: =B8*2 -> 2000000
A17: 半期予算（月予算×6・参考） | B17: =B16*6 -> 12000000
A18: 年間予算（月予算×12・参考） | B18: =B16*12 -> 24000000
A20: 現在の週番号 | B20: =INT((B6-(B14-WEEKDAY(B14,2)+1))/7)+1 -> 52
A21: 現在の月番号 | B21: =(YEAR(B6)-YEAR(B14))*12+MONTH(B6)-MONTH(B14)+1 -> 12
A22: 現在の半期区分 | B22: =IF(B21<=6,"上半期","下半期") -> 下半期
A24: ■ スタッフ別進捗（今週・今月）
A25: 対象 | B25: 予算 | C25: 実績 | D25: 達成率 | E25: 残り必要額
A26: 小原（今週） | B26: =B7 -> 250000 | C26: =INDEX(週次集計!D3:D56,$B$20) -> 258259 | D26: =IFERROR(C26/B26,0) -> 1.033036 | E26: =MAX(B26-C26,0) -> 0
A27: 前園（今週） | B27: =B7 -> 250000 | C27: =INDEX(週次集計!E3:E56,$B$20) -> 198722 | D27: =IFERROR(C27/B27,0) -> 0.794888 | E27: =MAX(B27-C27,0) -> 51278
A28: 小原（今月） | B28: =B8 -> 1000000 | C28: =INDEX(月次集計!D3:D15,$B$21) -> 939646 | D28: =IFERROR(C28/B28,0) -> 0.939646 | E28: =MAX(B28-C28,0) -> 60354
A29: 前園（今月） | B29: =B8 -> 1000000 | C29: =INDEX(月次集計!E3:E15,$B$21) -> 581922 | D29: =IFERROR(C29/B29,0) -> 0.581922 | E29: =MAX(B29-C29,0) -> 418078
A32: ■ 優先度ダッシュボード（1日あたり必要額が大きいほど優先）
A33: 対象 | B33: 予算 | C33: 実績 | D33: 残り必要額 | E33: 期限 | F33: 残り日数 | G33: 1日あたり必要額 | H33: 優先度
A34: 小原（今週） | B34: =B7 -> 250000 | C34: =INDEX(週次集計!D3:D56,$B$20) -> 258259 | D34: =MAX(B34-C34,0) -> 0 | E34: =INDEX(週次集計!C3:C56,$B$20) -> 46320 | F34: =MAX(E34-$B$6+1,1) -> 1 | G34: =IFERROR(D34/F34,0) -> 0 | H34: =RANK(G34,$G$34:$G$41) -> 7
A35: 前園（今週） | B35: =B7 -> 250000 | C35: =INDEX(週次集計!E3:E56,$B$20) -> 198722 | D35: =MAX(B35-C35,0) -> 51278 | E35: =INDEX(週次集計!C3:C56,$B$20) -> 46320 | F35: =MAX(E35-$B$6+1,1) -> 1 | G35: =IFERROR(D35/F35,0) -> 51278 | H35: =RANK(G35,$G$34:$G$41) -> 4
A36: チーム（今週） | B36: =B15 -> 500000 | C36: =INDEX(週次集計!F3:F56,$B$20) -> 456981 | D36: =MAX(B36-C36,0) -> 43019 | E36: =INDEX(週次集計!C3:C56,$B$20) -> 46320 | F36: =MAX(E36-$B$6+1,1) -> 1 | G36: =IFERROR(D36/F36,0) -> 43019 | H36: =RANK(G36,$G$34:$G$41) -> 5
A37: 小原（今月） | B37: =B8 -> 1000000 | C37: =INDEX(月次集計!D3:D15,$B$21) -> 939646 | D37: =MAX(B37-C37,0) -> 60354 | E37: =INDEX(月次集計!C3:C15,$B$21) -> 46326 | F37: =MAX(E37-$B$6+1,1) -> 7 | G37: =IFERROR(D37/F37,0) -> 8622 | H37: =RANK(G37,$G$34:$G$41) -> 6
A38: 前園（今月） | B38: =B8 -> 1000000 | C38: =INDEX(月次集計!E3:E15,$B$21) -> 581922 | D38: =MAX(B38-C38,0) -> 418078 | E38: =INDEX(月次集計!C3:C15,$B$21) -> 46326 | F38: =MAX(E38-$B$6+1,1) -> 7 | G38: =IFERROR(D38/F38,0) -> 59725.429 | H38: =RANK(G38,$G$34:$G$41) -> 3
A39: チーム（今月） | B39: =B16 -> 2000000 | C39: =INDEX(月次集計!F3:F15,$B$21) -> 1521568 | D39: =MAX(B39-C39,0) -> 478432 | E39: =INDEX(月次集計!C3:C15,$B$21) -> 46326 | F39: =MAX(E39-$B$6+1,1) -> 7 | G39: =IFERROR(D39/F39,0) -> 68347.429 | H39: =RANK(G39,$G$34:$G$41) -> 2
A40: チーム（今半期） | B40: =B17 -> 12000000 | C40: =INDEX(半期年間集計!F3:F5,IF($B$22="上半期",1,2)) -> 12259597 | D40: =MAX(B40-C40,0) -> 0 | E40: =INDEX(半期年間集計!C3:C5,IF($B$22="上半期",1,2)) -> 46326 | F40: =MAX(E40-$B$6+1,1) -> 7 | G40: =IFERROR(D40/F40,0) -> 0 | H40: =RANK(G40,$G$34:$G$41) -> 7
A41: チーム（今年） | B41: =B18 -> 24000000 | C41: =INDEX(半期年間集計!F3:F5,3) -> 12259597 | D41: =MAX(B41-C41,0) -> 11740403 | E41: =INDEX(半期年間集計!C3:C5,3) -> 46326 | F41: =MAX(E41-$B$6+1,1) -> 7 | G41: =IFERROR(D41/F41,0) -> 1677200.4 | H41: =RANK(G41,$G$34:$G$41) -> 1
A43: ※「優先度」の1位は、残り必要額を残り日数で割った『1日あたり必要額』が最も大きい項目です。そこから手をつけるのが最も効率的です。
A44: ※ 個人の月予算は1人100万円、チームは200万円（個人×2）です。半期・年間はチーム月予算からの参考換算値です。
A45: ※ 週は月曜始まり。月をまたぐ週も前後月の実績を含めて集計します。
A47: ■ 今月 カテゴリー別内訳（実績のみ）
A48: ="（"&TEXT(INDEX(月次集計!$B$3:$B$15,$B$21),"m月")&"分）" -> （10月分）
...

Sheet 受注ログ
A1: 受注ログ（1行＝1受注。Aに日にちだけ入力→日付は自動。C〜Hで日別・本日の状況がすぐ分かります）
B2: 小原週残 | C2: 前園週残 | D2: チーム週実績 | E2: チーム週残 | F2: 小原本日 | G2: 前園本日 | H2: チーム本日
B3: =MAX(サマリー!$B$7-INDEX(週次集計!$D$3:$D$56,サマリー!$B$20),0) -> 0 | C3: =MAX(サマリー!$B$7-INDEX(週次集計!$E$3:$E$56,サマリー!$B$20),0) -> 51278 | D3: =INDEX(週次集計!$F$3:$F$56,サマリー!$B$20) -> 456981 | E3: =MAX(サマリー!$B$15-INDEX(週次集計!$F$3:$F$56,サマリー!$B$20),0) -> 43019 | F3: =SUMIFS($C$6:$C$99901,$B$6:$B$99901,TODAY()) -> 0 | G3: =SUMIFS($D$6:$D$99901,$B$6:$B$99901,TODAY()) -> 0 | H3: =F3+G3 -> 0
I4: 小原 | S4: 前園
A5: 日 | B5: 日付 | C5: 小原計 | D5: 前園計 | E5: 合計 | I5: 松山本店 | J5: 持込 | K5: RYTS | L5: 大洲店 | M5: 西予店 | N5: 宇和島店 | O5: サテライト | P5: JET業務 (件数) | Q5: JONE (100/200) | R5: YTS (件数) | S5: 松山本店 | T5: 持込 | U5: RYTS | V5: 新居浜店 | W5: サテライト | X5: JET業務 (件数) | Y5: JONE (100/200) | Z5: YTS (件数)
A6: 1 | B6: 46143 | C6: =I6+J6+K6+L6+M6+N6+O6+IF(P6="",0,P6*サマリー!$B$9)+IF(Q6="",0,IF(Q6=200,サマリー!$B$10,IF(Q6=100,サマリー!$B$11,0)))+IF(R6="",0,R6*サマリー!$B$12) -> 31760 | D6: =S6+T6+U6+V6+W6+IF(X6="",0,X6*サマリー!$B$9)+IF(Y6="",0,IF(Y6=200,サマリー!$B$10,IF(Y6=100,サマリー!$B$11,0)))+IF(Z6="",0,Z6*サマリー!$B$12) -> 8055 | E6: =C6+D6 -> 39815 | I6: 24519 | Q6: 200 | V6: 8055
A7: 1 | B7: =IF(A7="",B6,IF(A7<DAY(B6),DATE(YEAR(B6),MONTH(B6)+1,A7),DATE(YEAR(B6),MONTH(B6),A7))) -> 46143 | C7: =I7+J7+K7+L7+M7+N7+O7+IF(P7="",0,P7*サマリー!$B$9)+IF(Q7="",0,IF(Q7=200,サマリー!$B$10,IF(Q7=100,サマリー!$B$11,0)))+IF(R7="",0,R7*サマリー!$B$12) -> 100500 | D7: =S7+T7+U7+V7+W7+IF(X7="",0,X7*サマリー!$B$9)+IF(Y7="",0,IF(Y7=200,サマリー!$B$10,IF(Y7=100,サマリー!$B$11,0)))+IF(Z7="",0,Z7*サマリー!$B$12) -> 0 | E7: =C7+D7 -> 100500 | J7: 100500
A8: 2 | B8: =IF(A8="",B7,IF(A8<DAY(B7),DATE(YEAR(B7),MONTH(B7)+1,A8),DATE(YEAR(B7),MONTH(B7),A8))) -> 46144 | C8: =I8+J8+K8+L8+M8+N8+O8+IF(P8="",0,P8*サマリー!$B$9)+IF(Q8="",0,IF(Q8=200,サマリー!$B$10,IF(Q8=100,サマリー!$B$11,0)))+IF(R8="",0,R8*サマリー!$B$12) -> 50560 | D8: =S8+T8+U8+V8+W8+IF(X8="",0,X8*サマリー!$B$9)+IF(Y8="",0,IF(Y8=200,サマリー!$B$10,IF(Y8=100,サマリー!$B$11,0)))+IF(Z8="",0,Z8*サマリー!$B$12) -> 0 | E8: =C8+D8 -> 50560 | I8: 24519 | L8: 18800 | Q8: 200
A9: 2 | B9: =IF(A9="",B8,IF(A9<DAY(B8),DATE(YEAR(B8),MONTH(B8)+1,A9),DATE(YEAR(B8),MONTH(B8),A9))) -> 46144 | C9: =I9+J9+K9+L9+M9+N9+O9+IF(P9="",0,P9*サマリー!$B$9)+IF(Q9="",0,IF(Q9=200,サマリー!$B$10,IF(Q9=100,サマリー!$B$11,0)))+IF(R9="",0,R9*サマリー!$B$12) -> 0 | D9: =S9+T9+U9+V9+W9+IF(X9="",0,X9*サマリー!$B$9)+IF(Y9="",0,IF(Y9=200,サマリー!$B$10,IF(Y9=100,サマリー!$B$11,0)))+IF(Z9="",0,Z9*サマリー!$B$12) -> 22000 | E9: =C9+D9 -> 22000 | T9: 22000
A10: 2 | B10: =IF(A10="",B9,IF(A10<DAY(B9),DATE(YEAR(B9),MONTH(B9)+1,A10),DATE(YEAR(B9),MONTH(B9),A10))) -> 46144 | C10: =I10+J10+K10+L10+M10+N10+O10+IF(P10="",0,P10*サマリー!$B$9)+IF(Q10="",0,IF(Q10=200,サマリー!$B$10,IF(Q10=100,サマリー!$B$11,0)))+IF(R10="",0,R10*サマリー!$B$12) -> 9910 | D10: =S10+T10+U10+V10+W10+IF(X10="",0,X10*サマリー!$B$9)+IF(Y10="",0,IF(Y10=200,サマリー!$B$10,IF(Y10=100,サマリー!$B$11,0)))+IF(Z10="",0,Z10*サマリー!$B$12) -> 0 | E10: =C10+D10 -> 9910 | J10: 9910
A11: 3 | B11: =IF(A11="",B10,IF(A11<DAY(B10),DATE(YEAR(B10),MONTH(B10)+1,A11),DATE(YEAR(B10),MONTH(B10),A11))) -> 46145 | C11: =I11+J11+K11+L11+M11+N11+O11+IF(P11="",0,P11*サマリー!$B$9)+IF(Q11="",0,IF(Q11=200,サマリー!$B$10,IF(Q11=100,サマリー!$B$11,0)))+IF(R11="",0,R11*サマリー!$B$12) -> 2200 | D11: =S11+T11+U11+V11+W11+IF(X11="",0,X11*サマリー!$B$9)+IF(Y11="",0,IF(Y11=200,サマリー!$B$10,IF(Y11=100,サマリー!$B$11,0)))+IF(Z11="",0,Z11*サマリー!$B$12) -> 0 | E11: =C11+D11 -> 2200 | J11: 2200
B12: =IF(A12="",B11,IF(A12<DAY(B11),DATE(YEAR(B11),MONTH(B11)+1,A12),DATE(YEAR(B11),MONTH(B11),A12))) -> 46145 | C12: =I12+J12+K12+L12+M12+N12+O12+IF(P12="",0,P12*サマリー!$B$9)+IF(Q12="",0,IF(Q12=200,サマリー!$B$10,IF(Q12=100,サマリー!$B$11,0)))+IF(R12="",0,R12*サマリー!$B$12) -> 0 | D12: =S12+T12+U12+V12+W12+IF(X12="",0,X12*サマリー!$B$9)+IF(Y12="",0,IF(Y12=200,サマリー!$B$10,IF(Y12=100,サマリー!$B$11,0)))+IF(Z12="",0,Z12*サマリー!$B$12) -> 22440 | E12: =C12+D12 -> 22440 | S12: 22440
B13: =IF(A13="",B12,IF(A13<DAY(B12),DATE(YEAR(B12),MONTH(B12)+1,A13),DATE(YEAR(B12),MONTH(B12),A13))) -> 46145 | C13: =I13+J13+K13+L13+M13+N13+O13+IF(P13="",0,P13*サマリー!$B$9)+IF(Q13="",0,IF(Q13=200,サマリー!$B$10,IF(Q13=100,サマリー!$B$11,0)))+IF(R13="",0,R13*サマリー!$B$12) -> 31760 | D13: =S13+T13+U13+V13+W13+IF(X13="",0,X13*サマリー!$B$9)+IF(Y13="",0,IF(Y13=200,サマリー!$B$10,IF(Y13=100,サマリー!$B$11,0)))+IF(Z13="",0,Z13*サマリー!$B$12) -> 0 | E13: =C13+D13 -> 31760 | I13: 24519 | Q13: 200
B14: =IF(A14="",B13,IF(A14<DAY(B13),DATE(YEAR(B13),MONTH(B13)+1,A14),DATE(YEAR(B13),MONTH(B13),A14))) -> 46145 | C14: =I14+J14+K14+L14+M14+N14+O14+IF(P14="",0,P14*サマリー!$B$9)+IF(Q14="",0,IF(Q14=200,サマリー!$B$10,IF(Q14=100,サマリー!$B$11,0)))+IF(R14="",0,R14*サマリー!$B$12) -> 31760 | D14: =S14+T14+U14+V14+W14+IF(X14="",0,X14*サマリー!$B$9)+IF(Y14="",0,IF(Y14=200,サマリー!$B$10,IF(Y14=100,サマリー!$B$11,0)))+IF(Z14="",0,Z14*サマリー!$B$12) -> 0 | E14: =C14+D14 -> 31760 | I14: 24519 | Q14: 200
B15: =IF(A15="",B14,IF(A15<DAY(B14),DATE(YEAR(B14),MONTH(B14)+1,A15),DATE(YEAR(B14),MONTH(B14),A15))) -> 46145 | C15: =I15+J15+K15+L15+M15+N15+O15+IF(P15="",0,P15*サマリー!$B$9)+IF(Q15="",0,IF(Q15=200,サマリー!$B$10,IF(Q15=100,サマリー!$B$11,0)))+IF(R15="",0,R15*サマリー!$B$12) -> 0 | D15: =S15+T15+U15+V15+W15+IF(X15="",0,X15*サマリー!$B$9)+IF(Y15="",0,IF(Y15=200,サマリー!$B$10,IF(Y15=100,サマリー!$B$11,0)))+IF(Z15="",0,Z15*サマリー!$B$12) -> 39960 | E15: =C15+D15 -> 39960 | S15: 32719 | Y15: 200
B16: =IF(A16="",B15,IF(A16<DAY(B15),DATE(YEAR(B15),MONTH(B15)+1,A16),DATE(YEAR(B15),MONTH(B15),A16))) -> 46145 | C16: =I16+J16+K16+L16+M16+N16+O16+IF(P16="",0,P16*サマリー!$B$9)+IF(Q16="",0,IF(Q16=200,サマリー!$B$10,IF(Q16=100,サマリー!$B$11,0)))+IF(R16="",0,R16*サマリー!$B$12) -> 46560 | D16: =S16+T16+U16+V16+W16+IF(X16="",0,X16*サマリー!$B$9)+IF(Y16="",0,IF(Y16=200,サマリー!$B$10,IF(Y16=100,サマリー!$B$11,0)))+IF(Z16="",0,Z16*サマリー!$B$12) -> 0 | E16: =C16+D16 -> 46560 | I16: 39319 | Q16: 200
B17: =IF(A17="",B16,IF(A17<DAY(B16),DATE(YEAR(B16),MONTH(B16)+1,A17),DATE(YEAR(B16),MONTH(B16),A17))) -> 46145 | C17: =I17+J17+K17+L17+M17+N17+O17+IF(P17="",0,P17*サマリー!$B$9)+IF(Q17="",0,IF(Q17=200,サマリー!$B$10,IF(Q17=100,サマリー!$B$11,0)))+IF(R17="",0,R17*サマリー!$B$12) -> 46560 | D17: =S17+T17+U17+V17+W17+IF(X17="",0,X17*サマリー!$B$9)+IF(Y17="",0,IF(Y17=200,サマリー!$B$10,IF(Y17=100,サマリー!$B$11,0)))+IF(Z17="",0,Z17*サマリー!$B$12) -> 0 | E17: =C17+D17 -> 46560 | I17: 39319 | Q17: 200
B18: =IF(A18="",B17,IF(A18<DAY(B17),DATE(YEAR(B17),MONTH(B17)+1,A18),DATE(YEAR(B17),MONTH(B17),A18))) -> 46145 | C18: =I18+J18+K18+L18+M18+N18+O18+IF(P18="",0,P18*サマリー!$B$9)+IF(Q18="",0,IF(Q18=200,サマリー!$B$10,IF(Q18=100,サマリー!$B$11,0)))+IF(R18="",0,R18*サマリー!$B$12) -> 0 | D18: =S18+T18+U18+V18+W18+IF(X18="",0,X18*サマリー!$B$9)+IF(Y18="",0,IF(Y18=200,サマリー!$B$10,IF(Y18=100,サマリー!$B$11,0)))+IF(Z18="",0,Z18*サマリー!$B$12) -> 6400 | E18: =C18+D18 -> 6400 | T18: 6400
A19: 4 | B19: =IF(A19="",B18,IF(A19<DAY(B18),DATE(YEAR(B18),MONTH(B18)+1,A19),DATE(YEAR(B18),MONTH(B18),A19))) -> 46146 | C19: =I19+J19+K19+L19+M19+N19+O19+IF(P19="",0,P19*サマリー!$B$9)+IF(Q19="",0,IF(Q19=200,サマリー!$B$10,IF(Q19=100,サマリー!$B$11,0)))+IF(R19="",0,R19*サマリー!$B$12) -> 0 | D19: =S19+T19+U19+V19+W19+IF(X19="",0,X19*サマリー!$B$9)+IF(Y19="",0,IF(Y19=200,サマリー!$B$10,IF(Y19=100,サマリー!$B$11,0)))+IF(Z19="",0,Z19*サマリー!$B$12) -> 4955 | E19: =C19+D19 -> 4955 | T19: 4955
B20: =IF(A20="",B19,IF(A20<DAY(B19),DATE(YEAR(B19),MONTH(B19)+1,A20),DATE(YEAR(B19),MONTH(B19),A20))) -> 46146 | C20: =I20+J20+K20+L20+M20+N20+O20+IF(P20="",0,P20*サマリー!$B$9)+IF(Q20="",0,IF(Q20=200,サマリー!$B$10,IF(Q20=100,サマリー!$B$11,0)))+IF(R20="",0,R20*サマリー!$B$12) -> 0 | D20: =S20+T20+U20+V20+W20+IF(X20="",0,X20*サマリー!$B$9)+IF(Y20="",0,IF(Y20=200,サマリー!$B$10,IF(Y20=100,サマリー!$B$11,0)))+IF(Z20="",0,Z20*サマリー!$B$12) -> 13201 | E20: =C20+D20 -> 13201 | T20: 13201
B21: =IF(A21="",B20,IF(A21<DAY(B20),DATE(YEAR(B20),MONTH(B20)+1,A21),DATE(YEAR(B20),MONTH(B20),A21))) -> 46146 | C21: =I21+J21+K21+L21+M21+N21+O21+IF(P21="",0,P21*サマリー!$B$9)+IF(Q21="",0,IF(Q21=200,サマリー!$B$10,IF(Q21=100,サマリー!$B$11,0)))+IF(R21="",0,R21*サマリー!$B$12) -> 0 | D21: =S21+T21+U21+V21+W21+IF(X21="",0,X21*サマリー!$B$9)+IF(Y21="",0,IF(Y21=200,サマリー!$B$10,IF(Y21=100,サマリー!$B$11,0)))+IF(Z21="",0,Z21*サマリー!$B$12) -> 31557 | E21: =C21+D21 -> 31557 | S21: 31557
B22: =IF(A22="",B21,IF(A22<DAY(B21),DATE(YEAR(B21),MONTH(B21)+1,A22),DATE(YEAR(B21),MONTH(B21),A22))) -> 46146 | C22: =I22+J22+K22+L22+M22+N22+O22+IF(P22="",0,P22*サマリー!$B$9)+IF(Q22="",0,IF(Q22=200,サマリー!$B$10,IF(Q22=100,サマリー!$B$11,0)))+IF(R22="",0,R22*サマリー!$B$12) -> 0 | D22: =S22+T22+U22+V22+W22+IF(X22="",0,X22*サマリー!$B$9)+IF(Y22="",0,IF(Y22=200,サマリー!$B$10,IF(Y22=100,サマリー!$B$11,0)))+IF(Z22="",0,Z22*サマリー!$B$12) -> 21000 | E22: =C22+D22 -> 21000 | S22: 21000
A23: 5 | B23: =IF(A23="",B22,IF(A23<DAY(B22),DATE(YEAR(B22),MONTH(B22)+1,A23),DATE(YEAR(B22),MONTH(B22),A23))) -> 46147 | C23: =I23+J23+K23+L23+M23+N23+O23+IF(P23="",0,P23*サマリー!$B$9)+IF(Q23="",0,IF(Q23=200,サマリー!$B$10,IF(Q23=100,サマリー!$B$11,0)))+IF(R23="",0,R23*サマリー!$B$12) -> 3955 | D23: =S23+T23+U23+V23+W23+IF(X23="",0,X23*サマリー!$B$9)+IF(Y23="",0,IF(Y23=200,サマリー!$B$10,IF(Y23=100,サマリー!$B$11,0)))+IF(Z23="",0,Z23*サマリー!$B$12) -> 0 | E23: =C23+D23 -> 3955 | J23: 3955
B24: =IF(A24="",B23,IF(A24<DAY(B23),DATE(YEAR(B23),MONTH(B23)+1,A24),DATE(YEAR(B23),MONTH(B23),A24))) -> 46147 | C24: =I24+J24+K24+L24+M24+N24+O24+IF(P24="",0,P24*サマリー!$B$9)+IF(Q24="",0,IF(Q24=200,サマリー!$B$10,IF(Q24=100,サマリー!$B$11,0)))+IF(R24="",0,R24*サマリー!$B$12) -> 44079 | D24: =S24+T24+U24+V24+W24+IF(X24="",0,X24*サマリー!$B$9)+IF(Y24="",0,IF(Y24=200,サマリー!$B$10,IF(Y24=100,サマリー!$B$11,0)))+IF(Z24="",0,Z24*サマリー!$B$12) -> 0 | E24: =C24+D24 -> 44079 | I24: 36838 | Q24: 200
B25: =IF(A25="",B24,IF(A25<DAY(B24),DATE(YEAR(B24),MONTH(B24)+1,A25),DATE(YEAR(B24),MONTH(B24),A25))) -> 46147 | C25: =I25+J25+K25+L25+M25+N25+O25+IF(P25="",0,P25*サマリー!$B$9)+IF(Q25="",0,IF(Q25=200,サマリー!$B$10,IF(Q25=100,サマリー!$B$11,0)))+IF(R25="",0,R25*サマリー!$B$12) -> 1655 | D25: =S25+T25+U25+V25+W25+IF(X25="",0,X25*サマリー!$B$9)+IF(Y25="",0,IF(Y25=200,サマリー!$B$10,IF(Y25=100,サマリー!$B$11,0)))+IF(Z25="",0,Z25*サマリー!$B$12) -> 0 | E25: =C25+D25 -> 1655 | J25: 1655
A26: 6 | B26: =IF(A26="",B25,IF(A26<DAY(B25),DATE(YEAR(B25),MONTH(B25)+1,A26),DATE(YEAR(B25),MONTH(B25),A26))) -> 46148 | C26: =I26+J26+K26+L26+M26+N26+O26+IF(P26="",0,P26*サマリー!$B$9)+IF(Q26="",0,IF(Q26=200,サマリー!$B$10,IF(Q26=100,サマリー!$B$11,0)))+IF(R26="",0,R26*サマリー!$B$12) -> 31760 | D26: =S26+T26+U26+V26+W26+IF(X26="",0,X26*サマリー!$B$9)+IF(Y26="",0,IF(Y26=200,サマリー!$B$10,IF(Y26=100,サマリー!$B$11,0)))+IF(Z26="",0,Z26*サマリー!$B$12) -> 0 | E26: =C26+D26 -> 31760 | I26: 24519 | Q26: 200
B27: =IF(A27="",B26,IF(A27<DAY(B26),DATE(YEAR(B26),MONTH(B26)+1,A27),DATE(YEAR(B26),MONTH(B26),A27))) -> 46148 | C27: =I27+J27+K27+L27+M27+N27+O27+IF(P27="",0,P27*サマリー!$B$9)+IF(Q27="",0,IF(Q27=200,サマリー!$B$10,IF(Q27=100,サマリー!$B$11,0)))+IF(R27="",0,R27*サマリー!$B$12) -> 0 | D27: =S27+T27+U27+V27+W27+IF(X27="",0,X27*サマリー!$B$9)+IF(Y27="",0,IF(Y27=200,サマリー!$B$10,IF(Y27=100,サマリー!$B$11,0)))+IF(Z27="",0,Z27*サマリー!$B$12) -> 68489 | E27: =C27+D27 -> 68489 | S27: 61248 | Y27: 200
B28: =IF(A28="",B27,IF(A28<DAY(B27),DATE(YEAR(B27),MONTH(B27)+1,A28),DATE(YEAR(B27),MONTH(B27),A28))) -> 46148 | C28: =I28+J28+K28+L28+M28+N28+O28+IF(P28="",0,P28*サマリー!$B$9)+IF(Q28="",0,IF(Q28=200,サマリー!$B$10,IF(Q28=100,サマリー!$B$11,0)))+IF(R28="",0,R28*サマリー!$B$12) -> 18791 | D28: =S28+T28+U28+V28+W28+IF(X28="",0,X28*サマリー!$B$9)+IF(Y28="",0,IF(Y28=200,サマリー!$B$10,IF(Y28=100,サマリー!$B$11,0)))+IF(Z28="",0,Z28*サマリー!$B$12) -> 0 | E28: =C28+D28 -> 18791 | J28: 18791
A29: 7 | B29: =IF(A29="",B28,IF(A29<DAY(B28),DATE(YEAR(B28),MONTH(B28)+1,A29),DATE(YEAR(B28),MONTH(B28),A29))) -> 46149 | C29: =I29+J29+K29+L29+M29+N29+O29+IF(P29="",0,P29*サマリー!$B$9)+IF(Q29="",0,IF(Q29=200,サマリー!$B$10,IF(Q29=100,サマリー!$B$11,0)))+IF(R29="",0,R29*サマリー!$B$12) -> 28319 | D29: =S29+T29+U29+V29+W29+IF(X29="",0,X29*サマリー!$B$9)+IF(Y29="",0,IF(Y29=200,サマリー!$B$10,IF(Y29=100,サマリー!$B$11,0)))+IF(Z29="",0,Z29*サマリー!$B$12) -> 8600 | E29: =C29+D29 -> 36919 | L29: 3319 | P29: 1 | T29: 8600
B30: =IF(A30="",B29,IF(A30<DAY(B29),DATE(YEAR(B29),MONTH(B29)+1,A30),DATE(YEAR(B29),MONTH(B29),A30))) -> 46149 | C30: =I30+J30+K30+L30+M30+N30+O30+IF(P30="",0,P30*サマリー!$B$9)+IF(Q30="",0,IF(Q30=200,サマリー!$B$10,IF(Q30=100,サマリー!$B$11,0)))+IF(R30="",0,R30*サマリー!$B$12) -> 0 | D30: =S30+T30+U30+V30+W30+IF(X30="",0,X30*サマリー!$B$9)+IF(Y30="",0,IF(Y30=200,サマリー!$B$10,IF(Y30=100,サマリー!$B$11,0)))+IF(Z30="",0,Z30*サマリー!$B$12) -> 39960 | E30: =C30+D30 -> 39960 | S30: 32719 | Y30: 200
B31: =IF(A31="",B30,IF(A31<DAY(B30),DATE(YEAR(B30),MONTH(B30)+1,A31),DATE(YEAR(B30),MONTH(B30),A31))) -> 46149 | C31: =I31+J31+K31+L31+M31+N31+O31+IF(P31="",0,P31*サマリー!$B$9)+IF(Q31="",0,IF(Q31=200,サマリー!$B$10,IF(Q31=100,サマリー!$B$11,0)))+IF(R31="",0,R31*サマリー!$B$12) -> 0 | D31: =S31+T31+U31+V31+W31+IF(X31="",0,X31*サマリー!$B$9)+IF(Y31="",0,IF(Y31=200,サマリー!$B$10,IF(Y31=100,サマリー!$B$11,0)))+IF(Z31="",0,Z31*サマリー!$B$12) -> 35279 | E31: =C31+D31 -> 35279 | S31: 28038 | Y31: 200
A32: 8 | B32: =IF(A32="",B31,IF(A32<DAY(B31),DATE(YEAR(B31),MONTH(B31)+1,A32),DATE(YEAR(B31),MONTH(B31),A32))) -> 46150 | C32: =I32+J32+K32+L32+M32+N32+O32+IF(P32="",0,P32*サマリー!$B$9)+IF(Q32="",0,IF(Q32=200,サマリー!$B$10,IF(Q32=100,サマリー!$B$11,0)))+IF(R32="",0,R32*サマリー!$B$12) -> 0 | D32: =S32+T32+U32+V32+W32+IF(X32="",0,X32*サマリー!$B$9)+IF(Y32="",0,IF(Y32=200,サマリー!$B$10,IF(Y32=100,サマリー!$B$11,0)))+IF(Z32="",0,Z32*サマリー!$B$12) -> 12800 | E32: =C32+D32 -> 12800 | I32: 0 | V32: 12800
A33: 9 | B33: =IF(A33="",B32,IF(A33<DAY(B32),DATE(YEAR(B32),MONTH(B32)+1,A33),DATE(YEAR(B32),MONTH(B32),A33))) -> 46151 | C33: =I33+J33+K33+L33+M33+N33+O33+IF(P33="",0,P33*サマリー!$B$9)+IF(Q33="",0,IF(Q33=200,サマリー!$B$10,IF(Q33=100,サマリー!$B$11,0)))+IF(R33="",0,R33*サマリー!$B$12) -> 4755 | D33: =S33+T33+U33+V33+W33+IF(X33="",0,X33*サマリー!$B$9)+IF(Y33="",0,IF(Y33=200,サマリー!$B$10,IF(Y33=100,サマリー!$B$11,0)))+IF(Z33="",0,Z33*サマリー!$B$12) -> 0 | E33: =C33+D33 -> 4755 | J33: 4755
A34: 10 | B34: =IF(A34="",B33,IF(A34<DAY(B33),DATE(YEAR(B33),MONTH(B33)+1,A34),DATE(YEAR(B33),MONTH(B33),A34))) -> 46152 | C34: =I34+J34+K34+L34+M34+N34+O34+IF(P34="",0,P34*サマリー!$B$9)+IF(Q34="",0,IF(Q34=200,サマリー!$B$10,IF(Q34=100,サマリー!$B$11,0)))+IF(R34="",0,R34*サマリー!$B$12) -> 0 | D34: =S34+T34+U34+V34+W34+IF(X34="",0,X34*サマリー!$B$9)+IF(Y34="",0,IF(Y34=200,サマリー!$B$10,IF(Y34=100,サマリー!$B$11,0)))+IF(Z34="",0,Z34*サマリー!$B$12) -> 533336 | E34: =C34+D34 -> 533336 | S34: 506638 | V34: 22319 | Y34: 100
B35: =IF(A35="",B34,IF(A35<DAY(B34),DATE(YEAR(B34),MONTH(B34)+1,A35),DATE(YEAR(B34),MONTH(B34),A35))) -> 46152 | C35: =I35+J35+K35+L35+M35+N35+O35+IF(P35="",0,P35*サマリー!$B$9)+IF(Q35="",0,IF(Q35=200,サマリー!$B$10,IF(Q35=100,サマリー!$B$11,0)))+IF(R35="",0,R35*サマリー!$B$12) -> 31760 | D35: =S35+T35+U35+V35+W35+IF(X35="",0,X35*サマリー!$B$9)+IF(Y35="",0,IF(Y35=200,サマリー!$B$10,IF(Y35=100,サマリー!$B$11,0)))+IF(Z35="",0,Z35*サマリー!$B$12) -> 0 | E35: =C35+D35 -> 31760 | I35: 24519 | Q35: 200
B36: =IF(A36="",B35,IF(A36<DAY(B35),DATE(YEAR(B35),MONTH(B35)+1,A36),DATE(YEAR(B35),MONTH(B35),A36))) -> 46152 | C36: =I36+J36+K36+L36+M36+N36+O36+IF(P36="",0,P36*サマリー!$B$9)+IF(Q36="",0,IF(Q36=200,サマリー!$B$10,IF(Q36=100,サマリー!$B$11,0)))+IF(R36="",0,R36*サマリー!$B$12) -> 0 | D36: =S36+T36+U36+V36+W36+IF(X36="",0,X36*サマリー!$B$9)+IF(Y36="",0,IF(Y36=200,サマリー!$B$10,IF(Y36=100,サマリー!$B$11,0)))+IF(Z36="",0,Z36*サマリー!$B$12) -> 2200 | E36: =C36+D36 -> 2200 | T36: 2200
B37: =IF(A37="",B36,IF(A37<DAY(B36),DATE(YEAR(B36),MONTH(B36)+1,A37),DATE(YEAR(B36),MONTH(B36),A37))) -> 46152 | C37: =I37+J37+K37+L37+M37+N37+O37+IF(P37="",0,P37*サマリー!$B$9)+IF(Q37="",0,IF(Q37=200,サマリー!$B$10,IF(Q37=100,サマリー!$B$11,0)))+IF(R37="",0,R37*サマリー!$B$12) -> 0 | D37: =S37+T37+U37+V37+W37+IF(X37="",0,X37*サマリー!$B$9)+IF(Y37="",0,IF(Y37=200,サマリー!$B$10,IF(Y37=100,サマリー!$B$11,0)))+IF(Z37="",0,Z37*サマリー!$B$12) -> 4200 | E37: =C37+D37 -> 4200 | T37: 4200
B38: =IF(A38="",B37,IF(A38<DAY(B37),DATE(YEAR(B37),MONTH(B37)+1,A38),DATE(YEAR(B37),MONTH(B37),A38))) -> 46152 | C38: =I38+J38+K38+L38+M38+N38+O38+IF(P38="",0,P38*サマリー!$B$9)+IF(Q38="",0,IF(Q38=200,サマリー!$B$10,IF(Q38=100,サマリー!$B$11,0)))+IF(R38="",0,R38*サマリー!$B$12) -> 0 | D38: =S38+T38+U38+V38+W38+IF(X38="",0,X38*サマリー!$B$9)+IF(Y38="",0,IF(Y38=200,サマリー!$B$10,IF(Y38=100,サマリー!$B$11,0)))+IF(Z38="",0,Z38*サマリー!$B$12) -> 4400 | E38: =C38+D38 -> 4400 | T38: 4400
B39: =IF(A39="",B38,IF(A39<DAY(B38),DATE(YEAR(B38),MONTH(B38)+1,A39),DATE(YEAR(B38),MONTH(B38),A39))) -> 46152 | C39: =I39+J39+K39+L39+M39+N39+O39+IF(P39="",0,P39*サマリー!$B$9)+IF(Q39="",0,IF(Q39=200,サマリー!$B$10,IF(Q39=100,サマリー!$B$11,0)))+IF(R39="",0,R39*サマリー!$B$12) -> 0 | D39: =S39+T39+U39+V39+W39+IF(X39="",0,X39*サマリー!$B$9)+IF(Y39="",0,IF(Y39=200,サマリー!$B$10,IF(Y39=100,サマリー!$B$11,0)))+IF(Z39="",0,Z39*サマリー!$B$12) -> 32853 | E39: =C39+D39 -> 32853 | S39: 28474 | Y39: 100
A40: 11 | B40: =IF(A40="",B39,IF(A40<DAY(B39),DATE(YEAR(B39),MONTH(B39)+1,A40),DATE(YEAR(B39),MONTH(B39),A40))) -> 46153 | C40: =I40+J40+K40+L40+M40+N40+O40+IF(P40="",0,P40*サマリー!$B$9)+IF(Q40="",0,IF(Q40=200,サマリー!$B$10,IF(Q40=100,サマリー!$B$11,0)))+IF(R40="",0,R40*サマリー!$B$12) -> 0 | D40: =S40+T40+U40+V40+W40+IF(X40="",0,X40*サマリー!$B$9)+IF(Y40="",0,IF(Y40=200,サマリー!$B$10,IF(Y40=100,サマリー!$B$11,0)))+IF(Z40="",0,Z40*サマリー!$B$12) -> 59255 | E40: =C40+D40 -> 59255 | S40: 40357 | V40: 14519 | Y40: 100
...

Sheet 週次集計
A1: 週次集計（月曜始まり・月またぎ含む）
A2: 週番号 | B2: 開始日 | C2: 終了日 | D2: 小原実績 | E2: 前園実績 | F2: チーム計 | G2: チーム週予算 | H2: 差異 | I2: 達成率 | J2: 小原達成率 | K2: 前園達成率
A3: 1 | B3: =サマリー!$B$14-WEEKDAY(サマリー!$B$14,2)+1+(1-1)*7 -> 45957 | C3: =B3+6 -> 45963 | D3: =SUMIFS(受注ログ!$C$6:$C$99901,受注ログ!$B$6:$B$99901,">="&B3,受注ログ!$B$6:$B$99901,"<="&C3) -> 0 | E3: =SUMIFS(受注ログ!$D$6:$D$99901,受注ログ!$B$6:$B$99901,">="&B3,受注ログ!$B$6:$B$99901,"<="&C3) -> 0 | F3: =D3+E3 -> 0 | G3: =サマリー!$B$15 -> 500000 | H3: =F3-G3 -> -500000 | I3: =IFERROR(F3/G3,0) -> 0 | J3: =IFERROR(D3/サマリー!$B$7,0) -> 0 | K3: =IFERROR(E3/サマリー!$B$7,0) -> 0
A4: 2 | B4: =サマリー!$B$14-WEEKDAY(サマリー!$B$14,2)+1+(2-1)*7 -> 45964 | C4: =B4+6 -> 45970 | D4: =SUMIFS(受注ログ!$C$6:$C$99901,受注ログ!$B$6:$B$99901,">="&B4,受注ログ!$B$6:$B$99901,"<="&C4) -> 0 | E4: =SUMIFS(受注ログ!$D$6:$D$99901,受注ログ!$B$6:$B$99901,">="&B4,受注ログ!$B$6:$B$99901,"<="&C4) -> 0 | F4: =D4+E4 -> 0 | G4: =サマリー!$B$15 -> 500000 | H4: =F4-G4 -> -500000 | I4: =IFERROR(F4/G4,0) -> 0 | J4: =IFERROR(D4/サマリー!$B$7,0) -> 0 | K4: =IFERROR(E4/サマリー!$B$7,0) -> 0
A5: 3 | B5: =サマリー!$B$14-WEEKDAY(サマリー!$B$14,2)+1+(3-1)*7 -> 45971 | C5: =B5+6 -> 45977 | D5: =SUMIFS(受注ログ!$C$6:$C$99901,受注ログ!$B$6:$B$99901,">="&B5,受注ログ!$B$6:$B$99901,"<="&C5) -> 0 | E5: =SUMIFS(受注ログ!$D$6:$D$99901,受注ログ!$B$6:$B$99901,">="&B5,受注ログ!$B$6:$B$99901,"<="&C5) -> 0 | F5: =D5+E5 -> 0 | G5: =サマリー!$B$15 -> 500000 | H5: =F5-G5 -> -500000 | I5: =IFERROR(F5/G5,0) -> 0 | J5: =IFERROR(D5/サマリー!$B$7,0) -> 0 | K5: =IFERROR(E5/サマリー!$B$7,0) -> 0
A6: 4 | B6: =サマリー!$B$14-WEEKDAY(サマリー!$B$14,2)+1+(4-1)*7 -> 45978 | C6: =B6+6 -> 45984 | D6: =SUMIFS(受注ログ!$C$6:$C$99901,受注ログ!$B$6:$B$99901,">="&B6,受注ログ!$B$6:$B$99901,"<="&C6) -> 0 | E6: =SUMIFS(受注ログ!$D$6:$D$99901,受注ログ!$B$6:$B$99901,">="&B6,受注ログ!$B$6:$B$99901,"<="&C6) -> 0 | F6: =D6+E6 -> 0 | G6: =サマリー!$B$15 -> 500000 | H6: =F6-G6 -> -500000 | I6: =IFERROR(F6/G6,0) -> 0 | J6: =IFERROR(D6/サマリー!$B$7,0) -> 0 | K6: =IFERROR(E6/サマリー!$B$7,0) -> 0
A7: 5 | B7: =サマリー!$B$14-WEEKDAY(サマリー!$B$14,2)+1+(5-1)*7 -> 45985 | C7: =B7+6 -> 45991 | D7: =SUMIFS(受注ログ!$C$6:$C$99901,受注ログ!$B$6:$B$99901,">="&B7,受注ログ!$B$6:$B$99901,"<="&C7) -> 0 | E7: =SUMIFS(受注ログ!$D$6:$D$99901,受注ログ!$B$6:$B$99901,">="&B7,受注ログ!$B$6:$B$99901,"<="&C7) -> 0 | F7: =D7+E7 -> 0 | G7: =サマリー!$B$15 -> 500000 | H7: =F7-G7 -> -500000 | I7: =IFERROR(F7/G7,0) -> 0 | J7: =IFERROR(D7/サマリー!$B$7,0) -> 0 | K7: =IFERROR(E7/サマリー!$B$7,0) -> 0
A8: 6 | B8: =サマリー!$B$14-WEEKDAY(サマリー!$B$14,2)+1+(6-1)*7 -> 45992 | C8: =B8+6 -> 45998 | D8: =SUMIFS(受注ログ!$C$6:$C$99901,受注ログ!$B$6:$B$99901,">="&B8,受注ログ!$B$6:$B$99901,"<="&C8) -> 0 | E8: =SUMIFS(受注ログ!$D$6:$D$99901,受注ログ!$B$6:$B$99901,">="&B8,受注ログ!$B$6:$B$99901,"<="&C8) -> 0 | F8: =D8+E8 -> 0 | G8: =サマリー!$B$15 -> 500000 | H8: =F8-G8 -> -500000 | I8: =IFERROR(F8/G8,0) -> 0 | J8: =IFERROR(D8/サマリー!$B$7,0) -> 0 | K8: =IFERROR(E8/サマリー!$B$7,0) -> 0
A9: 7 | B9: =サマリー!$B$14-WEEKDAY(サマリー!$B$14,2)+1+(7-1)*7 -> 45999 | C9: =B9+6 -> 46005 | D9: =SUMIFS(受注ログ!$C$6:$C$99901,受注ログ!$B$6:$B$99901,">="&B9,受注ログ!$B$6:$B$99901,"<="&C9) -> 0 | E9: =SUMIFS(受注ログ!$D$6:$D$99901,受注ログ!$B$6:$B$99901,">="&B9,受注ログ!$B$6:$B$99901,"<="&C9) -> 0 | F9: =D9+E9 -> 0 | G9: =サマリー!$B$15 -> 500000 | H9: =F9-G9 -> -500000 | I9: =IFERROR(F9/G9,0) -> 0 | J9: =IFERROR(D9/サマリー!$B$7,0) -> 0 | K9: =IFERROR(E9/サマリー!$B$7,0) -> 0
A10: 8 | B10: =サマリー!$B$14-WEEKDAY(サマリー!$B$14,2)+1+(8-1)*7 -> 46006 | C10: =B10+6 -> 46012 | D10: =SUMIFS(受注ログ!$C$6:$C$99901,受注ログ!$B$6:$B$99901,">="&B10,受注ログ!$B$6:$B$99901,"<="&C10) -> 0 | E10: =SUMIFS(受注ログ!$D$6:$D$99901,受注ログ!$B$6:$B$99901,">="&B10,受注ログ!$B$6:$B$99901,"<="&C10) -> 0 | F10: =D10+E10 -> 0 | G10: =サマリー!$B$15 -> 500000 | H10: =F10-G10 -> -500000 | I10: =IFERROR(F10/G10,0) -> 0 | J10: =IFERROR(D10/サマリー!$B$7,0) -> 0 | K10: =IFERROR(E10/サマリー!$B$7,0) -> 0
A11: 9 | B11: =サマリー!$B$14-WEEKDAY(サマリー!$B$14,2)+1+(9-1)*7 -> 46013 | C11: =B11+6 -> 46019 | D11: =SUMIFS(受注ログ!$C$6:$C$99901,受注ログ!$B$6:$B$99901,">="&B11,受注ログ!$B$6:$B$99901,"<="&C11) -> 0 | E11: =SUMIFS(受注ログ!$D$6:$D$99901,受注ログ!$B$6:$B$99901,">="&B11,受注ログ!$B$6:$B$99901,"<="&C11) -> 0 | F11: =D11+E11 -> 0 | G11: =サマリー!$B$15 -> 500000 | H11: =F11-G11 -> -500000 | I11: =IFERROR(F11/G11,0) -> 0 | J11: =IFERROR(D11/サマリー!$B$7,0) -> 0 | K11: =IFERROR(E11/サマリー!$B$7,0) -> 0
A12: 10 | B12: =サマリー!$B$14-WEEKDAY(サマリー!$B$14,2)+1+(10-1)*7 -> 46020 | C12: =B12+6 -> 46026 | D12: =SUMIFS(受注ログ!$C$6:$C$99901,受注ログ!$B$6:$B$99901,">="&B12,受注ログ!$B$6:$B$99901,"<="&C12) -> 0 | E12: =SUMIFS(受注ログ!$D$6:$D$99901,受注ログ!$B$6:$B$99901,">="&B12,受注ログ!$B$6:$B$99901,"<="&C12) -> 0 | F12: =D12+E12 -> 0 | G12: =サマリー!$B$15 -> 500000 | H12: =F12-G12 -> -500000 | I12: =IFERROR(F12/G12,0) -> 0 | J12: =IFERROR(D12/サマリー!$B$7,0) -> 0 | K12: =IFERROR(E12/サマリー!$B$7,0) -> 0
A13: 11 | B13: =サマリー!$B$14-WEEKDAY(サマリー!$B$14,2)+1+(11-1)*7 -> 46027 | C13: =B13+6 -> 46033 | D13: =SUMIFS(受注ログ!$C$6:$C$99901,受注ログ!$B$6:$B$99901,">="&B13,受注ログ!$B$6:$B$99901,"<="&C13) -> 0 | E13: =SUMIFS(受注ログ!$D$6:$D$99901,受注ログ!$B$6:$B$99901,">="&B13,受注ログ!$B$6:$B$99901,"<="&C13) -> 0 | F13: =D13+E13 -> 0 | G13: =サマリー!$B$15 -> 500000 | H13: =F13-G13 -> -500000 | I13: =IFERROR(F13/G13,0) -> 0 | J13: =IFERROR(D13/サマリー!$B$7,0) -> 0 | K13: =IFERROR(E13/サマリー!$B$7,0) -> 0
A14: 12 | B14: =サマリー!$B$14-WEEKDAY(サマリー!$B$14,2)+1+(12-1)*7 -> 46034 | C14: =B14+6 -> 46040 | D14: =SUMIFS(受注ログ!$C$6:$C$99901,受注ログ!$B$6:$B$99901,">="&B14,受注ログ!$B$6:$B$99901,"<="&C14) -> 0 | E14: =SUMIFS(受注ログ!$D$6:$D$99901,受注ログ!$B$6:$B$99901,">="&B14,受注ログ!$B$6:$B$99901,"<="&C14) -> 0 | F14: =D14+E14 -> 0 | G14: =サマリー!$B$15 -> 500000 | H14: =F14-G14 -> -500000 | I14: =IFERROR(F14/G14,0) -> 0 | J14: =IFERROR(D14/サマリー!$B$7,0) -> 0 | K14: =IFERROR(E14/サマリー!$B$7,0) -> 0
A15: 13 | B15: =サマリー!$B$14-WEEKDAY(サマリー!$B$14,2)+1+(13-1)*7 -> 46041 | C15: =B15+6 -> 46047 | D15: =SUMIFS(受注ログ!$C$6:$C$99901,受注ログ!$B$6:$B$99901,">="&B15,受注ログ!$B$6:$B$99901,"<="&C15) -> 0 | E15: =SUMIFS(受注ログ!$D$6:$D$99901,受注ログ!$B$6:$B$99901,">="&B15,受注ログ!$B$6:$B$99901,"<="&C15) -> 0 | F15: =D15+E15 -> 0 | G15: =サマリー!$B$15 -> 500000 | H15: =F15-G15 -> -500000 | I15: =IFERROR(F15/G15,0) -> 0 | J15: =IFERROR(D15/サマリー!$B$7,0) -> 0 | K15: =IFERROR(E15/サマリー!$B$7,0) -> 0
A16: 14 | B16: =サマリー!$B$14-WEEKDAY(サマリー!$B$14,2)+1+(14-1)*7 -> 46048 | C16: =B16+6 -> 46054 | D16: =SUMIFS(受注ログ!$C$6:$C$99901,受注ログ!$B$6:$B$99901,">="&B16,受注ログ!$B$6:$B$99901,"<="&C16) -> 0 | E16: =SUMIFS(受注ログ!$D$6:$D$99901,受注ログ!$B$6:$B$99901,">="&B16,受注ログ!$B$6:$B$99901,"<="&C16) -> 0 | F16: =D16+E16 -> 0 | G16: =サマリー!$B$15 -> 500000 | H16: =F16-G16 -> -500000 | I16: =IFERROR(F16/G16,0) -> 0 | J16: =IFERROR(D16/サマリー!$B$7,0) -> 0 | K16: =IFERROR(E16/サマリー!$B$7,0) -> 0
A17: 15 | B17: =サマリー!$B$14-WEEKDAY(サマリー!$B$14,2)+1+(15-1)*7 -> 46055 | C17: =B17+6 -> 46061 | D17: =SUMIFS(受注ログ!$C$6:$C$99901,受注ログ!$B$6:$B$99901,">="&B17,受注ログ!$B$6:$B$99901,"<="&C17) -> 0 | E17: =SUMIFS(受注ログ!$D$6:$D$99901,受注ログ!$B$6:$B$99901,">="&B17,受注ログ!$B$6:$B$99901,"<="&C17) -> 0 | F17: =D17+E17 -> 0 | G17: =サマリー!$B$15 -> 500000 | H17: =F17-G17 -> -500000 | I17: =IFERROR(F17/G17,0) -> 0 | J17: =IFERROR(D17/サマリー!$B$7,0) -> 0 | K17: =IFERROR(E17/サマリー!$B$7,0) -> 0
A18: 16 | B18: =サマリー!$B$14-WEEKDAY(サマリー!$B$14,2)+1+(16-1)*7 -> 46062 | C18: =B18+6 -> 46068 | D18: =SUMIFS(受注ログ!$C$6:$C$99901,受注ログ!$B$6:$B$99901,">="&B18,受注ログ!$B$6:$B$99901,"<="&C18) -> 0 | E18: =SUMIFS(受注ログ!$D$6:$D$99901,受注ログ!$B$6:$B$99901,">="&B18,受注ログ!$B$6:$B$99901,"<="&C18) -> 0 | F18: =D18+E18 -> 0 | G18: =サマリー!$B$15 -> 500000 | H18: =F18-G18 -> -500000 | I18: =IFERROR(F18/G18,0) -> 0 | J18: =IFERROR(D18/サマリー!$B$7,0) -> 0 | K18: =IFERROR(E18/サマリー!$B$7,0) -> 0
A19: 17 | B19: =サマリー!$B$14-WEEKDAY(サマリー!$B$14,2)+1+(17-1)*7 -> 46069 | C19: =B19+6 -> 46075 | D19: =SUMIFS(受注ログ!$C$6:$C$99901,受注ログ!$B$6:$B$99901,">="&B19,受注ログ!$B$6:$B$99901,"<="&C19) -> 0 | E19: =SUMIFS(受注ログ!$D$6:$D$99901,受注ログ!$B$6:$B$99901,">="&B19,受注ログ!$B$6:$B$99901,"<="&C19) -> 0 | F19: =D19+E19 -> 0 | G19: =サマリー!$B$15 -> 500000 | H19: =F19-G19 -> -500000 | I19: =IFERROR(F19/G19,0) -> 0 | J19: =IFERROR(D19/サマリー!$B$7,0) -> 0 | K19: =IFERROR(E19/サマリー!$B$7,0) -> 0
A20: 18 | B20: =サマリー!$B$14-WEEKDAY(サマリー!$B$14,2)+1+(18-1)*7 -> 46076 | C20: =B20+6 -> 46082 | D20: =SUMIFS(受注ログ!$C$6:$C$99901,受注ログ!$B$6:$B$99901,">="&B20,受注ログ!$B$6:$B$99901,"<="&C20) -> 0 | E20: =SUMIFS(受注ログ!$D$6:$D$99901,受注ログ!$B$6:$B$99901,">="&B20,受注ログ!$B$6:$B$99901,"<="&C20) -> 0 | F20: =D20+E20 -> 0 | G20: =サマリー!$B$15 -> 500000 | H20: =F20-G20 -> -500000 | I20: =IFERROR(F20/G20,0) -> 0 | J20: =IFERROR(D20/サマリー!$B$7,0) -> 0 | K20: =IFERROR(E20/サマリー!$B$7,0) -> 0
A21: 19 | B21: =サマリー!$B$14-WEEKDAY(サマリー!$B$14,2)+1+(19-1)*7 -> 46083 | C21: =B21+6 -> 46089 | D21: =SUMIFS(受注ログ!$C$6:$C$99901,受注ログ!$B$6:$B$99901,">="&B21,受注ログ!$B$6:$B$99901,"<="&C21) -> 0 | E21: =SUMIFS(受注ログ!$D$6:$D$99901,受注ログ!$B$6:$B$99901,">="&B21,受注ログ!$B$6:$B$99901,"<="&C21) -> 0 | F21: =D21+E21 -> 0 | G21: =サマリー!$B$15 -> 500000 | H21: =F21-G21 -> -500000 | I21: =IFERROR(F21/G21,0) -> 0 | J21: =IFERROR(D21/サマリー!$B$7,0) -> 0 | K21: =IFERROR(E21/サマリー!$B$7,0) -> 0
A22: 20 | B22: =サマリー!$B$14-WEEKDAY(サマリー!$B$14,2)+1+(20-1)*7 -> 46090 | C22: =B22+6 -> 46096 | D22: =SUMIFS(受注ログ!$C$6:$C$99901,受注ログ!$B$6:$B$99901,">="&B22,受注ログ!$B$6:$B$99901,"<="&C22) -> 0 | E22: =SUMIFS(受注ログ!$D$6:$D$99901,受注ログ!$B$6:$B$99901,">="&B22,受注ログ!$B$6:$B$99901,"<="&C22) -> 0 | F22: =D22+E22 -> 0 | G22: =サマリー!$B$15 -> 500000 | H22: =F22-G22 -> -500000 | I22: =IFERROR(F22/G22,0) -> 0 | J22: =IFERROR(D22/サマリー!$B$7,0) -> 0 | K22: =IFERROR(E22/サマリー!$B$7,0) -> 0
A23: 21 | B23: =サマリー!$B$14-WEEKDAY(サマリー!$B$14,2)+1+(21-1)*7 -> 46097 | C23: =B23+6 -> 46103 | D23: =SUMIFS(受注ログ!$C$6:$C$99901,受注ログ!$B$6:$B$99901,">="&B23,受注ログ!$B$6:$B$99901,"<="&C23) -> 0 | E23: =SUMIFS(受注ログ!$D$6:$D$99901,受注ログ!$B$6:$B$99901,">="&B23,受注ログ!$B$6:$B$99901,"<="&C23) -> 0 | F23: =D23+E23 -> 0 | G23: =サマリー!$B$15 -> 500000 | H23: =F23-G23 -> -500000 | I23: =IFERROR(F23/G23,0) -> 0 | J23: =IFERROR(D23/サマリー!$B$7,0) -> 0 | K23: =IFERROR(E23/サマリー!$B$7,0) -> 0
A24: 22 | B24: =サマリー!$B$14-WEEKDAY(サマリー!$B$14,2)+1+(22-1)*7 -> 46104 | C24: =B24+6 -> 46110 | D24: =SUMIFS(受注ログ!$C$6:$C$99901,受注ログ!$B$6:$B$99901,">="&B24,受注ログ!$B$6:$B$99901,"<="&C24) -> 0 | E24: =SUMIFS(受注ログ!$D$6:$D$99901,受注ログ!$B$6:$B$99901,">="&B24,受注ログ!$B$6:$B$99901,"<="&C24) -> 0 | F24: =D24+E24 -> 0 | G24: =サマリー!$B$15 -> 500000 | H24: =F24-G24 -> -500000 | I24: =IFERROR(F24/G24,0) -> 0 | J24: =IFERROR(D24/サマリー!$B$7,0) -> 0 | K24: =IFERROR(E24/サマリー!$B$7,0) -> 0
A25: 23 | B25: =サマリー!$B$14-WEEKDAY(サマリー!$B$14,2)+1+(23-1)*7 -> 46111 | C25: =B25+6 -> 46117 | D25: =SUMIFS(受注ログ!$C$6:$C$99901,受注ログ!$B$6:$B$99901,">="&B25,受注ログ!$B$6:$B$99901,"<="&C25) -> 0 | E25: =SUMIFS(受注ログ!$D$6:$D$99901,受注ログ!$B$6:$B$99901,">="&B25,受注ログ!$B$6:$B$99901,"<="&C25) -> 0 | F25: =D25+E25 -> 0 | G25: =サマリー!$B$15 -> 500000 | H25: =F25-G25 -> -500000 | I25: =IFERROR(F25/G25,0) -> 0 | J25: =IFERROR(D25/サマリー!$B$7,0) -> 0 | K25: =IFERROR(E25/サマリー!$B$7,0) -> 0
A26: 24 | B26: =サマリー!$B$14-WEEKDAY(サマリー!$B$14,2)+1+(24-1)*7 -> 46118 | C26: =B26+6 -> 46124 | D26: =SUMIFS(受注ログ!$C$6:$C$99901,受注ログ!$B$6:$B$99901,">="&B26,受注ログ!$B$6:$B$99901,"<="&C26) -> 0 | E26: =SUMIFS(受注ログ!$D$6:$D$99901,受注ログ!$B$6:$B$99901,">="&B26,受注ログ!$B$6:$B$99901,"<="&C26) -> 0 | F26: =D26+E26 -> 0 | G26: =サマリー!$B$15 -> 500000 | H26: =F26-G26 -> -500000 | I26: =IFERROR(F26/G26,0) -> 0 | J26: =IFERROR(D26/サマリー!$B$7,0) -> 0 | K26: =IFERROR(E26/サマリー!$B$7,0) -> 0
A27: 25 | B27: =サマリー!$B$14-WEEKDAY(サマリー!$B$14,2)+1+(25-1)*7 -> 46125 | C27: =B27+6 -> 46131 | D27: =SUMIFS(受注ログ!$C$6:$C$99901,受注ログ!$B$6:$B$99901,">="&B27,受注ログ!$B$6:$B$99901,"<="&C27) -> 0 | E27: =SUMIFS(受注ログ!$D$6:$D$99901,受注ログ!$B$6:$B$99901,">="&B27,受注ログ!$B$6:$B$99901,"<="&C27) -> 0 | F27: =D27+E27 -> 0 | G27: =サマリー!$B$15 -> 500000 | H27: =F27-G27 -> -500000 | I27: =IFERROR(F27/G27,0) -> 0 | J27: =IFERROR(D27/サマリー!$B$7,0) -> 0 | K27: =IFERROR(E27/サマリー!$B$7,0) -> 0
A28: 26 | B28: =サマリー!$B$14-WEEKDAY(サマリー!$B$14,2)+1+(26-1)*7 -> 46132 | C28: =B28+6 -> 46138 | D28: =SUMIFS(受注ログ!$C$6:$C$99901,受注ログ!$B$6:$B$99901,">="&B28,受注ログ!$B$6:$B$99901,"<="&C28) -> 0 | E28: =SUMIFS(受注ログ!$D$6:$D$99901,受注ログ!$B$6:$B$99901,">="&B28,受注ログ!$B$6:$B$99901,"<="&C28) -> 0 | F28: =D28+E28 -> 0 | G28: =サマリー!$B$15 -> 500000 | H28: =F28-G28 -> -500000 | I28: =IFERROR(F28/G28,0) -> 0 | J28: =IFERROR(D28/サマリー!$B$7,0) -> 0 | K28: =IFERROR(E28/サマリー!$B$7,0) -> 0
A29: 27 | B29: =サマリー!$B$14-WEEKDAY(サマリー!$B$14,2)+1+(27-1)*7 -> 46139 | C29: =B29+6 -> 46145 | D29: =SUMIFS(受注ログ!$C$6:$C$99901,受注ログ!$B$6:$B$99901,">="&B29,受注ログ!$B$6:$B$99901,"<="&C29) -> 351570 | E29: =SUMIFS(受注ログ!$D$6:$D$99901,受注ログ!$B$6:$B$99901,">="&B29,受注ログ!$B$6:$B$99901,"<="&C29) -> 98855 | F29: =D29+E29 -> 450425 | G29: =サマリー!$B$15 -> 500000 | H29: =F29-G29 -> -49575 | I29: =IFERROR(F29/G29,0) -> 0.90085 | J29: =IFERROR(D29/サマリー!$B$7,0) -> 1.40628 | K29: =IFERROR(E29/サマリー!$B$7,0) -> 0.39542
A30: 28 | B30: =サマリー!$B$14-WEEKDAY(サマリー!$B$14,2)+1+(28-1)*7 -> 46146 | C30: =B30+6 -> 46152 | D30: =SUMIFS(受注ログ!$C$6:$C$99901,受注ログ!$B$6:$B$99901,">="&B30,受注ログ!$B$6:$B$99901,"<="&C30) -> 165074 | E30: =SUMIFS(受注ログ!$D$6:$D$99901,受注ログ!$B$6:$B$99901,">="&B30,受注ログ!$B$6:$B$99901,"<="&C30) -> 812830 | F30: =D30+E30 -> 977904 | G30: =サマリー!$B$15 -> 500000 | H30: =F30-G30 -> 477904 | I30: =IFERROR(F30/G30,0) -> 1.955808 | J30: =IFERROR(D30/サマリー!$B$7,0) -> 0.660296 | K30: =IFERROR(E30/サマリー!$B$7,0) -> 3.25132
A31: 29 | B31: =サマリー!$B$14-WEEKDAY(サマリー!$B$14,2)+1+(29-1)*7 -> 46153 | C31: =B31+6 -> 46159 | D31: =SUMIFS(受注ログ!$C$6:$C$99901,受注ログ!$B$6:$B$99901,">="&B31,受注ログ!$B$6:$B$99901,"<="&C31) -> 233705 | E31: =SUMIFS(受注ログ!$D$6:$D$99901,受注ログ!$B$6:$B$99901,">="&B31,受注ログ!$B$6:$B$99901,"<="&C31) -> 283078 | F31: =D31+E31 -> 516783 | G31: =サマリー!$B$15 -> 500000 | H31: =F31-G31 -> 16783 | I31: =IFERROR(F31/G31,0) -> 1.033566 | J31: =IFERROR(D31/サマリー!$B$7,0) -> 0.93482 | K31: =IFERROR(E31/サマリー!$B$7,0) -> 1.132312
A32: 30 | B32: =サマリー!$B$14-WEEKDAY(サマリー!$B$14,2)+1+(30-1)*7 -> 46160 | C32: =B32+6 -> 46166 | D32: =SUMIFS(受注ログ!$C$6:$C$99901,受注ログ!$B$6:$B$99901,">="&B32,受注ログ!$B$6:$B$99901,"<="&C32) -> 237372 | E32: =SUMIFS(受注ログ!$D$6:$D$99901,受注ログ!$B$6:$B$99901,">="&B32,受注ログ!$B$6:$B$99901,"<="&C32) -> 233457 | F32: =D32+E32 -> 470829 | G32: =サマリー!$B$15 -> 500000 | H32: =F32-G32 -> -29171 | I32: =IFERROR(F32/G32,0) -> 0.941658 | J32: =IFERROR(D32/サマリー!$B$7,0) -> 0.949488 | K32: =IFERROR(E32/サマリー!$B$7,0) -> 0.933828
A33: 31 | B33: =サマリー!$B$14-WEEKDAY(サマリー!$B$14,2)+1+(31-1)*7 -> 46167 | C33: =B33+6 -> 46173 | D33: =SUMIFS(受注ログ!$C$6:$C$99901,受注ログ!$B$6:$B$99901,">="&B33,受注ログ!$B$6:$B$99901,"<="&C33) -> 261198 | E33: =SUMIFS(受注ログ!$D$6:$D$99901,受注ログ!$B$6:$B$99901,">="&B33,受注ログ!$B$6:$B$99901,"<="&C33) -> 164679 | F33: =D33+E33 -> 425877 | G33: =サマリー!$B$15 -> 500000 | H33: =F33-G33 -> -74123 | I33: =IFERROR(F33/G33,0) -> 0.851754 | J33: =IFERROR(D33/サマリー!$B$7,0) -> 1.044792 | K33: =IFERROR(E33/サマリー!$B$7,0) -> 0.658716
A34: 32 | B34: =サマリー!$B$14-WEEKDAY(サマリー!$B$14,2)+1+(32-1)*7 -> 46174 | C34: =B34+6 -> 46180 | D34: =SUMIFS(受注ログ!$C$6:$C$99901,受注ログ!$B$6:$B$99901,">="&B34,受注ログ!$B$6:$B$99901,"<="&C34) -> 144358 | E34: =SUMIFS(受注ログ!$D$6:$D$99901,受注ログ!$B$6:$B$99901,">="&B34,受注ログ!$B$6:$B$99901,"<="&C34) -> 227156 | F34: =D34+E34 -> 371514 | G34: =サマリー!$B$15 -> 500000 | H34: =F34-G34 -> -128486 | I34: =IFERROR(F34/G34,0) -> 0.743028 | J34: =IFERROR(D34/サマリー!$B$7,0) -> 0.577432 | K34: =IFERROR(E34/サマリー!$B$7,0) -> 0.908624
A35: 33 | B35: =サマリー!$B$14-WEEKDAY(サマリー!$B$14,2)+1+(33-1)*7 -> 46181 | C35: =B35+6 -> 46187 | D35: =SUMIFS(受注ログ!$C$6:$C$99901,受注ログ!$B$6:$B$99901,">="&B35,受注ログ!$B$6:$B$99901,"<="&C35) -> 257743 | E35: =SUMIFS(受注ログ!$D$6:$D$99901,受注ログ!$B$6:$B$99901,">="&B35,受注ログ!$B$6:$B$99901,"<="&C35) -> 217213 | F35: =D35+E35 -> 474956 | G35: =サマリー!$B$15 -> 500000 | H35: =F35-G35 -> -25044 | I35: =IFERROR(F35/G35,0) -> 0.949912 | J35: =IFERROR(D35/サマリー!$B$7,0) -> 1.030972 | K35: =IFERROR(E35/サマリー!$B$7,0) -> 0.868852
A36: 34 | B36: =サマリー!$B$14-WEEKDAY(サマリー!$B$14,2)+1+(34-1)*7 -> 46188 | C36: =B36+6 -> 46194 | D36: =SUMIFS(受注ログ!$C$6:$C$99901,受注ログ!$B$6:$B$99901,">="&B36,受注ログ!$B$6:$B$99901,"<="&C36) -> 264531 | E36: =SUMIFS(受注ログ!$D$6:$D$99901,受注ログ!$B$6:$B$99901,">="&B36,受注ログ!$B$6:$B$99901,"<="&C36) -> 226432 | F36: =D36+E36 -> 490963 | G36: =サマリー!$B$15 -> 500000 | H36: =F36-G36 -> -9037 | I36: =IFERROR(F36/G36,0) -> 0.981926 | J36: =IFERROR(D36/サマリー!$B$7,0) -> 1.058124 | K36: =IFERROR(E36/サマリー!$B$7,0) -> 0.905728
A37: 35 | B37: =サマリー!$B$14-WEEKDAY(サマリー!$B$14,2)+1+(35-1)*7 -> 46195 | C37: =B37+6 -> 46201 | D37: =SUMIFS(受注ログ!$C$6:$C$99901,受注ログ!$B$6:$B$99901,">="&B37,受注ログ!$B$6:$B$99901,"<="&C37) -> 297531 | E37: =SUMIFS(受注ログ!$D$6:$D$99901,受注ログ!$B$6:$B$99901,">="&B37,受注ログ!$B$6:$B$99901,"<="&C37) -> 134271 | F37: =D37+E37 -> 431802 | G37: =サマリー!$B$15 -> 500000 | H37: =F37-G37 -> -68198 | I37: =IFERROR(F37/G37,0) -> 0.863604 | J37: =IFERROR(D37/サマリー!$B$7,0) -> 1.190124 | K37: =IFERROR(E37/サマリー!$B$7,0) -> 0.537084
A38: 36 | B38: =サマリー!$B$14-WEEKDAY(サマリー!$B$14,2)+1+(36-1)*7 -> 46202 | C38: =B38+6 -> 46208 | D38: =SUMIFS(受注ログ!$C$6:$C$99901,受注ログ!$B$6:$B$99901,">="&B38,受注ログ!$B$6:$B$99901,"<="&C38) -> 245666 | E38: =SUMIFS(受注ログ!$D$6:$D$99901,受注ログ!$B$6:$B$99901,">="&B38,受注ログ!$B$6:$B$99901,"<="&C38) -> 90837 | F38: =D38+E38 -> 336503 | G38: =サマリー!$B$15 -> 500000 | H38: =F38-G38 -> -163497 | I38: =IFERROR(F38/G38,0) -> 0.673006 | J38: =IFERROR(D38/サマリー!$B$7,0) -> 0.982664 | K38: =IFERROR(E38/サマリー!$B$7,0) -> 0.363348
A39: 37 | B39: =サマリー!$B$14-WEEKDAY(サマリー!$B$14,2)+1+(37-1)*7 -> 46209 | C39: =B39+6 -> 46215 | D39: =SUMIFS(受注ログ!$C$6:$C$99901,受注ログ!$B$6:$B$99901,">="&B39,受注ログ!$B$6:$B$99901,"<="&C39) -> 193955 | E39: =SUMIFS(受注ログ!$D$6:$D$99901,受注ログ!$B$6:$B$99901,">="&B39,受注ログ!$B$6:$B$99901,"<="&C39) -> 172580 | F39: =D39+E39 -> 366535 | G39: =サマリー!$B$15 -> 500000 | H39: =F39-G39 -> -133465 | I39: =IFERROR(F39/G39,0) -> 0.73307 | J39: =IFERROR(D39/サマリー!$B$7,0) -> 0.77582 | K39: =IFERROR(E39/サマリー!$B$7,0) -> 0.69032
A40: 38 | B40: =サマリー!$B$14-WEEKDAY(サマリー!$B$14,2)+1+(38-1)*7 -> 46216 | C40: =B40+6 -> 46222 | D40: =SUMIFS(受注ログ!$C$6:$C$99901,受注ログ!$B$6:$B$99901,">="&B40,受注ログ!$B$6:$B$99901,"<="&C40) -> 268580 | E40: =SUMIFS(受注ログ!$D$6:$D$99901,受注ログ!$B$6:$B$99901,">="&B40,受注ログ!$B$6:$B$99901,"<="&C40) -> 88808 | F40: =D40+E40 -> 357388 | G40: =サマリー!$B$15 -> 500000 | H40: =F40-G40 -> -142612 | I40: =IFERROR(F40/G40,0) -> 0.714776 | J40: =IFERROR(D40/サマリー!$B$7,0) -> 1.07432 | K40: =IFERROR(E40/サマリー!$B$7,0) -> 0.355232
...

Sheet 月次集計
A1: 月次集計（個人月予算100万円×2＝チーム200万円）
A2: 月番号 | B2: 開始日 | C2: 終了日 | D2: 小原実績 | E2: 前園実績 | F2: チーム計 | G2: チーム月予算 | H2: 差異 | I2: 達成率 | J2: 小原達成率 | K2: 前園達成率
A3: 1 | B3: =EDATE(サマリー!$B$14,1-1) -> 45962 | C3: =EOMONTH(B3,0) -> 45991 | D3: =SUMIFS(受注ログ!$C$6:$C$99901,受注ログ!$B$6:$B$99901,">="&B3,受注ログ!$B$6:$B$99901,"<="&C3) -> 0 | E3: =SUMIFS(受注ログ!$D$6:$D$99901,受注ログ!$B$6:$B$99901,">="&B3,受注ログ!$B$6:$B$99901,"<="&C3) -> 0 | F3: =D3+E3 -> 0 | G3: =サマリー!$B$16 -> 2000000 | H3: =F3-G3 -> -2000000 | I3: =IFERROR(F3/G3,0) -> 0 | J3: =IFERROR(D3/サマリー!$B$8,0) -> 0 | K3: =IFERROR(E3/サマリー!$B$8,0) -> 0
A4: 2 | B4: =EDATE(サマリー!$B$14,2-1) -> 45992 | C4: =EOMONTH(B4,0) -> 46022 | D4: =SUMIFS(受注ログ!$C$6:$C$99901,受注ログ!$B$6:$B$99901,">="&B4,受注ログ!$B$6:$B$99901,"<="&C4) -> 0 | E4: =SUMIFS(受注ログ!$D$6:$D$99901,受注ログ!$B$6:$B$99901,">="&B4,受注ログ!$B$6:$B$99901,"<="&C4) -> 0 | F4: =D4+E4 -> 0 | G4: =サマリー!$B$16 -> 2000000 | H4: =F4-G4 -> -2000000 | I4: =IFERROR(F4/G4,0) -> 0 | J4: =IFERROR(D4/サマリー!$B$8,0) -> 0 | K4: =IFERROR(E4/サマリー!$B$8,0) -> 0
A5: 3 | B5: =EDATE(サマリー!$B$14,3-1) -> 46023 | C5: =EOMONTH(B5,0) -> 46053 | D5: =SUMIFS(受注ログ!$C$6:$C$99901,受注ログ!$B$6:$B$99901,">="&B5,受注ログ!$B$6:$B$99901,"<="&C5) -> 0 | E5: =SUMIFS(受注ログ!$D$6:$D$99901,受注ログ!$B$6:$B$99901,">="&B5,受注ログ!$B$6:$B$99901,"<="&C5) -> 0 | F5: =D5+E5 -> 0 | G5: =サマリー!$B$16 -> 2000000 | H5: =F5-G5 -> -2000000 | I5: =IFERROR(F5/G5,0) -> 0 | J5: =IFERROR(D5/サマリー!$B$8,0) -> 0 | K5: =IFERROR(E5/サマリー!$B$8,0) -> 0
A6: 4 | B6: =EDATE(サマリー!$B$14,4-1) -> 46054 | C6: =EOMONTH(B6,0) -> 46081 | D6: =SUMIFS(受注ログ!$C$6:$C$99901,受注ログ!$B$6:$B$99901,">="&B6,受注ログ!$B$6:$B$99901,"<="&C6) -> 0 | E6: =SUMIFS(受注ログ!$D$6:$D$99901,受注ログ!$B$6:$B$99901,">="&B6,受注ログ!$B$6:$B$99901,"<="&C6) -> 0 | F6: =D6+E6 -> 0 | G6: =サマリー!$B$16 -> 2000000 | H6: =F6-G6 -> -2000000 | I6: =IFERROR(F6/G6,0) -> 0 | J6: =IFERROR(D6/サマリー!$B$8,0) -> 0 | K6: =IFERROR(E6/サマリー!$B$8,0) -> 0
A7: 5 | B7: =EDATE(サマリー!$B$14,5-1) -> 46082 | C7: =EOMONTH(B7,0) -> 46112 | D7: =SUMIFS(受注ログ!$C$6:$C$99901,受注ログ!$B$6:$B$99901,">="&B7,受注ログ!$B$6:$B$99901,"<="&C7) -> 0 | E7: =SUMIFS(受注ログ!$D$6:$D$99901,受注ログ!$B$6:$B$99901,">="&B7,受注ログ!$B$6:$B$99901,"<="&C7) -> 0 | F7: =D7+E7 -> 0 | G7: =サマリー!$B$16 -> 2000000 | H7: =F7-G7 -> -2000000 | I7: =IFERROR(F7/G7,0) -> 0 | J7: =IFERROR(D7/サマリー!$B$8,0) -> 0 | K7: =IFERROR(E7/サマリー!$B$8,0) -> 0
A8: 6 | B8: =EDATE(サマリー!$B$14,6-1) -> 46113 | C8: =EOMONTH(B8,0) -> 46142 | D8: =SUMIFS(受注ログ!$C$6:$C$99901,受注ログ!$B$6:$B$99901,">="&B8,受注ログ!$B$6:$B$99901,"<="&C8) -> 0 | E8: =SUMIFS(受注ログ!$D$6:$D$99901,受注ログ!$B$6:$B$99901,">="&B8,受注ログ!$B$6:$B$99901,"<="&C8) -> 0 | F8: =D8+E8 -> 0 | G8: =サマリー!$B$16 -> 2000000 | H8: =F8-G8 -> -2000000 | I8: =IFERROR(F8/G8,0) -> 0 | J8: =IFERROR(D8/サマリー!$B$8,0) -> 0 | K8: =IFERROR(E8/サマリー!$B$8,0) -> 0
A9: 7 | B9: =EDATE(サマリー!$B$14,7-1) -> 46143 | C9: =EOMONTH(B9,0) -> 46173 | D9: =SUMIFS(受注ログ!$C$6:$C$99901,受注ログ!$B$6:$B$99901,">="&B9,受注ログ!$B$6:$B$99901,"<="&C9) -> 1248919 | E9: =SUMIFS(受注ログ!$D$6:$D$99901,受注ログ!$B$6:$B$99901,">="&B9,受注ログ!$B$6:$B$99901,"<="&C9) -> 1592899 | F9: =D9+E9 -> 2841818 | G9: =サマリー!$B$16 -> 2000000 | H9: =F9-G9 -> 841818 | I9: =IFERROR(F9/G9,0) -> 1.420909 | J9: =IFERROR(D9/サマリー!$B$8,0) -> 1.248919 | K9: =IFERROR(E9/サマリー!$B$8,0) -> 1.592899
A10: 8 | B10: =EDATE(サマリー!$B$14,8-1) -> 46174 | C10: =EOMONTH(B10,0) -> 46203 | D10: =SUMIFS(受注ログ!$C$6:$C$99901,受注ログ!$B$6:$B$99901,">="&B10,受注ログ!$B$6:$B$99901,"<="&C10) -> 1055167 | E10: =SUMIFS(受注ログ!$D$6:$D$99901,受注ログ!$B$6:$B$99901,">="&B10,受注ログ!$B$6:$B$99901,"<="&C10) -> 832944 | F10: =D10+E10 -> 1888111 | G10: =サマリー!$B$16 -> 2000000 | H10: =F10-G10 -> -111889 | I10: =IFERROR(F10/G10,0) -> 0.9440555 | J10: =IFERROR(D10/サマリー!$B$8,0) -> 1.055167 | K10: =IFERROR(E10/サマリー!$B$8,0) -> 0.832944
A11: 9 | B11: =EDATE(サマリー!$B$14,9-1) -> 46204 | C11: =EOMONTH(B11,0) -> 46234 | D11: =SUMIFS(受注ログ!$C$6:$C$99901,受注ログ!$B$6:$B$99901,">="&B11,受注ログ!$B$6:$B$99901,"<="&C11) -> 1123457 | E11: =SUMIFS(受注ログ!$D$6:$D$99901,受注ログ!$B$6:$B$99901,">="&B11,受注ログ!$B$6:$B$99901,"<="&C11) -> 639108 | F11: =D11+E11 -> 1762565 | G11: =サマリー!$B$16 -> 2000000 | H11: =F11-G11 -> -237435 | I11: =IFERROR(F11/G11,0) -> 0.8812825 | J11: =IFERROR(D11/サマリー!$B$8,0) -> 1.123457 | K11: =IFERROR(E11/サマリー!$B$8,0) -> 0.639108
A12: 10 | B12: =EDATE(サマリー!$B$14,10-1) -> 46235 | C12: =EOMONTH(B12,0) -> 46265 | D12: =SUMIFS(受注ログ!$C$6:$C$99901,受注ログ!$B$6:$B$99901,">="&B12,受注ログ!$B$6:$B$99901,"<="&C12) -> 1102988 | E12: =SUMIFS(受注ログ!$D$6:$D$99901,受注ログ!$B$6:$B$99901,">="&B12,受注ログ!$B$6:$B$99901,"<="&C12) -> 957083 | F12: =D12+E12 -> 2060071 | G12: =サマリー!$B$16 -> 2000000 | H12: =F12-G12 -> 60071 | I12: =IFERROR(F12/G12,0) -> 1.0300355 | J12: =IFERROR(D12/サマリー!$B$8,0) -> 1.102988 | K12: =IFERROR(E12/サマリー!$B$8,0) -> 0.957083
A13: 11 | B13: =EDATE(サマリー!$B$14,11-1) -> 46266 | C13: =EOMONTH(B13,0) -> 46295 | D13: =SUMIFS(受注ログ!$C$6:$C$99901,受注ログ!$B$6:$B$99901,">="&B13,受注ログ!$B$6:$B$99901,"<="&C13) -> 1468973 | E13: =SUMIFS(受注ログ!$D$6:$D$99901,受注ログ!$B$6:$B$99901,">="&B13,受注ログ!$B$6:$B$99901,"<="&C13) -> 716491 | F13: =D13+E13 -> 2185464 | G13: =サマリー!$B$16 -> 2000000 | H13: =F13-G13 -> 185464 | I13: =IFERROR(F13/G13,0) -> 1.092732 | J13: =IFERROR(D13/サマリー!$B$8,0) -> 1.468973 | K13: =IFERROR(E13/サマリー!$B$8,0) -> 0.716491
A14: 12 | B14: =EDATE(サマリー!$B$14,12-1) -> 46296 | C14: =EOMONTH(B14,0) -> 46326 | D14: =SUMIFS(受注ログ!$C$6:$C$99901,受注ログ!$B$6:$B$99901,">="&B14,受注ログ!$B$6:$B$99901,"<="&C14) -> 939646 | E14: =SUMIFS(受注ログ!$D$6:$D$99901,受注ログ!$B$6:$B$99901,">="&B14,受注ログ!$B$6:$B$99901,"<="&C14) -> 581922 | F14: =D14+E14 -> 1521568 | G14: =サマリー!$B$16 -> 2000000 | H14: =F14-G14 -> -478432 | I14: =IFERROR(F14/G14,0) -> 0.760784 | J14: =IFERROR(D14/サマリー!$B$8,0) -> 0.939646 | K14: =IFERROR(E14/サマリー!$B$8,0) -> 0.581922
A15: 13 | B15: =EDATE(サマリー!$B$14,13-1) -> 46327 | C15: =EOMONTH(B15,0) -> 46356 | D15: =SUMIFS(受注ログ!$C$6:$C$99901,受注ログ!$B$6:$B$99901,">="&B15,受注ログ!$B$6:$B$99901,"<="&C15) -> 0 | E15: =SUMIFS(受注ログ!$D$6:$D$99901,受注ログ!$B$6:$B$99901,">="&B15,受注ログ!$B$6:$B$99901,"<="&C15) -> 0 | F15: =D15+E15 -> 0 | G15: =サマリー!$B$16 -> 2000000 | H15: =F15-G15 -> -2000000 | I15: =IFERROR(F15/G15,0) -> 0 | J15: =IFERROR(D15/サマリー!$B$8,0) -> 0 | K15: =IFERROR(E15/サマリー!$B$8,0) -> 0

Sheet 半期年間集計
A1: 半期・年間集計（予算はチーム月予算からの参考換算）
A2: 区分 | B2: 開始日 | C2: 終了日 | D2: 小原実績 | E2: 前園実績 | F2: チーム計 | G2: 参考予算 | H2: 差異 | I2: 達成率
A3: 上半期 | B3: =サマリー!$B$14 -> 45962 | C3: =EOMONTH(サマリー!$B$14,5) -> 46142 | D3: =SUMIFS(受注ログ!$C$6:$C$99901,受注ログ!$B$6:$B$99901,">="&B3,受注ログ!$B$6:$B$99901,"<="&C3) -> 0 | E3: =SUMIFS(受注ログ!$D$6:$D$99901,受注ログ!$B$6:$B$99901,">="&B3,受注ログ!$B$6:$B$99901,"<="&C3) -> 0 | F3: =D3+E3 -> 0 | G3: =サマリー!$B$17 -> 12000000 | H3: =F3-G3 -> -12000000 | I3: =IFERROR(F3/G3,0) -> 0
A4: 下半期 | B4: =EDATE(サマリー!$B$14,6) -> 46143 | C4: =EOMONTH(サマリー!$B$14,11) -> 46326 | D4: =SUMIFS(受注ログ!$C$6:$C$99901,受注ログ!$B$6:$B$99901,">="&B4,受注ログ!$B$6:$B$99901,"<="&C4) -> 6939150 | E4: =SUMIFS(受注ログ!$D$6:$D$99901,受注ログ!$B$6:$B$99901,">="&B4,受注ログ!$B$6:$B$99901,"<="&C4) -> 5320447 | F4: =D4+E4 -> 12259597 | G4: =サマリー!$B$17 -> 12000000 | H4: =F4-G4 -> 259597 | I4: =IFERROR(F4/G4,0) -> 1.0216331
A5: 年間 | B5: =サマリー!$B$14 -> 45962 | C5: =EOMONTH(サマリー!$B$14,11) -> 46326 | D5: =SUMIFS(受注ログ!$C$6:$C$99901,受注ログ!$B$6:$B$99901,">="&B5,受注ログ!$B$6:$B$99901,"<="&C5) -> 6939150 | E5: =SUMIFS(受注ログ!$D$6:$D$99901,受注ログ!$B$6:$B$99901,">="&B5,受注ログ!$B$6:$B$99901,"<="&C5) -> 5320447 | F5: =D5+E5 -> 12259597 | G5: =サマリー!$B$18 -> 24000000 | H5: =F5-G5 -> -11740403 | I5: =IFERROR(F5/G5,0) -> 0.51081654

Sheet 印刷用
A1: 店舗別 売上状況
A2: ="（"&TEXT(サマリー!$B$6,"yyyy/m/d")&" 時点）" -> （2026/10/25 時点）
A4: ■ 店舗別 売上（今週・今月）
A5: 店舗 | B5: 今週 | C5: 今月
A6: 大洲店 | B6: =SUMIFS(受注ログ!$L$6:$L$99901,受注ログ!$B$6:$B$99901,">="&INDEX(週次集計!$B$3:$B$56,サマリー!$B$20),受注ログ!$B$6:$B$99901,"<="&INDEX(週次集計!$C$3:$C$56,サマリー!$B$20)) -> 0 | C6: =サマリー!D53 -> 115526
A7: 西予店 | B7: =SUMIFS(受注ログ!$M$6:$M$99901,受注ログ!$B$6:$B$99901,">="&INDEX(週次集計!$B$3:$B$56,サマリー!$B$20),受注ログ!$B$6:$B$99901,"<="&INDEX(週次集計!$C$3:$C$56,サマリー!$B$20)) -> 0 | C7: =サマリー!D54 -> 3300
A8: 宇和島店 | B8: =SUMIFS(受注ログ!$N$6:$N$99901,受注ログ!$B$6:$B$99901,">="&INDEX(週次集計!$B$3:$B$56,サマリー!$B$20),受注ログ!$B$6:$B$99901,"<="&INDEX(週次集計!$C$3:$C$56,サマリー!$B$20)) -> 0 | C8: =サマリー!D55 -> 47760
A9: 新居浜店 | B9: =SUMIFS(受注ログ!$V$6:$V$99901,受注ログ!$B$6:$B$99901,">="&INDEX(週次集計!$B$3:$B$56,サマリー!$B$20),受注ログ!$B$6:$B$99901,"<="&INDEX(週次集計!$C$3:$C$56,サマリー!$B$20)) -> 0 | C9: =サマリー!D56 -> 49903
A11: ※ 個人の実績・予算は含めていません（店舗別の売上のみ表示）。
A12: ※「印刷用」シートを開いた状態でCtrl+P（印刷）を押すと、この内容だけがA4一枚で印刷されます。
