Workbook

Sheet サマリー
A1: ="売上ダッシュボード（"&B13&"）" -> 売上ダッシュボード（39期 夏期）
A3: ■ 入力項目（黄色セルのみ編集） 新しい期は B4・B5・B13 を変更するだけ
A4: 期の開始年 | B4: 2026
A5: 期の開始月 | B5: 11
A6: 本日の日付（自動） | B6: =TODAY() -> 46320
A7: 個人 週予算（1人あたり） | B7: 250000
A8: 個人 月予算（1人あたり） | B8: 1000000
A9: JET業務 単価（1件） | B9: 25000
A10: JONE200 単価 | B10: 7241
A11: JONE100 単価（未定の場合は0） | B11: 4379
A12: YTS 単価（1件） | B12: 30000
A13: 期の名称（表示用） | B13: 39期 夏期
A14: 期の開始日 | B14: =DATE(B4,B5,1) -> 46327
A15: チーム週予算（個人×2） | B15: =B7*2 -> 500000
A16: チーム月予算（個人×2） | B16: =B8*2 -> 2000000
A17: 半期予算（月予算×6・参考） | B17: =B16*6 -> 12000000
A18: 年間予算（月予算×12・参考） | B18: =B16*12 -> 24000000
A20: 現在の週番号（期の開始前は1） | B20: =MAX(1,MIN(54,INT((B6-(B14-WEEKDAY(B14,2)+1))/7)+1)) -> 1
A21: 現在の月番号（期の開始前は1） | B21: =MAX(1,MIN(13,(YEAR(B6)-YEAR(B14))*12+MONTH(B6)-MONTH(B14)+1)) -> 1
A22: 現在の半期区分 | B22: =IF(B21<=6,"上半期","下半期") -> 上半期
A24: ■ スタッフ別進捗（今週・今月）
A25: 対象 | B25: 予算 | C25: 実績 | D25: 達成率 | E25: 残り必要額
A26: 小原（今週） | B26: =B7 -> 250000 | C26: =INDEX(週次集計!D3:D56,$B$20) -> 0 | D26: =IFERROR(C26/B26,0) -> 0 | E26: =MAX(B26-C26,0) -> 250000
A27: 前園（今週） | B27: =B7 -> 250000 | C27: =INDEX(週次集計!E3:E56,$B$20) -> 0 | D27: =IFERROR(C27/B27,0) -> 0 | E27: =MAX(B27-C27,0) -> 250000
A28: 小原（今月） | B28: =B8 -> 1000000 | C28: =INDEX(月次集計!D3:D15,$B$21) -> 0 | D28: =IFERROR(C28/B28,0) -> 0 | E28: =MAX(B28-C28,0) -> 1000000
A29: 前園（今月） | B29: =B8 -> 1000000 | C29: =INDEX(月次集計!E3:E15,$B$21) -> 0 | D29: =IFERROR(C29/B29,0) -> 0 | E29: =MAX(B29-C29,0) -> 1000000
A32: ■ 優先度ダッシュボード（1日あたり必要額が大きいほど優先）
A33: 対象 | B33: 予算 | C33: 実績 | D33: 残り必要額 | E33: 期限 | F33: 残り日数 | G33: 1日あたり必要額 | H33: 優先度
A34: 小原（今週） | B34: =B7 -> 250000 | C34: =INDEX(週次集計!D3:D56,$B$20) -> 0 | D34: =MAX(B34-C34,0) -> 250000 | E34: =INDEX(週次集計!C3:C56,$B$20) -> 46327 | F34: =MAX(E34-$B$6+1,1) -> 8 | G34: =IFERROR(D34/F34,0) -> 31250 | H34: =RANK(G34,$G$34:$G$41) -> 5
A35: 前園（今週） | B35: =B7 -> 250000 | C35: =INDEX(週次集計!E3:E56,$B$20) -> 0 | D35: =MAX(B35-C35,0) -> 250000 | E35: =INDEX(週次集計!C3:C56,$B$20) -> 46327 | F35: =MAX(E35-$B$6+1,1) -> 8 | G35: =IFERROR(D35/F35,0) -> 31250 | H35: =RANK(G35,$G$34:$G$41) -> 5
A36: チーム（今週） | B36: =B15 -> 500000 | C36: =INDEX(週次集計!F3:F56,$B$20) -> 0 | D36: =MAX(B36-C36,0) -> 500000 | E36: =INDEX(週次集計!C3:C56,$B$20) -> 46327 | F36: =MAX(E36-$B$6+1,1) -> 8 | G36: =IFERROR(D36/F36,0) -> 62500 | H36: =RANK(G36,$G$34:$G$41) -> 3
A37: 小原（今月） | B37: =B8 -> 1000000 | C37: =INDEX(月次集計!D3:D15,$B$21) -> 0 | D37: =MAX(B37-C37,0) -> 1000000 | E37: =INDEX(月次集計!C3:C15,$B$21) -> 46356 | F37: =MAX(E37-$B$6+1,1) -> 37 | G37: =IFERROR(D37/F37,0) -> 27027.027 | H37: =RANK(G37,$G$34:$G$41) -> 7
A38: 前園（今月） | B38: =B8 -> 1000000 | C38: =INDEX(月次集計!E3:E15,$B$21) -> 0 | D38: =MAX(B38-C38,0) -> 1000000 | E38: =INDEX(月次集計!C3:C15,$B$21) -> 46356 | F38: =MAX(E38-$B$6+1,1) -> 37 | G38: =IFERROR(D38/F38,0) -> 27027.027 | H38: =RANK(G38,$G$34:$G$41) -> 7
A39: チーム（今月） | B39: =B16 -> 2000000 | C39: =INDEX(月次集計!F3:F15,$B$21) -> 0 | D39: =MAX(B39-C39,0) -> 2000000 | E39: =INDEX(月次集計!C3:C15,$B$21) -> 46356 | F39: =MAX(E39-$B$6+1,1) -> 37 | G39: =IFERROR(D39/F39,0) -> 54054.054 | H39: =RANK(G39,$G$34:$G$41) -> 4
A40: チーム（今半期） | B40: =B17 -> 12000000 | C40: =INDEX(半期年間集計!F3:F5,IF($B$22="上半期",1,2)) -> 0 | D40: =MAX(B40-C40,0) -> 12000000 | E40: =INDEX(半期年間集計!C3:C5,IF($B$22="上半期",1,2)) -> 46507 | F40: =MAX(E40-$B$6+1,1) -> 188 | G40: =IFERROR(D40/F40,0) -> 63829.787 | H40: =RANK(G40,$G$34:$G$41) -> 2
A41: チーム（今年） | B41: =B18 -> 24000000 | C41: =INDEX(半期年間集計!F3:F5,3) -> 0 | D41: =MAX(B41-C41,0) -> 24000000 | E41: =INDEX(半期年間集計!C3:C5,3) -> 46691 | F41: =MAX(E41-$B$6+1,1) -> 372 | G41: =IFERROR(D41/F41,0) -> 64516.129 | H41: =RANK(G41,$G$34:$G$41) -> 1
A43: ※「優先度」の1位は、残り必要額を残り日数で割った『1日あたり必要額』が最も大きい項目です。
A44: ※ 個人の月予算は1人100万円、チームは200万円（個人×2）。半期・年間はチーム月予算からの参考換算値です。
A45: ※ 週は月曜始まり。月をまたぐ週も前後月の実績を含めて集計します。
A46: ※【新しい期の作り方】このファイルをコピー → B4（開始年）・B5（開始月）・B13（期の名称）を変更 → 受注ログに入力開始。
...

Sheet 受注ログ
A1: 受注ログ（1行＝1受注。Aに日にちだけ入力→日付は自動。C〜Hで日別・本日の状況がすぐ分かります）
B2: 小原週残 | C2: 前園週残 | D2: チーム週実績 | E2: チーム週残 | F2: 小原本日 | G2: 前園本日 | H2: チーム本日
B3: =MAX(サマリー!$B$7-INDEX(週次集計!$D$3:$D$56,サマリー!$B$20),0) -> 250000 | C3: =MAX(サマリー!$B$7-INDEX(週次集計!$E$3:$E$56,サマリー!$B$20),0) -> 250000 | D3: =INDEX(週次集計!$F$3:$F$56,サマリー!$B$20) -> 0 | E3: =MAX(サマリー!$B$15-INDEX(週次集計!$F$3:$F$56,サマリー!$B$20),0) -> 500000 | F3: =SUMIFS($C$6:$C$100000,$B$6:$B$100000,TODAY()) -> 0 | G3: =SUMIFS($D$6:$D$100000,$B$6:$B$100000,TODAY()) -> 0 | H3: =F3+G3 -> 0
I4: 小原 | T4: 前園
A5: 日 | B5: 日付 | C5: 小原計 | D5: 前園計 | E5: 合計 | I5: 松山本店 | J5: 持込 | K5: 診断解決 | L5: RYTS | M5: 大洲店 | N5: 西予店 | O5: 宇和島店 | P5: サテライト | Q5: JET業務 (件数) | R5: JONE (100/200) | S5: YTS (件数) | T5: 松山本店 | U5: 持込 | V5: RYTS | W5: 新居浜店 | X5: サテライト | Y5: JET業務 (件数) | Z5: JONE (100/200) | AA5: YTS (件数)
B6: =IF(A6="",サマリー!$B$14,DATE(YEAR(サマリー!$B$14),MONTH(サマリー!$B$14),A6)) -> 46327 | C6: =I6+J6+K6+L6+M6+N6+O6+P6+IF(Q6="",0,Q6*サマリー!$B$9)+IF(R6="",0,IF(R6=200,サマリー!$B$10,IF(R6=100,サマリー!$B$11,0)))+IF(S6="",0,S6*サマリー!$B$12) -> 0 | D6: =T6+U6+V6+W6+X6+IF(Y6="",0,Y6*サマリー!$B$9)+IF(Z6="",0,IF(Z6=200,サマリー!$B$10,IF(Z6=100,サマリー!$B$11,0)))+IF(AA6="",0,AA6*サマリー!$B$12) -> 0 | E6: =C6+D6 -> 0
B7: =IF(A7="",B6,IF(A7<DAY(B6),DATE(YEAR(B6),MONTH(B6)+1,A7),DATE(YEAR(B6),MONTH(B6),A7))) -> 46327 | C7: =I7+J7+K7+L7+M7+N7+O7+P7+IF(Q7="",0,Q7*サマリー!$B$9)+IF(R7="",0,IF(R7=200,サマリー!$B$10,IF(R7=100,サマリー!$B$11,0)))+IF(S7="",0,S7*サマリー!$B$12) -> 0 | D7: =T7+U7+V7+W7+X7+IF(Y7="",0,Y7*サマリー!$B$9)+IF(Z7="",0,IF(Z7=200,サマリー!$B$10,IF(Z7=100,サマリー!$B$11,0)))+IF(AA7="",0,AA7*サマリー!$B$12) -> 0 | E7: =C7+D7 -> 0
B8: =IF(A8="",B7,IF(A8<DAY(B7),DATE(YEAR(B7),MONTH(B7)+1,A8),DATE(YEAR(B7),MONTH(B7),A8))) -> 46327 | C8: =I8+J8+K8+L8+M8+N8+O8+P8+IF(Q8="",0,Q8*サマリー!$B$9)+IF(R8="",0,IF(R8=200,サマリー!$B$10,IF(R8=100,サマリー!$B$11,0)))+IF(S8="",0,S8*サマリー!$B$12) -> 0 | D8: =T8+U8+V8+W8+X8+IF(Y8="",0,Y8*サマリー!$B$9)+IF(Z8="",0,IF(Z8=200,サマリー!$B$10,IF(Z8=100,サマリー!$B$11,0)))+IF(AA8="",0,AA8*サマリー!$B$12) -> 0 | E8: =C8+D8 -> 0
B9: =IF(A9="",B8,IF(A9<DAY(B8),DATE(YEAR(B8),MONTH(B8)+1,A9),DATE(YEAR(B8),MONTH(B8),A9))) -> 46327 | C9: =I9+J9+K9+L9+M9+N9+O9+P9+IF(Q9="",0,Q9*サマリー!$B$9)+IF(R9="",0,IF(R9=200,サマリー!$B$10,IF(R9=100,サマリー!$B$11,0)))+IF(S9="",0,S9*サマリー!$B$12) -> 0 | D9: =T9+U9+V9+W9+X9+IF(Y9="",0,Y9*サマリー!$B$9)+IF(Z9="",0,IF(Z9=200,サマリー!$B$10,IF(Z9=100,サマリー!$B$11,0)))+IF(AA9="",0,AA9*サマリー!$B$12) -> 0 | E9: =C9+D9 -> 0
B10: =IF(A10="",B9,IF(A10<DAY(B9),DATE(YEAR(B9),MONTH(B9)+1,A10),DATE(YEAR(B9),MONTH(B9),A10))) -> 46327 | C10: =I10+J10+K10+L10+M10+N10+O10+P10+IF(Q10="",0,Q10*サマリー!$B$9)+IF(R10="",0,IF(R10=200,サマリー!$B$10,IF(R10=100,サマリー!$B$11,0)))+IF(S10="",0,S10*サマリー!$B$12) -> 0 | D10: =T10+U10+V10+W10+X10+IF(Y10="",0,Y10*サマリー!$B$9)+IF(Z10="",0,IF(Z10=200,サマリー!$B$10,IF(Z10=100,サマリー!$B$11,0)))+IF(AA10="",0,AA10*サマリー!$B$12) -> 0 | E10: =C10+D10 -> 0
B11: =IF(A11="",B10,IF(A11<DAY(B10),DATE(YEAR(B10),MONTH(B10)+1,A11),DATE(YEAR(B10),MONTH(B10),A11))) -> 46327 | C11: =I11+J11+K11+L11+M11+N11+O11+P11+IF(Q11="",0,Q11*サマリー!$B$9)+IF(R11="",0,IF(R11=200,サマリー!$B$10,IF(R11=100,サマリー!$B$11,0)))+IF(S11="",0,S11*サマリー!$B$12) -> 0 | D11: =T11+U11+V11+W11+X11+IF(Y11="",0,Y11*サマリー!$B$9)+IF(Z11="",0,IF(Z11=200,サマリー!$B$10,IF(Z11=100,サマリー!$B$11,0)))+IF(AA11="",0,AA11*サマリー!$B$12) -> 0 | E11: =C11+D11 -> 0
B12: =IF(A12="",B11,IF(A12<DAY(B11),DATE(YEAR(B11),MONTH(B11)+1,A12),DATE(YEAR(B11),MONTH(B11),A12))) -> 46327 | C12: =I12+J12+K12+L12+M12+N12+O12+P12+IF(Q12="",0,Q12*サマリー!$B$9)+IF(R12="",0,IF(R12=200,サマリー!$B$10,IF(R12=100,サマリー!$B$11,0)))+IF(S12="",0,S12*サマリー!$B$12) -> 0 | D12: =T12+U12+V12+W12+X12+IF(Y12="",0,Y12*サマリー!$B$9)+IF(Z12="",0,IF(Z12=200,サマリー!$B$10,IF(Z12=100,サマリー!$B$11,0)))+IF(AA12="",0,AA12*サマリー!$B$12) -> 0 | E12: =C12+D12 -> 0
B13: =IF(A13="",B12,IF(A13<DAY(B12),DATE(YEAR(B12),MONTH(B12)+1,A13),DATE(YEAR(B12),MONTH(B12),A13))) -> 46327 | C13: =I13+J13+K13+L13+M13+N13+O13+P13+IF(Q13="",0,Q13*サマリー!$B$9)+IF(R13="",0,IF(R13=200,サマリー!$B$10,IF(R13=100,サマリー!$B$11,0)))+IF(S13="",0,S13*サマリー!$B$12) -> 0 | D13: =T13+U13+V13+W13+X13+IF(Y13="",0,Y13*サマリー!$B$9)+IF(Z13="",0,IF(Z13=200,サマリー!$B$10,IF(Z13=100,サマリー!$B$11,0)))+IF(AA13="",0,AA13*サマリー!$B$12) -> 0 | E13: =C13+D13 -> 0
B14: =IF(A14="",B13,IF(A14<DAY(B13),DATE(YEAR(B13),MONTH(B13)+1,A14),DATE(YEAR(B13),MONTH(B13),A14))) -> 46327 | C14: =I14+J14+K14+L14+M14+N14+O14+P14+IF(Q14="",0,Q14*サマリー!$B$9)+IF(R14="",0,IF(R14=200,サマリー!$B$10,IF(R14=100,サマリー!$B$11,0)))+IF(S14="",0,S14*サマリー!$B$12) -> 0 | D14: =T14+U14+V14+W14+X14+IF(Y14="",0,Y14*サマリー!$B$9)+IF(Z14="",0,IF(Z14=200,サマリー!$B$10,IF(Z14=100,サマリー!$B$11,0)))+IF(AA14="",0,AA14*サマリー!$B$12) -> 0 | E14: =C14+D14 -> 0
B15: =IF(A15="",B14,IF(A15<DAY(B14),DATE(YEAR(B14),MONTH(B14)+1,A15),DATE(YEAR(B14),MONTH(B14),A15))) -> 46327 | C15: =I15+J15+K15+L15+M15+N15+O15+P15+IF(Q15="",0,Q15*サマリー!$B$9)+IF(R15="",0,IF(R15=200,サマリー!$B$10,IF(R15=100,サマリー!$B$11,0)))+IF(S15="",0,S15*サマリー!$B$12) -> 0 | D15: =T15+U15+V15+W15+X15+IF(Y15="",0,Y15*サマリー!$B$9)+IF(Z15="",0,IF(Z15=200,サマリー!$B$10,IF(Z15=100,サマリー!$B$11,0)))+IF(AA15="",0,AA15*サマリー!$B$12) -> 0 | E15: =C15+D15 -> 0
B16: =IF(A16="",B15,IF(A16<DAY(B15),DATE(YEAR(B15),MONTH(B15)+1,A16),DATE(YEAR(B15),MONTH(B15),A16))) -> 46327 | C16: =I16+J16+K16+L16+M16+N16+O16+P16+IF(Q16="",0,Q16*サマリー!$B$9)+IF(R16="",0,IF(R16=200,サマリー!$B$10,IF(R16=100,サマリー!$B$11,0)))+IF(S16="",0,S16*サマリー!$B$12) -> 0 | D16: =T16+U16+V16+W16+X16+IF(Y16="",0,Y16*サマリー!$B$9)+IF(Z16="",0,IF(Z16=200,サマリー!$B$10,IF(Z16=100,サマリー!$B$11,0)))+IF(AA16="",0,AA16*サマリー!$B$12) -> 0 | E16: =C16+D16 -> 0
B17: =IF(A17="",B16,IF(A17<DAY(B16),DATE(YEAR(B16),MONTH(B16)+1,A17),DATE(YEAR(B16),MONTH(B16),A17))) -> 46327 | C17: =I17+J17+K17+L17+M17+N17+O17+P17+IF(Q17="",0,Q17*サマリー!$B$9)+IF(R17="",0,IF(R17=200,サマリー!$B$10,IF(R17=100,サマリー!$B$11,0)))+IF(S17="",0,S17*サマリー!$B$12) -> 0 | D17: =T17+U17+V17+W17+X17+IF(Y17="",0,Y17*サマリー!$B$9)+IF(Z17="",0,IF(Z17=200,サマリー!$B$10,IF(Z17=100,サマリー!$B$11,0)))+IF(AA17="",0,AA17*サマリー!$B$12) -> 0 | E17: =C17+D17 -> 0
B18: =IF(A18="",B17,IF(A18<DAY(B17),DATE(YEAR(B17),MONTH(B17)+1,A18),DATE(YEAR(B17),MONTH(B17),A18))) -> 46327 | C18: =I18+J18+K18+L18+M18+N18+O18+P18+IF(Q18="",0,Q18*サマリー!$B$9)+IF(R18="",0,IF(R18=200,サマリー!$B$10,IF(R18=100,サマリー!$B$11,0)))+IF(S18="",0,S18*サマリー!$B$12) -> 0 | D18: =T18+U18+V18+W18+X18+IF(Y18="",0,Y18*サマリー!$B$9)+IF(Z18="",0,IF(Z18=200,サマリー!$B$10,IF(Z18=100,サマリー!$B$11,0)))+IF(AA18="",0,AA18*サマリー!$B$12) -> 0 | E18: =C18+D18 -> 0
... B1505: =IF(A1505="",B1504,IF(A1505<DAY(B1504),DATE(YEAR(B1504),MONTH(B1504)+1,A1505),DATE(YEAR(B1504),MONTH(B1504),A1505))) -> 46327 | C1505: =I1505+J1505+K1505+L1505+M1505+N1505+O1505+P1505+IF(Q1505="",0,Q1505*サマリー!$B$9)+IF(R1505="",0,IF(R1505=200,サマリー!$B$10,IF(R1505=100,サマリー!$B$11,0)))+IF(S1505="",0,S1505*サマリー!$B$12) -> 0 | D1505: =T1505+U1505+V1505+W1505+X1505+IF(Y1505="",0,Y1505*サマリー!$B$9)+IF(Z1505="",0,IF(Z1505=200,サマリー!$B$10,IF(Z1505=100,サマリー!$B$11,0)))+IF(AA1505="",0,AA1505*サマリー!$B$12) -> 0 | E1505: =C1505+D1505 -> 0
A1507: ※ A列（日にちだけ）に数字を入れると、B列の日付が自動計算されます。空欄なら上の行と同じ日付です（月またぎも自動判定）。
A1508: ※ 実際に入力されたセルには自動で緑色、次に入力する行にはオレンジ色が付きます。
A1509: ※ 松山本店・持込・RYTSの3列合計が「松山本店の売上」です。診断解決は小原のみ別列で入力します。
A1510: ※ 小原は新居浜店、前園は大洲店・西予店・宇和島店の列がありません（担当外のため）。
A1511: ※ JET業務・JONE・YTSは件数/コードを入力すると、小原計/前園計に自動で金額換算されます（単価はサマリーで変更）。
A1512: ※ 行が足りなくなったら、一番下の行を選んで下にドラッグして増やしてください（集計は10万行目まで自動で含まれます）。

Sheet 週次集計
A1: 週次集計（月曜始まり・月またぎ含む）
A2: 週番号 | B2: 開始日 | C2: 終了日 | D2: 小原実績 | E2: 前園実績 | F2: チーム計 | G2: チーム週予算 | H2: 差異 | I2: 達成率 | J2: 小原達成率 | K2: 前園達成率
A3: 1 | B3: =サマリー!$B$14-WEEKDAY(サマリー!$B$14,2)+1+(1-1)*7 -> 46321 | C3: =B3+6 -> 46327 | D3: =SUMIFS(受注ログ!$C$6:$C$100000,受注ログ!$B$6:$B$100000,">="&B3,受注ログ!$B$6:$B$100000,"<="&C3) -> 0 | E3: =SUMIFS(受注ログ!$D$6:$D$100000,受注ログ!$B$6:$B$100000,">="&B3,受注ログ!$B$6:$B$100000,"<="&C3) -> 0 | F3: =D3+E3 -> 0 | G3: =サマリー!$B$15 -> 500000 | H3: =F3-G3 -> -500000 | I3: =IFERROR(F3/G3,0) -> 0 | J3: =IFERROR(D3/サマリー!$B$7,0) -> 0 | K3: =IFERROR(E3/サマリー!$B$7,0) -> 0
A4: 2 | B4: =サマリー!$B$14-WEEKDAY(サマリー!$B$14,2)+1+(2-1)*7 -> 46328 | C4: =B4+6 -> 46334 | D4: =SUMIFS(受注ログ!$C$6:$C$100000,受注ログ!$B$6:$B$100000,">="&B4,受注ログ!$B$6:$B$100000,"<="&C4) -> 0 | E4: =SUMIFS(受注ログ!$D$6:$D$100000,受注ログ!$B$6:$B$100000,">="&B4,受注ログ!$B$6:$B$100000,"<="&C4) -> 0 | F4: =D4+E4 -> 0 | G4: =サマリー!$B$15 -> 500000 | H4: =F4-G4 -> -500000 | I4: =IFERROR(F4/G4,0) -> 0 | J4: =IFERROR(D4/サマリー!$B$7,0) -> 0 | K4: =IFERROR(E4/サマリー!$B$7,0) -> 0
A5: 3 | B5: =サマリー!$B$14-WEEKDAY(サマリー!$B$14,2)+1+(3-1)*7 -> 46335 | C5: =B5+6 -> 46341 | D5: =SUMIFS(受注ログ!$C$6:$C$100000,受注ログ!$B$6:$B$100000,">="&B5,受注ログ!$B$6:$B$100000,"<="&C5) -> 0 | E5: =SUMIFS(受注ログ!$D$6:$D$100000,受注ログ!$B$6:$B$100000,">="&B5,受注ログ!$B$6:$B$100000,"<="&C5) -> 0 | F5: =D5+E5 -> 0 | G5: =サマリー!$B$15 -> 500000 | H5: =F5-G5 -> -500000 | I5: =IFERROR(F5/G5,0) -> 0 | J5: =IFERROR(D5/サマリー!$B$7,0) -> 0 | K5: =IFERROR(E5/サマリー!$B$7,0) -> 0
A6: 4 | B6: =サマリー!$B$14-WEEKDAY(サマリー!$B$14,2)+1+(4-1)*7 -> 46342 | C6: =B6+6 -> 46348 | D6: =SUMIFS(受注ログ!$C$6:$C$100000,受注ログ!$B$6:$B$100000,">="&B6,受注ログ!$B$6:$B$100000,"<="&C6) -> 0 | E6: =SUMIFS(受注ログ!$D$6:$D$100000,受注ログ!$B$6:$B$100000,">="&B6,受注ログ!$B$6:$B$100000,"<="&C6) -> 0 | F6: =D6+E6 -> 0 | G6: =サマリー!$B$15 -> 500000 | H6: =F6-G6 -> -500000 | I6: =IFERROR(F6/G6,0) -> 0 | J6: =IFERROR(D6/サマリー!$B$7,0) -> 0 | K6: =IFERROR(E6/サマリー!$B$7,0) -> 0
A7: 5 | B7: =サマリー!$B$14-WEEKDAY(サマリー!$B$14,2)+1+(5-1)*7 -> 46349 | C7: =B7+6 -> 46355 | D7: =SUMIFS(受注ログ!$C$6:$C$100000,受注ログ!$B$6:$B$100000,">="&B7,受注ログ!$B$6:$B$100000,"<="&C7) -> 0 | E7: =SUMIFS(受注ログ!$D$6:$D$100000,受注ログ!$B$6:$B$100000,">="&B7,受注ログ!$B$6:$B$100000,"<="&C7) -> 0 | F7: =D7+E7 -> 0 | G7: =サマリー!$B$15 -> 500000 | H7: =F7-G7 -> -500000 | I7: =IFERROR(F7/G7,0) -> 0 | J7: =IFERROR(D7/サマリー!$B$7,0) -> 0 | K7: =IFERROR(E7/サマリー!$B$7,0) -> 0
A8: 6 | B8: =サマリー!$B$14-WEEKDAY(サマリー!$B$14,2)+1+(6-1)*7 -> 46356 | C8: =B8+6 -> 46362 | D8: =SUMIFS(受注ログ!$C$6:$C$100000,受注ログ!$B$6:$B$100000,">="&B8,受注ログ!$B$6:$B$100000,"<="&C8) -> 0 | E8: =SUMIFS(受注ログ!$D$6:$D$100000,受注ログ!$B$6:$B$100000,">="&B8,受注ログ!$B$6:$B$100000,"<="&C8) -> 0 | F8: =D8+E8 -> 0 | G8: =サマリー!$B$15 -> 500000 | H8: =F8-G8 -> -500000 | I8: =IFERROR(F8/G8,0) -> 0 | J8: =IFERROR(D8/サマリー!$B$7,0) -> 0 | K8: =IFERROR(E8/サマリー!$B$7,0) -> 0
A9: 7 | B9: =サマリー!$B$14-WEEKDAY(サマリー!$B$14,2)+1+(7-1)*7 -> 46363 | C9: =B9+6 -> 46369 | D9: =SUMIFS(受注ログ!$C$6:$C$100000,受注ログ!$B$6:$B$100000,">="&B9,受注ログ!$B$6:$B$100000,"<="&C9) -> 0 | E9: =SUMIFS(受注ログ!$D$6:$D$100000,受注ログ!$B$6:$B$100000,">="&B9,受注ログ!$B$6:$B$100000,"<="&C9) -> 0 | F9: =D9+E9 -> 0 | G9: =サマリー!$B$15 -> 500000 | H9: =F9-G9 -> -500000 | I9: =IFERROR(F9/G9,0) -> 0 | J9: =IFERROR(D9/サマリー!$B$7,0) -> 0 | K9: =IFERROR(E9/サマリー!$B$7,0) -> 0
A10: 8 | B10: =サマリー!$B$14-WEEKDAY(サマリー!$B$14,2)+1+(8-1)*7 -> 46370 | C10: =B10+6 -> 46376 | D10: =SUMIFS(受注ログ!$C$6:$C$100000,受注ログ!$B$6:$B$100000,">="&B10,受注ログ!$B$6:$B$100000,"<="&C10) -> 0 | E10: =SUMIFS(受注ログ!$D$6:$D$100000,受注ログ!$B$6:$B$100000,">="&B10,受注ログ!$B$6:$B$100000,"<="&C10) -> 0 | F10: =D10+E10 -> 0 | G10: =サマリー!$B$15 -> 500000 | H10: =F10-G10 -> -500000 | I10: =IFERROR(F10/G10,0) -> 0 | J10: =IFERROR(D10/サマリー!$B$7,0) -> 0 | K10: =IFERROR(E10/サマリー!$B$7,0) -> 0
A11: 9 | B11: =サマリー!$B$14-WEEKDAY(サマリー!$B$14,2)+1+(9-1)*7 -> 46377 | C11: =B11+6 -> 46383 | D11: =SUMIFS(受注ログ!$C$6:$C$100000,受注ログ!$B$6:$B$100000,">="&B11,受注ログ!$B$6:$B$100000,"<="&C11) -> 0 | E11: =SUMIFS(受注ログ!$D$6:$D$100000,受注ログ!$B$6:$B$100000,">="&B11,受注ログ!$B$6:$B$100000,"<="&C11) -> 0 | F11: =D11+E11 -> 0 | G11: =サマリー!$B$15 -> 500000 | H11: =F11-G11 -> -500000 | I11: =IFERROR(F11/G11,0) -> 0 | J11: =IFERROR(D11/サマリー!$B$7,0) -> 0 | K11: =IFERROR(E11/サマリー!$B$7,0) -> 0
A12: 10 | B12: =サマリー!$B$14-WEEKDAY(サマリー!$B$14,2)+1+(10-1)*7 -> 46384 | C12: =B12+6 -> 46390 | D12: =SUMIFS(受注ログ!$C$6:$C$100000,受注ログ!$B$6:$B$100000,">="&B12,受注ログ!$B$6:$B$100000,"<="&C12) -> 0 | E12: =SUMIFS(受注ログ!$D$6:$D$100000,受注ログ!$B$6:$B$100000,">="&B12,受注ログ!$B$6:$B$100000,"<="&C12) -> 0 | F12: =D12+E12 -> 0 | G12: =サマリー!$B$15 -> 500000 | H12: =F12-G12 -> -500000 | I12: =IFERROR(F12/G12,0) -> 0 | J12: =IFERROR(D12/サマリー!$B$7,0) -> 0 | K12: =IFERROR(E12/サマリー!$B$7,0) -> 0
A13: 11 | B13: =サマリー!$B$14-WEEKDAY(サマリー!$B$14,2)+1+(11-1)*7 -> 46391 | C13: =B13+6 -> 46397 | D13: =SUMIFS(受注ログ!$C$6:$C$100000,受注ログ!$B$6:$B$100000,">="&B13,受注ログ!$B$6:$B$100000,"<="&C13) -> 0 | E13: =SUMIFS(受注ログ!$D$6:$D$100000,受注ログ!$B$6:$B$100000,">="&B13,受注ログ!$B$6:$B$100000,"<="&C13) -> 0 | F13: =D13+E13 -> 0 | G13: =サマリー!$B$15 -> 500000 | H13: =F13-G13 -> -500000 | I13: =IFERROR(F13/G13,0) -> 0 | J13: =IFERROR(D13/サマリー!$B$7,0) -> 0 | K13: =IFERROR(E13/サマリー!$B$7,0) -> 0
A14: 12 | B14: =サマリー!$B$14-WEEKDAY(サマリー!$B$14,2)+1+(12-1)*7 -> 46398 | C14: =B14+6 -> 46404 | D14: =SUMIFS(受注ログ!$C$6:$C$100000,受注ログ!$B$6:$B$100000,">="&B14,受注ログ!$B$6:$B$100000,"<="&C14) -> 0 | E14: =SUMIFS(受注ログ!$D$6:$D$100000,受注ログ!$B$6:$B$100000,">="&B14,受注ログ!$B$6:$B$100000,"<="&C14) -> 0 | F14: =D14+E14 -> 0 | G14: =サマリー!$B$15 -> 500000 | H14: =F14-G14 -> -500000 | I14: =IFERROR(F14/G14,0) -> 0 | J14: =IFERROR(D14/サマリー!$B$7,0) -> 0 | K14: =IFERROR(E14/サマリー!$B$7,0) -> 0
A15: 13 | B15: =サマリー!$B$14-WEEKDAY(サマリー!$B$14,2)+1+(13-1)*7 -> 46405 | C15: =B15+6 -> 46411 | D15: =SUMIFS(受注ログ!$C$6:$C$100000,受注ログ!$B$6:$B$100000,">="&B15,受注ログ!$B$6:$B$100000,"<="&C15) -> 0 | E15: =SUMIFS(受注ログ!$D$6:$D$100000,受注ログ!$B$6:$B$100000,">="&B15,受注ログ!$B$6:$B$100000,"<="&C15) -> 0 | F15: =D15+E15 -> 0 | G15: =サマリー!$B$15 -> 500000 | H15: =F15-G15 -> -500000 | I15: =IFERROR(F15/G15,0) -> 0 | J15: =IFERROR(D15/サマリー!$B$7,0) -> 0 | K15: =IFERROR(E15/サマリー!$B$7,0) -> 0
A16: 14 | B16: =サマリー!$B$14-WEEKDAY(サマリー!$B$14,2)+1+(14-1)*7 -> 46412 | C16: =B16+6 -> 46418 | D16: =SUMIFS(受注ログ!$C$6:$C$100000,受注ログ!$B$6:$B$100000,">="&B16,受注ログ!$B$6:$B$100000,"<="&C16) -> 0 | E16: =SUMIFS(受注ログ!$D$6:$D$100000,受注ログ!$B$6:$B$100000,">="&B16,受注ログ!$B$6:$B$100000,"<="&C16) -> 0 | F16: =D16+E16 -> 0 | G16: =サマリー!$B$15 -> 500000 | H16: =F16-G16 -> -500000 | I16: =IFERROR(F16/G16,0) -> 0 | J16: =IFERROR(D16/サマリー!$B$7,0) -> 0 | K16: =IFERROR(E16/サマリー!$B$7,0) -> 0
A17: 15 | B17: =サマリー!$B$14-WEEKDAY(サマリー!$B$14,2)+1+(15-1)*7 -> 46419 | C17: =B17+6 -> 46425 | D17: =SUMIFS(受注ログ!$C$6:$C$100000,受注ログ!$B$6:$B$100000,">="&B17,受注ログ!$B$6:$B$100000,"<="&C17) -> 0 | E17: =SUMIFS(受注ログ!$D$6:$D$100000,受注ログ!$B$6:$B$100000,">="&B17,受注ログ!$B$6:$B$100000,"<="&C17) -> 0 | F17: =D17+E17 -> 0 | G17: =サマリー!$B$15 -> 500000 | H17: =F17-G17 -> -500000 | I17: =IFERROR(F17/G17,0) -> 0 | J17: =IFERROR(D17/サマリー!$B$7,0) -> 0 | K17: =IFERROR(E17/サマリー!$B$7,0) -> 0
A18: 16 | B18: =サマリー!$B$14-WEEKDAY(サマリー!$B$14,2)+1+(16-1)*7 -> 46426 | C18: =B18+6 -> 46432 | D18: =SUMIFS(受注ログ!$C$6:$C$100000,受注ログ!$B$6:$B$100000,">="&B18,受注ログ!$B$6:$B$100000,"<="&C18) -> 0 | E18: =SUMIFS(受注ログ!$D$6:$D$100000,受注ログ!$B$6:$B$100000,">="&B18,受注ログ!$B$6:$B$100000,"<="&C18) -> 0 | F18: =D18+E18 -> 0 | G18: =サマリー!$B$15 -> 500000 | H18: =F18-G18 -> -500000 | I18: =IFERROR(F18/G18,0) -> 0 | J18: =IFERROR(D18/サマリー!$B$7,0) -> 0 | K18: =IFERROR(E18/サマリー!$B$7,0) -> 0
A19: 17 | B19: =サマリー!$B$14-WEEKDAY(サマリー!$B$14,2)+1+(17-1)*7 -> 46433 | C19: =B19+6 -> 46439 | D19: =SUMIFS(受注ログ!$C$6:$C$100000,受注ログ!$B$6:$B$100000,">="&B19,受注ログ!$B$6:$B$100000,"<="&C19) -> 0 | E19: =SUMIFS(受注ログ!$D$6:$D$100000,受注ログ!$B$6:$B$100000,">="&B19,受注ログ!$B$6:$B$100000,"<="&C19) -> 0 | F19: =D19+E19 -> 0 | G19: =サマリー!$B$15 -> 500000 | H19: =F19-G19 -> -500000 | I19: =IFERROR(F19/G19,0) -> 0 | J19: =IFERROR(D19/サマリー!$B$7,0) -> 0 | K19: =IFERROR(E19/サマリー!$B$7,0) -> 0
A20: 18 | B20: =サマリー!$B$14-WEEKDAY(サマリー!$B$14,2)+1+(18-1)*7 -> 46440 | C20: =B20+6 -> 46446 | D20: =SUMIFS(受注ログ!$C$6:$C$100000,受注ログ!$B$6:$B$100000,">="&B20,受注ログ!$B$6:$B$100000,"<="&C20) -> 0 | E20: =SUMIFS(受注ログ!$D$6:$D$100000,受注ログ!$B$6:$B$100000,">="&B20,受注ログ!$B$6:$B$100000,"<="&C20) -> 0 | F20: =D20+E20 -> 0 | G20: =サマリー!$B$15 -> 500000 | H20: =F20-G20 -> -500000 | I20: =IFERROR(F20/G20,0) -> 0 | J20: =IFERROR(D20/サマリー!$B$7,0) -> 0 | K20: =IFERROR(E20/サマリー!$B$7,0) -> 0
A21: 19 | B21: =サマリー!$B$14-WEEKDAY(サマリー!$B$14,2)+1+(19-1)*7 -> 46447 | C21: =B21+6 -> 46453 | D21: =SUMIFS(受注ログ!$C$6:$C$100000,受注ログ!$B$6:$B$100000,">="&B21,受注ログ!$B$6:$B$100000,"<="&C21) -> 0 | E21: =SUMIFS(受注ログ!$D$6:$D$100000,受注ログ!$B$6:$B$100000,">="&B21,受注ログ!$B$6:$B$100000,"<="&C21) -> 0 | F21: =D21+E21 -> 0 | G21: =サマリー!$B$15 -> 500000 | H21: =F21-G21 -> -500000 | I21: =IFERROR(F21/G21,0) -> 0 | J21: =IFERROR(D21/サマリー!$B$7,0) -> 0 | K21: =IFERROR(E21/サマリー!$B$7,0) -> 0
A22: 20 | B22: =サマリー!$B$14-WEEKDAY(サマリー!$B$14,2)+1+(20-1)*7 -> 46454 | C22: =B22+6 -> 46460 | D22: =SUMIFS(受注ログ!$C$6:$C$100000,受注ログ!$B$6:$B$100000,">="&B22,受注ログ!$B$6:$B$100000,"<="&C22) -> 0 | E22: =SUMIFS(受注ログ!$D$6:$D$100000,受注ログ!$B$6:$B$100000,">="&B22,受注ログ!$B$6:$B$100000,"<="&C22) -> 0 | F22: =D22+E22 -> 0 | G22: =サマリー!$B$15 -> 500000 | H22: =F22-G22 -> -500000 | I22: =IFERROR(F22/G22,0) -> 0 | J22: =IFERROR(D22/サマリー!$B$7,0) -> 0 | K22: =IFERROR(E22/サマリー!$B$7,0) -> 0
A23: 21 | B23: =サマリー!$B$14-WEEKDAY(サマリー!$B$14,2)+1+(21-1)*7 -> 46461 | C23: =B23+6 -> 46467 | D23: =SUMIFS(受注ログ!$C$6:$C$100000,受注ログ!$B$6:$B$100000,">="&B23,受注ログ!$B$6:$B$100000,"<="&C23) -> 0 | E23: =SUMIFS(受注ログ!$D$6:$D$100000,受注ログ!$B$6:$B$100000,">="&B23,受注ログ!$B$6:$B$100000,"<="&C23) -> 0 | F23: =D23+E23 -> 0 | G23: =サマリー!$B$15 -> 500000 | H23: =F23-G23 -> -500000 | I23: =IFERROR(F23/G23,0) -> 0 | J23: =IFERROR(D23/サマリー!$B$7,0) -> 0 | K23: =IFERROR(E23/サマリー!$B$7,0) -> 0
A24: 22 | B24: =サマリー!$B$14-WEEKDAY(サマリー!$B$14,2)+1+(22-1)*7 -> 46468 | C24: =B24+6 -> 46474 | D24: =SUMIFS(受注ログ!$C$6:$C$100000,受注ログ!$B$6:$B$100000,">="&B24,受注ログ!$B$6:$B$100000,"<="&C24) -> 0 | E24: =SUMIFS(受注ログ!$D$6:$D$100000,受注ログ!$B$6:$B$100000,">="&B24,受注ログ!$B$6:$B$100000,"<="&C24) -> 0 | F24: =D24+E24 -> 0 | G24: =サマリー!$B$15 -> 500000 | H24: =F24-G24 -> -500000 | I24: =IFERROR(F24/G24,0) -> 0 | J24: =IFERROR(D24/サマリー!$B$7,0) -> 0 | K24: =IFERROR(E24/サマリー!$B$7,0) -> 0
A25: 23 | B25: =サマリー!$B$14-WEEKDAY(サマリー!$B$14,2)+1+(23-1)*7 -> 46475 | C25: =B25+6 -> 46481 | D25: =SUMIFS(受注ログ!$C$6:$C$100000,受注ログ!$B$6:$B$100000,">="&B25,受注ログ!$B$6:$B$100000,"<="&C25) -> 0 | E25: =SUMIFS(受注ログ!$D$6:$D$100000,受注ログ!$B$6:$B$100000,">="&B25,受注ログ!$B$6:$B$100000,"<="&C25) -> 0 | F25: =D25+E25 -> 0 | G25: =サマリー!$B$15 -> 500000 | H25: =F25-G25 -> -500000 | I25: =IFERROR(F25/G25,0) -> 0 | J25: =IFERROR(D25/サマリー!$B$7,0) -> 0 | K25: =IFERROR(E25/サマリー!$B$7,0) -> 0
A26: 24 | B26: =サマリー!$B$14-WEEKDAY(サマリー!$B$14,2)+1+(24-1)*7 -> 46482 | C26: =B26+6 -> 46488 | D26: =SUMIFS(受注ログ!$C$6:$C$100000,受注ログ!$B$6:$B$100000,">="&B26,受注ログ!$B$6:$B$100000,"<="&C26) -> 0 | E26: =SUMIFS(受注ログ!$D$6:$D$100000,受注ログ!$B$6:$B$100000,">="&B26,受注ログ!$B$6:$B$100000,"<="&C26) -> 0 | F26: =D26+E26 -> 0 | G26: =サマリー!$B$15 -> 500000 | H26: =F26-G26 -> -500000 | I26: =IFERROR(F26/G26,0) -> 0 | J26: =IFERROR(D26/サマリー!$B$7,0) -> 0 | K26: =IFERROR(E26/サマリー!$B$7,0) -> 0
A27: 25 | B27: =サマリー!$B$14-WEEKDAY(サマリー!$B$14,2)+1+(25-1)*7 -> 46489 | C27: =B27+6 -> 46495 | D27: =SUMIFS(受注ログ!$C$6:$C$100000,受注ログ!$B$6:$B$100000,">="&B27,受注ログ!$B$6:$B$100000,"<="&C27) -> 0 | E27: =SUMIFS(受注ログ!$D$6:$D$100000,受注ログ!$B$6:$B$100000,">="&B27,受注ログ!$B$6:$B$100000,"<="&C27) -> 0 | F27: =D27+E27 -> 0 | G27: =サマリー!$B$15 -> 500000 | H27: =F27-G27 -> -500000 | I27: =IFERROR(F27/G27,0) -> 0 | J27: =IFERROR(D27/サマリー!$B$7,0) -> 0 | K27: =IFERROR(E27/サマリー!$B$7,0) -> 0
A28: 26 | B28: =サマリー!$B$14-WEEKDAY(サマリー!$B$14,2)+1+(26-1)*7 -> 46496 | C28: =B28+6 -> 46502 | D28: =SUMIFS(受注ログ!$C$6:$C$100000,受注ログ!$B$6:$B$100000,">="&B28,受注ログ!$B$6:$B$100000,"<="&C28) -> 0 | E28: =SUMIFS(受注ログ!$D$6:$D$100000,受注ログ!$B$6:$B$100000,">="&B28,受注ログ!$B$6:$B$100000,"<="&C28) -> 0 | F28: =D28+E28 -> 0 | G28: =サマリー!$B$15 -> 500000 | H28: =F28-G28 -> -500000 | I28: =IFERROR(F28/G28,0) -> 0 | J28: =IFERROR(D28/サマリー!$B$7,0) -> 0 | K28: =IFERROR(E28/サマリー!$B$7,0) -> 0
A29: 27 | B29: =サマリー!$B$14-WEEKDAY(サマリー!$B$14,2)+1+(27-1)*7 -> 46503 | C29: =B29+6 -> 46509 | D29: =SUMIFS(受注ログ!$C$6:$C$100000,受注ログ!$B$6:$B$100000,">="&B29,受注ログ!$B$6:$B$100000,"<="&C29) -> 0 | E29: =SUMIFS(受注ログ!$D$6:$D$100000,受注ログ!$B$6:$B$100000,">="&B29,受注ログ!$B$6:$B$100000,"<="&C29) -> 0 | F29: =D29+E29 -> 0 | G29: =サマリー!$B$15 -> 500000 | H29: =F29-G29 -> -500000 | I29: =IFERROR(F29/G29,0) -> 0 | J29: =IFERROR(D29/サマリー!$B$7,0) -> 0 | K29: =IFERROR(E29/サマリー!$B$7,0) -> 0
A30: 28 | B30: =サマリー!$B$14-WEEKDAY(サマリー!$B$14,2)+1+(28-1)*7 -> 46510 | C30: =B30+6 -> 46516 | D30: =SUMIFS(受注ログ!$C$6:$C$100000,受注ログ!$B$6:$B$100000,">="&B30,受注ログ!$B$6:$B$100000,"<="&C30) -> 0 | E30: =SUMIFS(受注ログ!$D$6:$D$100000,受注ログ!$B$6:$B$100000,">="&B30,受注ログ!$B$6:$B$100000,"<="&C30) -> 0 | F30: =D30+E30 -> 0 | G30: =サマリー!$B$15 -> 500000 | H30: =F30-G30 -> -500000 | I30: =IFERROR(F30/G30,0) -> 0 | J30: =IFERROR(D30/サマリー!$B$7,0) -> 0 | K30: =IFERROR(E30/サマリー!$B$7,0) -> 0
A31: 29 | B31: =サマリー!$B$14-WEEKDAY(サマリー!$B$14,2)+1+(29-1)*7 -> 46517 | C31: =B31+6 -> 46523 | D31: =SUMIFS(受注ログ!$C$6:$C$100000,受注ログ!$B$6:$B$100000,">="&B31,受注ログ!$B$6:$B$100000,"<="&C31) -> 0 | E31: =SUMIFS(受注ログ!$D$6:$D$100000,受注ログ!$B$6:$B$100000,">="&B31,受注ログ!$B$6:$B$100000,"<="&C31) -> 0 | F31: =D31+E31 -> 0 | G31: =サマリー!$B$15 -> 500000 | H31: =F31-G31 -> -500000 | I31: =IFERROR(F31/G31,0) -> 0 | J31: =IFERROR(D31/サマリー!$B$7,0) -> 0 | K31: =IFERROR(E31/サマリー!$B$7,0) -> 0
A32: 30 | B32: =サマリー!$B$14-WEEKDAY(サマリー!$B$14,2)+1+(30-1)*7 -> 46524 | C32: =B32+6 -> 46530 | D32: =SUMIFS(受注ログ!$C$6:$C$100000,受注ログ!$B$6:$B$100000,">="&B32,受注ログ!$B$6:$B$100000,"<="&C32) -> 0 | E32: =SUMIFS(受注ログ!$D$6:$D$100000,受注ログ!$B$6:$B$100000,">="&B32,受注ログ!$B$6:$B$100000,"<="&C32) -> 0 | F32: =D32+E32 -> 0 | G32: =サマリー!$B$15 -> 500000 | H32: =F32-G32 -> -500000 | I32: =IFERROR(F32/G32,0) -> 0 | J32: =IFERROR(D32/サマリー!$B$7,0) -> 0 | K32: =IFERROR(E32/サマリー!$B$7,0) -> 0
A33: 31 | B33: =サマリー!$B$14-WEEKDAY(サマリー!$B$14,2)+1+(31-1)*7 -> 46531 | C33: =B33+6 -> 46537 | D33: =SUMIFS(受注ログ!$C$6:$C$100000,受注ログ!$B$6:$B$100000,">="&B33,受注ログ!$B$6:$B$100000,"<="&C33) -> 0 | E33: =SUMIFS(受注ログ!$D$6:$D$100000,受注ログ!$B$6:$B$100000,">="&B33,受注ログ!$B$6:$B$100000,"<="&C33) -> 0 | F33: =D33+E33 -> 0 | G33: =サマリー!$B$15 -> 500000 | H33: =F33-G33 -> -500000 | I33: =IFERROR(F33/G33,0) -> 0 | J33: =IFERROR(D33/サマリー!$B$7,0) -> 0 | K33: =IFERROR(E33/サマリー!$B$7,0) -> 0
A34: 32 | B34: =サマリー!$B$14-WEEKDAY(サマリー!$B$14,2)+1+(32-1)*7 -> 46538 | C34: =B34+6 -> 46544 | D34: =SUMIFS(受注ログ!$C$6:$C$100000,受注ログ!$B$6:$B$100000,">="&B34,受注ログ!$B$6:$B$100000,"<="&C34) -> 0 | E34: =SUMIFS(受注ログ!$D$6:$D$100000,受注ログ!$B$6:$B$100000,">="&B34,受注ログ!$B$6:$B$100000,"<="&C34) -> 0 | F34: =D34+E34 -> 0 | G34: =サマリー!$B$15 -> 500000 | H34: =F34-G34 -> -500000 | I34: =IFERROR(F34/G34,0) -> 0 | J34: =IFERROR(D34/サマリー!$B$7,0) -> 0 | K34: =IFERROR(E34/サマリー!$B$7,0) -> 0
A35: 33 | B35: =サマリー!$B$14-WEEKDAY(サマリー!$B$14,2)+1+(33-1)*7 -> 46545 | C35: =B35+6 -> 46551 | D35: =SUMIFS(受注ログ!$C$6:$C$100000,受注ログ!$B$6:$B$100000,">="&B35,受注ログ!$B$6:$B$100000,"<="&C35) -> 0 | E35: =SUMIFS(受注ログ!$D$6:$D$100000,受注ログ!$B$6:$B$100000,">="&B35,受注ログ!$B$6:$B$100000,"<="&C35) -> 0 | F35: =D35+E35 -> 0 | G35: =サマリー!$B$15 -> 500000 | H35: =F35-G35 -> -500000 | I35: =IFERROR(F35/G35,0) -> 0 | J35: =IFERROR(D35/サマリー!$B$7,0) -> 0 | K35: =IFERROR(E35/サマリー!$B$7,0) -> 0
A36: 34 | B36: =サマリー!$B$14-WEEKDAY(サマリー!$B$14,2)+1+(34-1)*7 -> 46552 | C36: =B36+6 -> 46558 | D36: =SUMIFS(受注ログ!$C$6:$C$100000,受注ログ!$B$6:$B$100000,">="&B36,受注ログ!$B$6:$B$100000,"<="&C36) -> 0 | E36: =SUMIFS(受注ログ!$D$6:$D$100000,受注ログ!$B$6:$B$100000,">="&B36,受注ログ!$B$6:$B$100000,"<="&C36) -> 0 | F36: =D36+E36 -> 0 | G36: =サマリー!$B$15 -> 500000 | H36: =F36-G36 -> -500000 | I36: =IFERROR(F36/G36,0) -> 0 | J36: =IFERROR(D36/サマリー!$B$7,0) -> 0 | K36: =IFERROR(E36/サマリー!$B$7,0) -> 0
A37: 35 | B37: =サマリー!$B$14-WEEKDAY(サマリー!$B$14,2)+1+(35-1)*7 -> 46559 | C37: =B37+6 -> 46565 | D37: =SUMIFS(受注ログ!$C$6:$C$100000,受注ログ!$B$6:$B$100000,">="&B37,受注ログ!$B$6:$B$100000,"<="&C37) -> 0 | E37: =SUMIFS(受注ログ!$D$6:$D$100000,受注ログ!$B$6:$B$100000,">="&B37,受注ログ!$B$6:$B$100000,"<="&C37) -> 0 | F37: =D37+E37 -> 0 | G37: =サマリー!$B$15 -> 500000 | H37: =F37-G37 -> -500000 | I37: =IFERROR(F37/G37,0) -> 0 | J37: =IFERROR(D37/サマリー!$B$7,0) -> 0 | K37: =IFERROR(E37/サマリー!$B$7,0) -> 0
A38: 36 | B38: =サマリー!$B$14-WEEKDAY(サマリー!$B$14,2)+1+(36-1)*7 -> 46566 | C38: =B38+6 -> 46572 | D38: =SUMIFS(受注ログ!$C$6:$C$100000,受注ログ!$B$6:$B$100000,">="&B38,受注ログ!$B$6:$B$100000,"<="&C38) -> 0 | E38: =SUMIFS(受注ログ!$D$6:$D$100000,受注ログ!$B$6:$B$100000,">="&B38,受注ログ!$B$6:$B$100000,"<="&C38) -> 0 | F38: =D38+E38 -> 0 | G38: =サマリー!$B$15 -> 500000 | H38: =F38-G38 -> -500000 | I38: =IFERROR(F38/G38,0) -> 0 | J38: =IFERROR(D38/サマリー!$B$7,0) -> 0 | K38: =IFERROR(E38/サマリー!$B$7,0) -> 0
A39: 37 | B39: =サマリー!$B$14-WEEKDAY(サマリー!$B$14,2)+1+(37-1)*7 -> 46573 | C39: =B39+6 -> 46579 | D39: =SUMIFS(受注ログ!$C$6:$C$100000,受注ログ!$B$6:$B$100000,">="&B39,受注ログ!$B$6:$B$100000,"<="&C39) -> 0 | E39: =SUMIFS(受注ログ!$D$6:$D$100000,受注ログ!$B$6:$B$100000,">="&B39,受注ログ!$B$6:$B$100000,"<="&C39) -> 0 | F39: =D39+E39 -> 0 | G39: =サマリー!$B$15 -> 500000 | H39: =F39-G39 -> -500000 | I39: =IFERROR(F39/G39,0) -> 0 | J39: =IFERROR(D39/サマリー!$B$7,0) -> 0 | K39: =IFERROR(E39/サマリー!$B$7,0) -> 0
A40: 38 | B40: =サマリー!$B$14-WEEKDAY(サマリー!$B$14,2)+1+(38-1)*7 -> 46580 | C40: =B40+6 -> 46586 | D40: =SUMIFS(受注ログ!$C$6:$C$100000,受注ログ!$B$6:$B$100000,">="&B40,受注ログ!$B$6:$B$100000,"<="&C40) -> 0 | E40: =SUMIFS(受注ログ!$D$6:$D$100000,受注ログ!$B$6:$B$100000,">="&B40,受注ログ!$B$6:$B$100000,"<="&C40) -> 0 | F40: =D40+E40 -> 0 | G40: =サマリー!$B$15 -> 500000 | H40: =F40-G40 -> -500000 | I40: =IFERROR(F40/G40,0) -> 0 | J40: =IFERROR(D40/サマリー!$B$7,0) -> 0 | K40: =IFERROR(E40/サマリー!$B$7,0) -> 0
...

Sheet 月次集計
A1: 月次集計（個人月予算×2＝チーム月予算）
A2: 月番号 | B2: 開始日 | C2: 終了日 | D2: 小原実績 | E2: 前園実績 | F2: チーム計 | G2: チーム月予算 | H2: 差異 | I2: 達成率 | J2: 小原達成率 | K2: 前園達成率
A3: 1 | B3: =EDATE(サマリー!$B$14,1-1) -> 46327 | C3: =EOMONTH(B3,0) -> 46356 | D3: =SUMIFS(受注ログ!$C$6:$C$100000,受注ログ!$B$6:$B$100000,">="&B3,受注ログ!$B$6:$B$100000,"<="&C3) -> 0 | E3: =SUMIFS(受注ログ!$D$6:$D$100000,受注ログ!$B$6:$B$100000,">="&B3,受注ログ!$B$6:$B$100000,"<="&C3) -> 0 | F3: =D3+E3 -> 0 | G3: =サマリー!$B$16 -> 2000000 | H3: =F3-G3 -> -2000000 | I3: =IFERROR(F3/G3,0) -> 0 | J3: =IFERROR(D3/サマリー!$B$8,0) -> 0 | K3: =IFERROR(E3/サマリー!$B$8,0) -> 0
A4: 2 | B4: =EDATE(サマリー!$B$14,2-1) -> 46357 | C4: =EOMONTH(B4,0) -> 46387 | D4: =SUMIFS(受注ログ!$C$6:$C$100000,受注ログ!$B$6:$B$100000,">="&B4,受注ログ!$B$6:$B$100000,"<="&C4) -> 0 | E4: =SUMIFS(受注ログ!$D$6:$D$100000,受注ログ!$B$6:$B$100000,">="&B4,受注ログ!$B$6:$B$100000,"<="&C4) -> 0 | F4: =D4+E4 -> 0 | G4: =サマリー!$B$16 -> 2000000 | H4: =F4-G4 -> -2000000 | I4: =IFERROR(F4/G4,0) -> 0 | J4: =IFERROR(D4/サマリー!$B$8,0) -> 0 | K4: =IFERROR(E4/サマリー!$B$8,0) -> 0
A5: 3 | B5: =EDATE(サマリー!$B$14,3-1) -> 46388 | C5: =EOMONTH(B5,0) -> 46418 | D5: =SUMIFS(受注ログ!$C$6:$C$100000,受注ログ!$B$6:$B$100000,">="&B5,受注ログ!$B$6:$B$100000,"<="&C5) -> 0 | E5: =SUMIFS(受注ログ!$D$6:$D$100000,受注ログ!$B$6:$B$100000,">="&B5,受注ログ!$B$6:$B$100000,"<="&C5) -> 0 | F5: =D5+E5 -> 0 | G5: =サマリー!$B$16 -> 2000000 | H5: =F5-G5 -> -2000000 | I5: =IFERROR(F5/G5,0) -> 0 | J5: =IFERROR(D5/サマリー!$B$8,0) -> 0 | K5: =IFERROR(E5/サマリー!$B$8,0) -> 0
A6: 4 | B6: =EDATE(サマリー!$B$14,4-1) -> 46419 | C6: =EOMONTH(B6,0) -> 46446 | D6: =SUMIFS(受注ログ!$C$6:$C$100000,受注ログ!$B$6:$B$100000,">="&B6,受注ログ!$B$6:$B$100000,"<="&C6) -> 0 | E6: =SUMIFS(受注ログ!$D$6:$D$100000,受注ログ!$B$6:$B$100000,">="&B6,受注ログ!$B$6:$B$100000,"<="&C6) -> 0 | F6: =D6+E6 -> 0 | G6: =サマリー!$B$16 -> 2000000 | H6: =F6-G6 -> -2000000 | I6: =IFERROR(F6/G6,0) -> 0 | J6: =IFERROR(D6/サマリー!$B$8,0) -> 0 | K6: =IFERROR(E6/サマリー!$B$8,0) -> 0
A7: 5 | B7: =EDATE(サマリー!$B$14,5-1) -> 46447 | C7: =EOMONTH(B7,0) -> 46477 | D7: =SUMIFS(受注ログ!$C$6:$C$100000,受注ログ!$B$6:$B$100000,">="&B7,受注ログ!$B$6:$B$100000,"<="&C7) -> 0 | E7: =SUMIFS(受注ログ!$D$6:$D$100000,受注ログ!$B$6:$B$100000,">="&B7,受注ログ!$B$6:$B$100000,"<="&C7) -> 0 | F7: =D7+E7 -> 0 | G7: =サマリー!$B$16 -> 2000000 | H7: =F7-G7 -> -2000000 | I7: =IFERROR(F7/G7,0) -> 0 | J7: =IFERROR(D7/サマリー!$B$8,0) -> 0 | K7: =IFERROR(E7/サマリー!$B$8,0) -> 0
A8: 6 | B8: =EDATE(サマリー!$B$14,6-1) -> 46478 | C8: =EOMONTH(B8,0) -> 46507 | D8: =SUMIFS(受注ログ!$C$6:$C$100000,受注ログ!$B$6:$B$100000,">="&B8,受注ログ!$B$6:$B$100000,"<="&C8) -> 0 | E8: =SUMIFS(受注ログ!$D$6:$D$100000,受注ログ!$B$6:$B$100000,">="&B8,受注ログ!$B$6:$B$100000,"<="&C8) -> 0 | F8: =D8+E8 -> 0 | G8: =サマリー!$B$16 -> 2000000 | H8: =F8-G8 -> -2000000 | I8: =IFERROR(F8/G8,0) -> 0 | J8: =IFERROR(D8/サマリー!$B$8,0) -> 0 | K8: =IFERROR(E8/サマリー!$B$8,0) -> 0
A9: 7 | B9: =EDATE(サマリー!$B$14,7-1) -> 46508 | C9: =EOMONTH(B9,0) -> 46538 | D9: =SUMIFS(受注ログ!$C$6:$C$100000,受注ログ!$B$6:$B$100000,">="&B9,受注ログ!$B$6:$B$100000,"<="&C9) -> 0 | E9: =SUMIFS(受注ログ!$D$6:$D$100000,受注ログ!$B$6:$B$100000,">="&B9,受注ログ!$B$6:$B$100000,"<="&C9) -> 0 | F9: =D9+E9 -> 0 | G9: =サマリー!$B$16 -> 2000000 | H9: =F9-G9 -> -2000000 | I9: =IFERROR(F9/G9,0) -> 0 | J9: =IFERROR(D9/サマリー!$B$8,0) -> 0 | K9: =IFERROR(E9/サマリー!$B$8,0) -> 0
A10: 8 | B10: =EDATE(サマリー!$B$14,8-1) -> 46539 | C10: =EOMONTH(B10,0) -> 46568 | D10: =SUMIFS(受注ログ!$C$6:$C$100000,受注ログ!$B$6:$B$100000,">="&B10,受注ログ!$B$6:$B$100000,"<="&C10) -> 0 | E10: =SUMIFS(受注ログ!$D$6:$D$100000,受注ログ!$B$6:$B$100000,">="&B10,受注ログ!$B$6:$B$100000,"<="&C10) -> 0 | F10: =D10+E10 -> 0 | G10: =サマリー!$B$16 -> 2000000 | H10: =F10-G10 -> -2000000 | I10: =IFERROR(F10/G10,0) -> 0 | J10: =IFERROR(D10/サマリー!$B$8,0) -> 0 | K10: =IFERROR(E10/サマリー!$B$8,0) -> 0
A11: 9 | B11: =EDATE(サマリー!$B$14,9-1) -> 46569 | C11: =EOMONTH(B11,0) -> 46599 | D11: =SUMIFS(受注ログ!$C$6:$C$100000,受注ログ!$B$6:$B$100000,">="&B11,受注ログ!$B$6:$B$100000,"<="&C11) -> 0 | E11: =SUMIFS(受注ログ!$D$6:$D$100000,受注ログ!$B$6:$B$100000,">="&B11,受注ログ!$B$6:$B$100000,"<="&C11) -> 0 | F11: =D11+E11 -> 0 | G11: =サマリー!$B$16 -> 2000000 | H11: =F11-G11 -> -2000000 | I11: =IFERROR(F11/G11,0) -> 0 | J11: =IFERROR(D11/サマリー!$B$8,0) -> 0 | K11: =IFERROR(E11/サマリー!$B$8,0) -> 0
A12: 10 | B12: =EDATE(サマリー!$B$14,10-1) -> 46600 | C12: =EOMONTH(B12,0) -> 46630 | D12: =SUMIFS(受注ログ!$C$6:$C$100000,受注ログ!$B$6:$B$100000,">="&B12,受注ログ!$B$6:$B$100000,"<="&C12) -> 0 | E12: =SUMIFS(受注ログ!$D$6:$D$100000,受注ログ!$B$6:$B$100000,">="&B12,受注ログ!$B$6:$B$100000,"<="&C12) -> 0 | F12: =D12+E12 -> 0 | G12: =サマリー!$B$16 -> 2000000 | H12: =F12-G12 -> -2000000 | I12: =IFERROR(F12/G12,0) -> 0 | J12: =IFERROR(D12/サマリー!$B$8,0) -> 0 | K12: =IFERROR(E12/サマリー!$B$8,0) -> 0
A13: 11 | B13: =EDATE(サマリー!$B$14,11-1) -> 46631 | C13: =EOMONTH(B13,0) -> 46660 | D13: =SUMIFS(受注ログ!$C$6:$C$100000,受注ログ!$B$6:$B$100000,">="&B13,受注ログ!$B$6:$B$100000,"<="&C13) -> 0 | E13: =SUMIFS(受注ログ!$D$6:$D$100000,受注ログ!$B$6:$B$100000,">="&B13,受注ログ!$B$6:$B$100000,"<="&C13) -> 0 | F13: =D13+E13 -> 0 | G13: =サマリー!$B$16 -> 2000000 | H13: =F13-G13 -> -2000000 | I13: =IFERROR(F13/G13,0) -> 0 | J13: =IFERROR(D13/サマリー!$B$8,0) -> 0 | K13: =IFERROR(E13/サマリー!$B$8,0) -> 0
A14: 12 | B14: =EDATE(サマリー!$B$14,12-1) -> 46661 | C14: =EOMONTH(B14,0) -> 46691 | D14: =SUMIFS(受注ログ!$C$6:$C$100000,受注ログ!$B$6:$B$100000,">="&B14,受注ログ!$B$6:$B$100000,"<="&C14) -> 0 | E14: =SUMIFS(受注ログ!$D$6:$D$100000,受注ログ!$B$6:$B$100000,">="&B14,受注ログ!$B$6:$B$100000,"<="&C14) -> 0 | F14: =D14+E14 -> 0 | G14: =サマリー!$B$16 -> 2000000 | H14: =F14-G14 -> -2000000 | I14: =IFERROR(F14/G14,0) -> 0 | J14: =IFERROR(D14/サマリー!$B$8,0) -> 0 | K14: =IFERROR(E14/サマリー!$B$8,0) -> 0
A15: 13 | B15: =EDATE(サマリー!$B$14,13-1) -> 46692 | C15: =EOMONTH(B15,0) -> 46721 | D15: =SUMIFS(受注ログ!$C$6:$C$100000,受注ログ!$B$6:$B$100000,">="&B15,受注ログ!$B$6:$B$100000,"<="&C15) -> 0 | E15: =SUMIFS(受注ログ!$D$6:$D$100000,受注ログ!$B$6:$B$100000,">="&B15,受注ログ!$B$6:$B$100000,"<="&C15) -> 0 | F15: =D15+E15 -> 0 | G15: =サマリー!$B$16 -> 2000000 | H15: =F15-G15 -> -2000000 | I15: =IFERROR(F15/G15,0) -> 0 | J15: =IFERROR(D15/サマリー!$B$8,0) -> 0 | K15: =IFERROR(E15/サマリー!$B$8,0) -> 0

Sheet 半期年間集計
A1: 半期・年間集計（予算はチーム月予算からの参考換算）
A2: 区分 | B2: 開始日 | C2: 終了日 | D2: 小原実績 | E2: 前園実績 | F2: チーム計 | G2: 参考予算 | H2: 差異 | I2: 達成率
A3: 上半期 | B3: =サマリー!$B$14 -> 46327 | C3: =EOMONTH(サマリー!$B$14,5) -> 46507 | D3: =SUMIFS(受注ログ!$C$6:$C$100000,受注ログ!$B$6:$B$100000,">="&B3,受注ログ!$B$6:$B$100000,"<="&C3) -> 0 | E3: =SUMIFS(受注ログ!$D$6:$D$100000,受注ログ!$B$6:$B$100000,">="&B3,受注ログ!$B$6:$B$100000,"<="&C3) -> 0 | F3: =D3+E3 -> 0 | G3: =サマリー!$B$17 -> 12000000 | H3: =F3-G3 -> -12000000 | I3: =IFERROR(F3/G3,0) -> 0
A4: 下半期 | B4: =EDATE(サマリー!$B$14,6) -> 46508 | C4: =EOMONTH(サマリー!$B$14,11) -> 46691 | D4: =SUMIFS(受注ログ!$C$6:$C$100000,受注ログ!$B$6:$B$100000,">="&B4,受注ログ!$B$6:$B$100000,"<="&C4) -> 0 | E4: =SUMIFS(受注ログ!$D$6:$D$100000,受注ログ!$B$6:$B$100000,">="&B4,受注ログ!$B$6:$B$100000,"<="&C4) -> 0 | F4: =D4+E4 -> 0 | G4: =サマリー!$B$17 -> 12000000 | H4: =F4-G4 -> -12000000 | I4: =IFERROR(F4/G4,0) -> 0
A5: 年間 | B5: =サマリー!$B$14 -> 46327 | C5: =EOMONTH(サマリー!$B$14,11) -> 46691 | D5: =SUMIFS(受注ログ!$C$6:$C$100000,受注ログ!$B$6:$B$100000,">="&B5,受注ログ!$B$6:$B$100000,"<="&C5) -> 0 | E5: =SUMIFS(受注ログ!$D$6:$D$100000,受注ログ!$B$6:$B$100000,">="&B5,受注ログ!$B$6:$B$100000,"<="&C5) -> 0 | F5: =D5+E5 -> 0 | G5: =サマリー!$B$18 -> 24000000 | H5: =F5-G5 -> -24000000 | I5: =IFERROR(F5/G5,0) -> 0

Sheet 印刷用
A1: ="店舗別 売上状況（"&サマリー!B13&"）" -> 店舗別 売上状況（39期 夏期）
A2: ="（"&TEXT(サマリー!$B$6,"yyyy/m/d")&" 時点）" -> （2026/10/25 時点）
A4: ■ 店舗別 売上（今週・今月）
A5: 店舗 | B5: 今週 | C5: 今月
A6: 大洲店 | B6: =SUMIFS(受注ログ!$M$6:$M$100000,受注ログ!$B$6:$B$100000,">="&INDEX(週次集計!$B$3:$B$56,サマリー!$B$20),受注ログ!$B$6:$B$100000,"<="&INDEX(週次集計!$C$3:$C$56,サマリー!$B$20)) -> 0 | C6: =サマリー!D55 -> 0
A7: 西予店 | B7: =SUMIFS(受注ログ!$N$6:$N$100000,受注ログ!$B$6:$B$100000,">="&INDEX(週次集計!$B$3:$B$56,サマリー!$B$20),受注ログ!$B$6:$B$100000,"<="&INDEX(週次集計!$C$3:$C$56,サマリー!$B$20)) -> 0 | C7: =サマリー!D56 -> 0
A8: 宇和島店 | B8: =SUMIFS(受注ログ!$O$6:$O$100000,受注ログ!$B$6:$B$100000,">="&INDEX(週次集計!$B$3:$B$56,サマリー!$B$20),受注ログ!$B$6:$B$100000,"<="&INDEX(週次集計!$C$3:$C$56,サマリー!$B$20)) -> 0 | C8: =サマリー!D57 -> 0
A9: 新居浜店 | B9: =SUMIFS(受注ログ!$W$6:$W$100000,受注ログ!$B$6:$B$100000,">="&INDEX(週次集計!$B$3:$B$56,サマリー!$B$20),受注ログ!$B$6:$B$100000,"<="&INDEX(週次集計!$C$3:$C$56,サマリー!$B$20)) -> 0 | C9: =サマリー!D58 -> 0
A11: ※ 個人の実績・予算は含めていません（店舗別の売上のみ表示）。
A12: ※「印刷用」シートを開いてCtrl+Pで、この内容だけがA4一枚で印刷されます。
