Workbook

Sheet サマリー
A1: 売上ダッシュボード（週・月・半期・年間）
A3: ■ 入力項目（黄色セルのみ編集）
A4: 集計対象年 | B4: 2026
A5: 年度開始月 | B5: 5
A6: 本日の日付（自動） | B6: =TODAY() -> 46289
A7: 個人 週予算（1人あたり） | B7: 250000
A8: 個人 月予算（1人あたり） | B8: 1000000
A9: JET業務 単価（1件） | B9: 25000
A10: JONE200 単価 | B10: 7241
A11: JONE100 単価（未定の場合は0） | B11: 0
A12: YTS 単価（1件） | B12: 30000
A14: 年度開始日 | B14: =DATE(B4,B5,1) -> 46143
A15: チーム週予算（個人×2） | B15: =B7*2 -> 500000
A16: チーム月予算（個人×2） | B16: =B8*2 -> 2000000
A17: 半期予算（月予算×6・参考） | B17: =B16*6 -> 12000000
A18: 年間予算（月予算×12・参考） | B18: =B16*12 -> 24000000
A20: 現在の週番号 | B20: =INT((B6-(B14-WEEKDAY(B14,2)+1))/7)+1 -> 22
A21: 現在の月番号 | B21: =(YEAR(B6)-YEAR(B14))*12+MONTH(B6)-MONTH(B14)+1 -> 5
A22: 現在の半期区分 | B22: =IF(B21<=6,"上半期","下半期") -> 上半期
A24: ■ スタッフ別進捗（今週・今月）
A25: 対象 | B25: 予算 | C25: 実績 | D25: 達成率 | E25: 残り必要額
A26: 小原（今週） | B26: =B7 -> 250000 | C26: =INDEX(週次集計!D3:D56,$B$20) -> 387801 | D26: =IFERROR(C26/B26,0) -> 1.551204 | E26: =MAX(B26-C26,0) -> 0
A27: 前園（今週） | B27: =B7 -> 250000 | C27: =INDEX(週次集計!E3:E56,$B$20) -> 22829 | D27: =IFERROR(C27/B27,0) -> 0.091316 | E27: =MAX(B27-C27,0) -> 227171
A28: 小原（今月） | B28: =B8 -> 1000000 | C28: =INDEX(月次集計!D3:D15,$B$21) -> 1229092 | D28: =IFERROR(C28/B28,0) -> 1.229092 | E28: =MAX(B28-C28,0) -> 0
A29: 前園（今月） | B29: =B8 -> 1000000 | C29: =INDEX(月次集計!E3:E15,$B$21) -> 541948 | D29: =IFERROR(C29/B29,0) -> 0.541948 | E29: =MAX(B29-C29,0) -> 458052
A32: ■ 優先度ダッシュボード（1日あたり必要額が大きいほど優先）
A33: 対象 | B33: 予算 | C33: 実績 | D33: 残り必要額 | E33: 期限 | F33: 残り日数 | G33: 1日あたり必要額 | H33: 優先度
A34: 小原（今週） | B34: =B7 -> 250000 | C34: =INDEX(週次集計!D3:D56,$B$20) -> 387801 | D34: =MAX(B34-C34,0) -> 0 | E34: =INDEX(週次集計!C3:C56,$B$20) -> 46292 | F34: =MAX(E34-$B$6+1,1) -> 4 | G34: =IFERROR(D34/F34,0) -> 0 | H34: =RANK(G34,$G$34:$G$41) -> 7
A35: 前園（今週） | B35: =B7 -> 250000 | C35: =INDEX(週次集計!E3:E56,$B$20) -> 22829 | D35: =MAX(B35-C35,0) -> 227171 | E35: =INDEX(週次集計!C3:C56,$B$20) -> 46292 | F35: =MAX(E35-$B$6+1,1) -> 4 | G35: =IFERROR(D35/F35,0) -> 56792.75 | H35: =RANK(G35,$G$34:$G$41) -> 4
A36: チーム（今週） | B36: =B15 -> 500000 | C36: =INDEX(週次集計!F3:F56,$B$20) -> 410630 | D36: =MAX(B36-C36,0) -> 89370 | E36: =INDEX(週次集計!C3:C56,$B$20) -> 46292 | F36: =MAX(E36-$B$6+1,1) -> 4 | G36: =IFERROR(D36/F36,0) -> 22342.5 | H36: =RANK(G36,$G$34:$G$41) -> 6
A37: 小原（今月） | B37: =B8 -> 1000000 | C37: =INDEX(月次集計!D3:D15,$B$21) -> 1229092 | D37: =MAX(B37-C37,0) -> 0 | E37: =INDEX(月次集計!C3:C15,$B$21) -> 46295 | F37: =MAX(E37-$B$6+1,1) -> 7 | G37: =IFERROR(D37/F37,0) -> 0 | H37: =RANK(G37,$G$34:$G$41) -> 7
A38: 前園（今月） | B38: =B8 -> 1000000 | C38: =INDEX(月次集計!E3:E15,$B$21) -> 541948 | D38: =MAX(B38-C38,0) -> 458052 | E38: =INDEX(月次集計!C3:C15,$B$21) -> 46295 | F38: =MAX(E38-$B$6+1,1) -> 7 | G38: =IFERROR(D38/F38,0) -> 65436 | H38: =RANK(G38,$G$34:$G$41) -> 3
A39: チーム（今月） | B39: =B16 -> 2000000 | C39: =INDEX(月次集計!F3:F15,$B$21) -> 1771040 | D39: =MAX(B39-C39,0) -> 228960 | E39: =INDEX(月次集計!C3:C15,$B$21) -> 46295 | F39: =MAX(E39-$B$6+1,1) -> 7 | G39: =IFERROR(D39/F39,0) -> 32708.571 | H39: =RANK(G39,$G$34:$G$41) -> 5
A40: チーム（今半期） | B40: =B17 -> 12000000 | C40: =INDEX(半期年間集計!F3:F5,IF($B$22="上半期",1,2)) -> 5645873 | D40: =MAX(B40-C40,0) -> 6354127 | E40: =INDEX(半期年間集計!C3:C5,IF($B$22="上半期",1,2)) -> 46326 | F40: =MAX(E40-$B$6+1,1) -> 38 | G40: =IFERROR(D40/F40,0) -> 167213.87 | H40: =RANK(G40,$G$34:$G$41) -> 1
A41: チーム（今年） | B41: =B18 -> 24000000 | C41: =INDEX(半期年間集計!F3:F5,3) -> 5645873 | D41: =MAX(B41-C41,0) -> 18354127 | E41: =INDEX(半期年間集計!C3:C5,3) -> 46507 | F41: =MAX(E41-$B$6+1,1) -> 219 | G41: =IFERROR(D41/F41,0) -> 83808.799 | H41: =RANK(G41,$G$34:$G$41) -> 2
A43: ※「優先度」の1位は、残り必要額を残り日数で割った『1日あたり必要額』が最も大きい項目です。そこから手をつけるのが最も効率的です。
A44: ※ 個人の月予算は1人100万円、チームは200万円（個人×2）です。半期・年間はチーム月予算からの参考換算値です。
A45: ※ 週は月曜始まり。月をまたぐ週も前後月の実績を含めて集計します。
A47: ■ 今月 カテゴリー別内訳（実績のみ）
A48: ="（"&TEXT(INDEX(月次集計!$B$3:$B$15,$B$21),"m月")&"分）" -> （9月分）
...

Sheet 受注ログ
A1: 受注ログ（1行＝1受注。Aに日にちだけ入力→日付は自動。C〜Hで日別・本日の状況がすぐ分かります） | AB1: ※ A列（日にちだけ）に数字を入れると、B列の日付が自動計算されます。空欄なら上の行と同じ日付のままです。
B2: 小原週残 | C2: 前園週残 | D2: チーム週実績 | E2: チーム週残 | F2: 小原本日 | G2: 前園本日 | H2: チーム本日 | AB2: ※ C列（小原計）・D列（前園計）・E列（合計）を見れば、右にスクロールしなくてもその日誰の売上があったか分かります。
B3: =MAX(サマリー!$B$7-INDEX(週次集計!$D$3:$D$56,サマリー!$B$20),0) -> 0 | C3: =MAX(サマリー!$B$7-INDEX(週次集計!$E$3:$E$56,サマリー!$B$20),0) -> 227171 | D3: =INDEX(週次集計!$F$3:$F$56,サマリー!$B$20) -> 410630 | E3: =MAX(サマリー!$B$15-INDEX(週次集計!$F$3:$F$56,サマリー!$B$20),0) -> 89370 | F3: =SUMIFS($C$6:$C$205,$B$6:$B$205,TODAY()) -> 0 | G3: =SUMIFS($D$6:$D$205,$B$6:$B$205,TODAY()) -> 0 | H3: =F3+G3 -> 0 | AB3: ※ 実際に入力されたセルには自動で緑色が付きます。
I4: 小原 | S4: 前園 | AB4: ※ 松山本店・持込・RYTSの3列合計が「松山本店の売上」になります。
A5: 日 | B5: 日付 | C5: 小原計 | D5: 前園計 | E5: 合計 | I5: 松山本店 | J5: 持込 | K5: RYTS | L5: 大洲店 | M5: 西予店 | N5: 宇和島店 | O5: サテライト | P5: JET業務 (件数) | Q5: JONE (100/200) | R5: YTS (件数) | S5: 松山本店 | T5: 持込 | U5: RYTS | V5: 新居浜店 | W5: サテライト | X5: JET業務 (件数) | Y5: JONE (100/200) | Z5: YTS (件数) | AB5: ※ 小原は新居浜店、前園は大洲店・西予店・宇和島店の列がありません（担当外のため）。
B6: 46202 | C6: =I6+J6+K6+L6+M6+N6+O6+IF(P6="",0,P6*サマリー!$B$9)+IF(Q6="",0,IF(Q6=200,サマリー!$B$10,IF(Q6=100,サマリー!$B$11,0)))+IF(R6="",0,R6*サマリー!$B$12) -> 0 | D6: =S6+T6+U6+V6+W6+IF(X6="",0,X6*サマリー!$B$9)+IF(Y6="",0,IF(Y6=200,サマリー!$B$10,IF(Y6=100,サマリー!$B$11,0)))+IF(Z6="",0,Z6*サマリー!$B$12) -> 27872 | E6: =C6+D6 -> 27872 | S6: 18250 | U6: 9622 | AB6: ※ JET業務・JONE・YTSは件数やコードを入力すると、小原計/前園計に自動で金額換算されます（単価はサマリーシートで変更可）。
A7: 30 | B7: =IF(A7="",B6,IF(A7<DAY(B6),DATE(YEAR(B6),MONTH(B6)+1,A7),DATE(YEAR(B6),MONTH(B6),A7))) -> 46203 | C7: =I7+J7+K7+L7+M7+N7+O7+IF(P7="",0,P7*サマリー!$B$9)+IF(Q7="",0,IF(Q7=200,サマリー!$B$10,IF(Q7=100,サマリー!$B$11,0)))+IF(R7="",0,R7*サマリー!$B$12) -> 47238 | D7: =S7+T7+U7+V7+W7+IF(X7="",0,X7*サマリー!$B$9)+IF(Y7="",0,IF(Y7=200,サマリー!$B$10,IF(Y7=100,サマリー!$B$11,0)))+IF(Z7="",0,Z7*サマリー!$B$12) -> 0 | E7: =C7+D7 -> 47238 | I7: 47238
B8: =IF(A8="",B7,IF(A8<DAY(B7),DATE(YEAR(B7),MONTH(B7)+1,A8),DATE(YEAR(B7),MONTH(B7),A8))) -> 46203 | C8: =I8+J8+K8+L8+M8+N8+O8+IF(P8="",0,P8*サマリー!$B$9)+IF(Q8="",0,IF(Q8=200,サマリー!$B$10,IF(Q8=100,サマリー!$B$11,0)))+IF(R8="",0,R8*サマリー!$B$12) -> 43766 | D8: =S8+T8+U8+V8+W8+IF(X8="",0,X8*サマリー!$B$9)+IF(Y8="",0,IF(Y8=200,サマリー!$B$10,IF(Y8=100,サマリー!$B$11,0)))+IF(Z8="",0,Z8*サマリー!$B$12) -> 0 | E8: =C8+D8 -> 43766 | I8: 31730 | K8: 12036
A9: 1 | B9: =IF(A9="",B8,IF(A9<DAY(B8),DATE(YEAR(B8),MONTH(B8)+1,A9),DATE(YEAR(B8),MONTH(B8),A9))) -> 46204 | C9: =I9+J9+K9+L9+M9+N9+O9+IF(P9="",0,P9*サマリー!$B$9)+IF(Q9="",0,IF(Q9=200,サマリー!$B$10,IF(Q9=100,サマリー!$B$11,0)))+IF(R9="",0,R9*サマリー!$B$12) -> 50000 | D9: =S9+T9+U9+V9+W9+IF(X9="",0,X9*サマリー!$B$9)+IF(Y9="",0,IF(Y9=200,サマリー!$B$10,IF(Y9=100,サマリー!$B$11,0)))+IF(Z9="",0,Z9*サマリー!$B$12) -> 555 | E9: =C9+D9 -> 50555 | P9: 2 | T9: 555
A10: 2 | B10: =IF(A10="",B9,IF(A10<DAY(B9),DATE(YEAR(B9),MONTH(B9)+1,A10),DATE(YEAR(B9),MONTH(B9),A10))) -> 46205 | C10: =I10+J10+K10+L10+M10+N10+O10+IF(P10="",0,P10*サマリー!$B$9)+IF(Q10="",0,IF(Q10=200,サマリー!$B$10,IF(Q10=100,サマリー!$B$11,0)))+IF(R10="",0,R10*サマリー!$B$12) -> 38000 | D10: =S10+T10+U10+V10+W10+IF(X10="",0,X10*サマリー!$B$9)+IF(Y10="",0,IF(Y10=200,サマリー!$B$10,IF(Y10=100,サマリー!$B$11,0)))+IF(Z10="",0,Z10*サマリー!$B$12) -> 23555 | E10: =C10+D10 -> 61555 | N10: 13000 | P10: 1 | T10: 23555
A11: 3 | B11: =IF(A11="",B10,IF(A11<DAY(B10),DATE(YEAR(B10),MONTH(B10)+1,A11),DATE(YEAR(B10),MONTH(B10),A11))) -> 46206 | C11: =I11+J11+K11+L11+M11+N11+O11+IF(P11="",0,P11*サマリー!$B$9)+IF(Q11="",0,IF(Q11=200,サマリー!$B$10,IF(Q11=100,サマリー!$B$11,0)))+IF(R11="",0,R11*サマリー!$B$12) -> 33519 | D11: =S11+T11+U11+V11+W11+IF(X11="",0,X11*サマリー!$B$9)+IF(Y11="",0,IF(Y11=200,サマリー!$B$10,IF(Y11=100,サマリー!$B$11,0)))+IF(Z11="",0,Z11*サマリー!$B$12) -> 1755 | E11: =C11+D11 -> 35274 | J11: 3519 | R11: 1 | V11: 1755
B12: =IF(A12="",B11,IF(A12<DAY(B11),DATE(YEAR(B11),MONTH(B11)+1,A12),DATE(YEAR(B11),MONTH(B11),A12))) -> 46206 | C12: =I12+J12+K12+L12+M12+N12+O12+IF(P12="",0,P12*サマリー!$B$9)+IF(Q12="",0,IF(Q12=200,サマリー!$B$10,IF(Q12=100,サマリー!$B$11,0)))+IF(R12="",0,R12*サマリー!$B$12) -> 0 | D12: =S12+T12+U12+V12+W12+IF(X12="",0,X12*サマリー!$B$9)+IF(Y12="",0,IF(Y12=200,サマリー!$B$10,IF(Y12=100,サマリー!$B$11,0)))+IF(Z12="",0,Z12*サマリー!$B$12) -> 6400 | E12: =C12+D12 -> 6400 | V12: 6400
B13: =IF(A13="",B12,IF(A13<DAY(B12),DATE(YEAR(B12),MONTH(B12)+1,A13),DATE(YEAR(B12),MONTH(B12),A13))) -> 46206 | C13: =I13+J13+K13+L13+M13+N13+O13+IF(P13="",0,P13*サマリー!$B$9)+IF(Q13="",0,IF(Q13=200,サマリー!$B$10,IF(Q13=100,サマリー!$B$11,0)))+IF(R13="",0,R13*サマリー!$B$12) -> 0 | D13: =S13+T13+U13+V13+W13+IF(X13="",0,X13*サマリー!$B$9)+IF(Y13="",0,IF(Y13=200,サマリー!$B$10,IF(Y13=100,サマリー!$B$11,0)))+IF(Z13="",0,Z13*サマリー!$B$12) -> 11900 | E13: =C13+D13 -> 11900 | V13: 11900
A14: 4 | B14: =IF(A14="",B13,IF(A14<DAY(B13),DATE(YEAR(B13),MONTH(B13)+1,A14),DATE(YEAR(B13),MONTH(B13),A14))) -> 46207 | C14: =I14+J14+K14+L14+M14+N14+O14+IF(P14="",0,P14*サマリー!$B$9)+IF(Q14="",0,IF(Q14=200,サマリー!$B$10,IF(Q14=100,サマリー!$B$11,0)))+IF(R14="",0,R14*サマリー!$B$12) -> 7255 | D14: =S14+T14+U14+V14+W14+IF(X14="",0,X14*サマリー!$B$9)+IF(Y14="",0,IF(Y14=200,サマリー!$B$10,IF(Y14=100,サマリー!$B$11,0)))+IF(Z14="",0,Z14*サマリー!$B$12) -> 0 | E14: =C14+D14 -> 7255 | J14: 1755 | L14: 5500
A15: 5 | B15: =IF(A15="",B14,IF(A15<DAY(B14),DATE(YEAR(B14),MONTH(B14)+1,A15),DATE(YEAR(B14),MONTH(B14),A15))) -> 46208 | C15: =I15+J15+K15+L15+M15+N15+O15+IF(P15="",0,P15*サマリー!$B$9)+IF(Q15="",0,IF(Q15=200,サマリー!$B$10,IF(Q15=100,サマリー!$B$11,0)))+IF(R15="",0,R15*サマリー!$B$12) -> 12119 | D15: =S15+T15+U15+V15+W15+IF(X15="",0,X15*サマリー!$B$9)+IF(Y15="",0,IF(Y15=200,サマリー!$B$10,IF(Y15=100,サマリー!$B$11,0)))+IF(Z15="",0,Z15*サマリー!$B$12) -> 18800 | E15: =C15+D15 -> 30919 | I15: 12119 | V15: 18800
B16: =IF(A16="",B15,IF(A16<DAY(B15),DATE(YEAR(B15),MONTH(B15)+1,A16),DATE(YEAR(B15),MONTH(B15),A16))) -> 46208 | C16: =I16+J16+K16+L16+M16+N16+O16+IF(P16="",0,P16*サマリー!$B$9)+IF(Q16="",0,IF(Q16=200,サマリー!$B$10,IF(Q16=100,サマリー!$B$11,0)))+IF(R16="",0,R16*サマリー!$B$12) -> 759 | D16: =S16+T16+U16+V16+W16+IF(X16="",0,X16*サマリー!$B$9)+IF(Y16="",0,IF(Y16=200,サマリー!$B$10,IF(Y16=100,サマリー!$B$11,0)))+IF(Z16="",0,Z16*サマリー!$B$12) -> 0 | E16: =C16+D16 -> 759 | I16: 550 | J16: 209
B17: =IF(A17="",B16,IF(A17<DAY(B16),DATE(YEAR(B16),MONTH(B16)+1,A17),DATE(YEAR(B16),MONTH(B16),A17))) -> 46208 | C17: =I17+J17+K17+L17+M17+N17+O17+IF(P17="",0,P17*サマリー!$B$9)+IF(Q17="",0,IF(Q17=200,サマリー!$B$10,IF(Q17=100,サマリー!$B$11,0)))+IF(R17="",0,R17*サマリー!$B$12) -> 13010 | D17: =S17+T17+U17+V17+W17+IF(X17="",0,X17*サマリー!$B$9)+IF(Y17="",0,IF(Y17=200,サマリー!$B$10,IF(Y17=100,サマリー!$B$11,0)))+IF(Z17="",0,Z17*サマリー!$B$12) -> 0 | E17: =C17+D17 -> 13010 | I17: 13010
A18: 6 | B18: =IF(A18="",B17,IF(A18<DAY(B17),DATE(YEAR(B17),MONTH(B17)+1,A18),DATE(YEAR(B17),MONTH(B17),A18))) -> 46209 | C18: =I18+J18+K18+L18+M18+N18+O18+IF(P18="",0,P18*サマリー!$B$9)+IF(Q18="",0,IF(Q18=200,サマリー!$B$10,IF(Q18=100,サマリー!$B$11,0)))+IF(R18="",0,R18*サマリー!$B$12) -> 2000 | D18: =S18+T18+U18+V18+W18+IF(X18="",0,X18*サマリー!$B$9)+IF(Y18="",0,IF(Y18=200,サマリー!$B$10,IF(Y18=100,サマリー!$B$11,0)))+IF(Z18="",0,Z18*サマリー!$B$12) -> 62258 | E18: =C18+D18 -> 64258 | L18: 2000 | S18: 23200 | U18: 31817 | Y18: 200
B19: =IF(A19="",B18,IF(A19<DAY(B18),DATE(YEAR(B18),MONTH(B18)+1,A19),DATE(YEAR(B18),MONTH(B18),A19))) -> 46209 | C19: =I19+J19+K19+L19+M19+N19+O19+IF(P19="",0,P19*サマリー!$B$9)+IF(Q19="",0,IF(Q19=200,サマリー!$B$10,IF(Q19=100,サマリー!$B$11,0)))+IF(R19="",0,R19*サマリー!$B$12) -> 0 | D19: =S19+T19+U19+V19+W19+IF(X19="",0,X19*サマリー!$B$9)+IF(Y19="",0,IF(Y19=200,サマリー!$B$10,IF(Y19=100,サマリー!$B$11,0)))+IF(Z19="",0,Z19*サマリー!$B$12) -> 3655 | E19: =C19+D19 -> 3655 | T19: 3655
B20: =IF(A20="",B19,IF(A20<DAY(B19),DATE(YEAR(B19),MONTH(B19)+1,A20),DATE(YEAR(B19),MONTH(B19),A20))) -> 46209 | C20: =I20+J20+K20+L20+M20+N20+O20+IF(P20="",0,P20*サマリー!$B$9)+IF(Q20="",0,IF(Q20=200,サマリー!$B$10,IF(Q20=100,サマリー!$B$11,0)))+IF(R20="",0,R20*サマリー!$B$12) -> 0 | D20: =S20+T20+U20+V20+W20+IF(X20="",0,X20*サマリー!$B$9)+IF(Y20="",0,IF(Y20=200,サマリー!$B$10,IF(Y20=100,サマリー!$B$11,0)))+IF(Z20="",0,Z20*サマリー!$B$12) -> 1100 | E20: =C20+D20 -> 1100 | T20: 1100
B21: =IF(A21="",B20,IF(A21<DAY(B20),DATE(YEAR(B20),MONTH(B20)+1,A21),DATE(YEAR(B20),MONTH(B20),A21))) -> 46209 | C21: =I21+J21+K21+L21+M21+N21+O21+IF(P21="",0,P21*サマリー!$B$9)+IF(Q21="",0,IF(Q21=200,サマリー!$B$10,IF(Q21=100,サマリー!$B$11,0)))+IF(R21="",0,R21*サマリー!$B$12) -> 0 | D21: =S21+T21+U21+V21+W21+IF(X21="",0,X21*サマリー!$B$9)+IF(Y21="",0,IF(Y21=200,サマリー!$B$10,IF(Y21=100,サマリー!$B$11,0)))+IF(Z21="",0,Z21*サマリー!$B$12) -> 3755 | E21: =C21+D21 -> 3755 | T21: 3755
B22: =IF(A22="",B21,IF(A22<DAY(B21),DATE(YEAR(B21),MONTH(B21)+1,A22),DATE(YEAR(B21),MONTH(B21),A22))) -> 46209 | C22: =I22+J22+K22+L22+M22+N22+O22+IF(P22="",0,P22*サマリー!$B$9)+IF(Q22="",0,IF(Q22=200,サマリー!$B$10,IF(Q22=100,サマリー!$B$11,0)))+IF(R22="",0,R22*サマリー!$B$12) -> 0 | D22: =S22+T22+U22+V22+W22+IF(X22="",0,X22*サマリー!$B$9)+IF(Y22="",0,IF(Y22=200,サマリー!$B$10,IF(Y22=100,サマリー!$B$11,0)))+IF(Z22="",0,Z22*サマリー!$B$12) -> 25838 | E22: =C22+D22 -> 25838 | S22: 25838
A23: 7 | B23: =IF(A23="",B22,IF(A23<DAY(B22),DATE(YEAR(B22),MONTH(B22)+1,A23),DATE(YEAR(B22),MONTH(B22),A23))) -> 46210 | C23: =I23+J23+K23+L23+M23+N23+O23+IF(P23="",0,P23*サマリー!$B$9)+IF(Q23="",0,IF(Q23=200,サマリー!$B$10,IF(Q23=100,サマリー!$B$11,0)))+IF(R23="",0,R23*サマリー!$B$12) -> 0 | D23: =S23+T23+U23+V23+W23+IF(X23="",0,X23*サマリー!$B$9)+IF(Y23="",0,IF(Y23=200,サマリー!$B$10,IF(Y23=100,サマリー!$B$11,0)))+IF(Z23="",0,Z23*サマリー!$B$12) -> 11441 | E23: =C23+D23 -> 11441 | T23: 4200 | Y23: 200
A24: 8 | B24: =IF(A24="",B23,IF(A24<DAY(B23),DATE(YEAR(B23),MONTH(B23)+1,A24),DATE(YEAR(B23),MONTH(B23),A24))) -> 46211 | C24: =I24+J24+K24+L24+M24+N24+O24+IF(P24="",0,P24*サマリー!$B$9)+IF(Q24="",0,IF(Q24=200,サマリー!$B$10,IF(Q24=100,サマリー!$B$11,0)))+IF(R24="",0,R24*サマリー!$B$12) -> 4955 | D24: =S24+T24+U24+V24+W24+IF(X24="",0,X24*サマリー!$B$9)+IF(Y24="",0,IF(Y24=200,サマリー!$B$10,IF(Y24=100,サマリー!$B$11,0)))+IF(Z24="",0,Z24*サマリー!$B$12) -> 0 | E24: =C24+D24 -> 4955 | J24: 4955
B25: =IF(A25="",B24,IF(A25<DAY(B24),DATE(YEAR(B24),MONTH(B24)+1,A25),DATE(YEAR(B24),MONTH(B24),A25))) -> 46211 | C25: =I25+J25+K25+L25+M25+N25+O25+IF(P25="",0,P25*サマリー!$B$9)+IF(Q25="",0,IF(Q25=200,サマリー!$B$10,IF(Q25=100,サマリー!$B$11,0)))+IF(R25="",0,R25*サマリー!$B$12) -> 1655 | D25: =S25+T25+U25+V25+W25+IF(X25="",0,X25*サマリー!$B$9)+IF(Y25="",0,IF(Y25=200,サマリー!$B$10,IF(Y25=100,サマリー!$B$11,0)))+IF(Z25="",0,Z25*サマリー!$B$12) -> 0 | E25: =C25+D25 -> 1655 | J25: 1655
A26: 9 | B26: =IF(A26="",B25,IF(A26<DAY(B25),DATE(YEAR(B25),MONTH(B25)+1,A26),DATE(YEAR(B25),MONTH(B25),A26))) -> 46212 | C26: =I26+J26+K26+L26+M26+N26+O26+IF(P26="",0,P26*サマリー!$B$9)+IF(Q26="",0,IF(Q26=200,サマリー!$B$10,IF(Q26=100,サマリー!$B$11,0)))+IF(R26="",0,R26*サマリー!$B$12) -> 25000 | D26: =S26+T26+U26+V26+W26+IF(X26="",0,X26*サマリー!$B$9)+IF(Y26="",0,IF(Y26=200,サマリー!$B$10,IF(Y26=100,サマリー!$B$11,0)))+IF(Z26="",0,Z26*サマリー!$B$12) -> 35034 | E26: =C26+D26 -> 60034 | P26: 1 | T26: 4200 | U26: 834 | Z26: 1
B27: =IF(A27="",B26,IF(A27<DAY(B26),DATE(YEAR(B26),MONTH(B26)+1,A27),DATE(YEAR(B26),MONTH(B26),A27))) -> 46212 | C27: =I27+J27+K27+L27+M27+N27+O27+IF(P27="",0,P27*サマリー!$B$9)+IF(Q27="",0,IF(Q27=200,サマリー!$B$10,IF(Q27=100,サマリー!$B$11,0)))+IF(R27="",0,R27*サマリー!$B$12) -> 0 | D27: =S27+T27+U27+V27+W27+IF(X27="",0,X27*サマリー!$B$9)+IF(Y27="",0,IF(Y27=200,サマリー!$B$10,IF(Y27=100,サマリー!$B$11,0)))+IF(Z27="",0,Z27*サマリー!$B$12) -> 2200 | E27: =C27+D27 -> 2200 | T27: 2200
B28: =IF(A28="",B27,IF(A28<DAY(B27),DATE(YEAR(B27),MONTH(B27)+1,A28),DATE(YEAR(B27),MONTH(B27),A28))) -> 46212 | C28: =I28+J28+K28+L28+M28+N28+O28+IF(P28="",0,P28*サマリー!$B$9)+IF(Q28="",0,IF(Q28=200,サマリー!$B$10,IF(Q28=100,サマリー!$B$11,0)))+IF(R28="",0,R28*サマリー!$B$12) -> 0 | D28: =S28+T28+U28+V28+W28+IF(X28="",0,X28*サマリー!$B$9)+IF(Y28="",0,IF(Y28=200,サマリー!$B$10,IF(Y28=100,サマリー!$B$11,0)))+IF(Z28="",0,Z28*サマリー!$B$12) -> 6400 | E28: =C28+D28 -> 6400 | T28: 6400
B29: =IF(A29="",B28,IF(A29<DAY(B28),DATE(YEAR(B28),MONTH(B28)+1,A29),DATE(YEAR(B28),MONTH(B28),A29))) -> 46212 | C29: =I29+J29+K29+L29+M29+N29+O29+IF(P29="",0,P29*サマリー!$B$9)+IF(Q29="",0,IF(Q29=200,サマリー!$B$10,IF(Q29=100,サマリー!$B$11,0)))+IF(R29="",0,R29*サマリー!$B$12) -> 0 | D29: =S29+T29+U29+V29+W29+IF(X29="",0,X29*サマリー!$B$9)+IF(Y29="",0,IF(Y29=200,サマリー!$B$10,IF(Y29=100,サマリー!$B$11,0)))+IF(Z29="",0,Z29*サマリー!$B$12) -> 3034 | E29: =C29+D29 -> 3034 | T29: 2200 | U29: 834
B30: =IF(A30="",B29,IF(A30<DAY(B29),DATE(YEAR(B29),MONTH(B29)+1,A30),DATE(YEAR(B29),MONTH(B29),A30))) -> 46212 | C30: =I30+J30+K30+L30+M30+N30+O30+IF(P30="",0,P30*サマリー!$B$9)+IF(Q30="",0,IF(Q30=200,サマリー!$B$10,IF(Q30=100,サマリー!$B$11,0)))+IF(R30="",0,R30*サマリー!$B$12) -> 0 | D30: =S30+T30+U30+V30+W30+IF(X30="",0,X30*サマリー!$B$9)+IF(Y30="",0,IF(Y30=200,サマリー!$B$10,IF(Y30=100,サマリー!$B$11,0)))+IF(Z30="",0,Z30*サマリー!$B$12) -> 1755 | E30: =C30+D30 -> 1755 | T30: 1755
A31: 10 | B31: =IF(A31="",B30,IF(A31<DAY(B30),DATE(YEAR(B30),MONTH(B30)+1,A31),DATE(YEAR(B30),MONTH(B30),A31))) -> 46213 | C31: =I31+J31+K31+L31+M31+N31+O31+IF(P31="",0,P31*サマリー!$B$9)+IF(Q31="",0,IF(Q31=200,サマリー!$B$10,IF(Q31=100,サマリー!$B$11,0)))+IF(R31="",0,R31*サマリー!$B$12) -> 15793 | D31: =S31+T31+U31+V31+W31+IF(X31="",0,X31*サマリー!$B$9)+IF(Y31="",0,IF(Y31=200,サマリー!$B$10,IF(Y31=100,サマリー!$B$11,0)))+IF(Z31="",0,Z31*サマリー!$B$12) -> 0 | E31: =C31+D31 -> 15793 | J31: 2200 | K31: 13593
B32: =IF(A32="",B31,IF(A32<DAY(B31),DATE(YEAR(B31),MONTH(B31)+1,A32),DATE(YEAR(B31),MONTH(B31),A32))) -> 46213 | C32: =I32+J32+K32+L32+M32+N32+O32+IF(P32="",0,P32*サマリー!$B$9)+IF(Q32="",0,IF(Q32=200,サマリー!$B$10,IF(Q32=100,サマリー!$B$11,0)))+IF(R32="",0,R32*サマリー!$B$12) -> 1100 | D32: =S32+T32+U32+V32+W32+IF(X32="",0,X32*サマリー!$B$9)+IF(Y32="",0,IF(Y32=200,サマリー!$B$10,IF(Y32=100,サマリー!$B$11,0)))+IF(Z32="",0,Z32*サマリー!$B$12) -> 0 | E32: =C32+D32 -> 1100 | J32: 1100
B33: =IF(A33="",B32,IF(A33<DAY(B32),DATE(YEAR(B32),MONTH(B32)+1,A33),DATE(YEAR(B32),MONTH(B32),A33))) -> 46213 | C33: =I33+J33+K33+L33+M33+N33+O33+IF(P33="",0,P33*サマリー!$B$9)+IF(Q33="",0,IF(Q33=200,サマリー!$B$10,IF(Q33=100,サマリー!$B$11,0)))+IF(R33="",0,R33*サマリー!$B$12) -> 6400 | D33: =S33+T33+U33+V33+W33+IF(X33="",0,X33*サマリー!$B$9)+IF(Y33="",0,IF(Y33=200,サマリー!$B$10,IF(Y33=100,サマリー!$B$11,0)))+IF(Z33="",0,Z33*サマリー!$B$12) -> 0 | E33: =C33+D33 -> 6400 | J33: 6400
B34: =IF(A34="",B33,IF(A34<DAY(B33),DATE(YEAR(B33),MONTH(B33)+1,A34),DATE(YEAR(B33),MONTH(B33),A34))) -> 46213 | C34: =I34+J34+K34+L34+M34+N34+O34+IF(P34="",0,P34*サマリー!$B$9)+IF(Q34="",0,IF(Q34=200,サマリー!$B$10,IF(Q34=100,サマリー!$B$11,0)))+IF(R34="",0,R34*サマリー!$B$12) -> 1655 | D34: =S34+T34+U34+V34+W34+IF(X34="",0,X34*サマリー!$B$9)+IF(Y34="",0,IF(Y34=200,サマリー!$B$10,IF(Y34=100,サマリー!$B$11,0)))+IF(Z34="",0,Z34*サマリー!$B$12) -> 0 | E34: =C34+D34 -> 1655 | J34: 1655
A35: 11 | B35: =IF(A35="",B34,IF(A35<DAY(B34),DATE(YEAR(B34),MONTH(B34)+1,A35),DATE(YEAR(B34),MONTH(B34),A35))) -> 46214 | C35: =I35+J35+K35+L35+M35+N35+O35+IF(P35="",0,P35*サマリー!$B$9)+IF(Q35="",0,IF(Q35=200,サマリー!$B$10,IF(Q35=100,サマリー!$B$11,0)))+IF(R35="",0,R35*サマリー!$B$12) -> 36552 | D35: =S35+T35+U35+V35+W35+IF(X35="",0,X35*サマリー!$B$9)+IF(Y35="",0,IF(Y35=200,サマリー!$B$10,IF(Y35=100,サマリー!$B$11,0)))+IF(Z35="",0,Z35*サマリー!$B$12) -> 555 | E35: =C35+D35 -> 37107 | K35: 6552 | R35: 1 | T35: 555
B36: =IF(A36="",B35,IF(A36<DAY(B35),DATE(YEAR(B35),MONTH(B35)+1,A36),DATE(YEAR(B35),MONTH(B35),A36))) -> 46214 | C36: =I36+J36+K36+L36+M36+N36+O36+IF(P36="",0,P36*サマリー!$B$9)+IF(Q36="",0,IF(Q36=200,サマリー!$B$10,IF(Q36=100,サマリー!$B$11,0)))+IF(R36="",0,R36*サマリー!$B$12) -> 18510 | D36: =S36+T36+U36+V36+W36+IF(X36="",0,X36*サマリー!$B$9)+IF(Y36="",0,IF(Y36=200,サマリー!$B$10,IF(Y36=100,サマリー!$B$11,0)))+IF(Z36="",0,Z36*サマリー!$B$12) -> 6400 | E36: =C36+D36 -> 24910 | J36: 18510 | T36: 6400
A37: 12 | B37: =IF(A37="",B36,IF(A37<DAY(B36),DATE(YEAR(B36),MONTH(B36)+1,A37),DATE(YEAR(B36),MONTH(B36),A37))) -> 46215 | C37: =I37+J37+K37+L37+M37+N37+O37+IF(P37="",0,P37*サマリー!$B$9)+IF(Q37="",0,IF(Q37=200,サマリー!$B$10,IF(Q37=100,サマリー!$B$11,0)))+IF(R37="",0,R37*サマリー!$B$12) -> 6397 | D37: =S37+T37+U37+V37+W37+IF(X37="",0,X37*サマリー!$B$9)+IF(Y37="",0,IF(Y37=200,サマリー!$B$10,IF(Y37=100,サマリー!$B$11,0)))+IF(Z37="",0,Z37*サマリー!$B$12) -> 9155 | E37: =C37+D37 -> 15552 | K37: 6397 | T37: 9155
B38: =IF(A38="",B37,IF(A38<DAY(B37),DATE(YEAR(B37),MONTH(B37)+1,A38),DATE(YEAR(B37),MONTH(B37),A38))) -> 46215 | C38: =I38+J38+K38+L38+M38+N38+O38+IF(P38="",0,P38*サマリー!$B$9)+IF(Q38="",0,IF(Q38=200,サマリー!$B$10,IF(Q38=100,サマリー!$B$11,0)))+IF(R38="",0,R38*サマリー!$B$12) -> 14500 | D38: =S38+T38+U38+V38+W38+IF(X38="",0,X38*サマリー!$B$9)+IF(Y38="",0,IF(Y38=200,サマリー!$B$10,IF(Y38=100,サマリー!$B$11,0)))+IF(Z38="",0,Z38*サマリー!$B$12) -> 0 | E38: =C38+D38 -> 14500 | K38: 14500
A39: 13 | B39: =IF(A39="",B38,IF(A39<DAY(B38),DATE(YEAR(B38),MONTH(B38)+1,A39),DATE(YEAR(B38),MONTH(B38),A39))) -> 46216 | C39: =I39+J39+K39+L39+M39+N39+O39+IF(P39="",0,P39*サマリー!$B$9)+IF(Q39="",0,IF(Q39=200,サマリー!$B$10,IF(Q39=100,サマリー!$B$11,0)))+IF(R39="",0,R39*サマリー!$B$12) -> 0 | D39: =S39+T39+U39+V39+W39+IF(X39="",0,X39*サマリー!$B$9)+IF(Y39="",0,IF(Y39=200,サマリー!$B$10,IF(Y39=100,サマリー!$B$11,0)))+IF(Z39="",0,Z39*サマリー!$B$12) -> 3034 | E39: =C39+D39 -> 3034 | T39: 2200 | U39: 834
A40: 14 | B40: =IF(A40="",B39,IF(A40<DAY(B39),DATE(YEAR(B39),MONTH(B39)+1,A40),DATE(YEAR(B39),MONTH(B39),A40))) -> 46217 | C40: =I40+J40+K40+L40+M40+N40+O40+IF(P40="",0,P40*サマリー!$B$9)+IF(Q40="",0,IF(Q40=200,サマリー!$B$10,IF(Q40=100,サマリー!$B$11,0)))+IF(R40="",0,R40*サマリー!$B$12) -> 70579 | D40: =S40+T40+U40+V40+W40+IF(X40="",0,X40*サマリー!$B$9)+IF(Y40="",0,IF(Y40=200,サマリー!$B$10,IF(Y40=100,サマリー!$B$11,0)))+IF(Z40="",0,Z40*サマリー!$B$12) -> 2000 | E40: =C40+D40 -> 72579 | I40: 29420 | K40: 11159 | R40: 1 | T40: 2000
...

Sheet 週次集計
A1: 週次集計（月曜始まり・月またぎ含む）
A2: 週番号 | B2: 開始日 | C2: 終了日 | D2: 小原実績 | E2: 前園実績 | F2: チーム計 | G2: チーム週予算 | H2: 差異 | I2: 達成率 | J2: 小原達成率 | K2: 前園達成率
A3: 1 | B3: =サマリー!$B$14-WEEKDAY(サマリー!$B$14,2)+1+(1-1)*7 -> 46139 | C3: =B3+6 -> 46145 | D3: =SUMIFS(受注ログ!$C$4:$C$5000,受注ログ!$B$4:$B$5000,">="&B3,受注ログ!$B$4:$B$5000,"<="&C3) -> 0 | E3: =SUMIFS(受注ログ!$D$4:$D$5000,受注ログ!$B$4:$B$5000,">="&B3,受注ログ!$B$4:$B$5000,"<="&C3) -> 0 | F3: =D3+E3 -> 0 | G3: =サマリー!$B$15 -> 500000 | H3: =F3-G3 -> -500000 | I3: =IFERROR(F3/G3,0) -> 0 | J3: =IFERROR(D3/サマリー!$B$7,0) -> 0 | K3: =IFERROR(E3/サマリー!$B$7,0) -> 0
A4: 2 | B4: =サマリー!$B$14-WEEKDAY(サマリー!$B$14,2)+1+(2-1)*7 -> 46146 | C4: =B4+6 -> 46152 | D4: =SUMIFS(受注ログ!$C$4:$C$5000,受注ログ!$B$4:$B$5000,">="&B4,受注ログ!$B$4:$B$5000,"<="&C4) -> 0 | E4: =SUMIFS(受注ログ!$D$4:$D$5000,受注ログ!$B$4:$B$5000,">="&B4,受注ログ!$B$4:$B$5000,"<="&C4) -> 0 | F4: =D4+E4 -> 0 | G4: =サマリー!$B$15 -> 500000 | H4: =F4-G4 -> -500000 | I4: =IFERROR(F4/G4,0) -> 0 | J4: =IFERROR(D4/サマリー!$B$7,0) -> 0 | K4: =IFERROR(E4/サマリー!$B$7,0) -> 0
A5: 3 | B5: =サマリー!$B$14-WEEKDAY(サマリー!$B$14,2)+1+(3-1)*7 -> 46153 | C5: =B5+6 -> 46159 | D5: =SUMIFS(受注ログ!$C$4:$C$5000,受注ログ!$B$4:$B$5000,">="&B5,受注ログ!$B$4:$B$5000,"<="&C5) -> 0 | E5: =SUMIFS(受注ログ!$D$4:$D$5000,受注ログ!$B$4:$B$5000,">="&B5,受注ログ!$B$4:$B$5000,"<="&C5) -> 0 | F5: =D5+E5 -> 0 | G5: =サマリー!$B$15 -> 500000 | H5: =F5-G5 -> -500000 | I5: =IFERROR(F5/G5,0) -> 0 | J5: =IFERROR(D5/サマリー!$B$7,0) -> 0 | K5: =IFERROR(E5/サマリー!$B$7,0) -> 0
A6: 4 | B6: =サマリー!$B$14-WEEKDAY(サマリー!$B$14,2)+1+(4-1)*7 -> 46160 | C6: =B6+6 -> 46166 | D6: =SUMIFS(受注ログ!$C$4:$C$5000,受注ログ!$B$4:$B$5000,">="&B6,受注ログ!$B$4:$B$5000,"<="&C6) -> 0 | E6: =SUMIFS(受注ログ!$D$4:$D$5000,受注ログ!$B$4:$B$5000,">="&B6,受注ログ!$B$4:$B$5000,"<="&C6) -> 0 | F6: =D6+E6 -> 0 | G6: =サマリー!$B$15 -> 500000 | H6: =F6-G6 -> -500000 | I6: =IFERROR(F6/G6,0) -> 0 | J6: =IFERROR(D6/サマリー!$B$7,0) -> 0 | K6: =IFERROR(E6/サマリー!$B$7,0) -> 0
A7: 5 | B7: =サマリー!$B$14-WEEKDAY(サマリー!$B$14,2)+1+(5-1)*7 -> 46167 | C7: =B7+6 -> 46173 | D7: =SUMIFS(受注ログ!$C$4:$C$5000,受注ログ!$B$4:$B$5000,">="&B7,受注ログ!$B$4:$B$5000,"<="&C7) -> 0 | E7: =SUMIFS(受注ログ!$D$4:$D$5000,受注ログ!$B$4:$B$5000,">="&B7,受注ログ!$B$4:$B$5000,"<="&C7) -> 0 | F7: =D7+E7 -> 0 | G7: =サマリー!$B$15 -> 500000 | H7: =F7-G7 -> -500000 | I7: =IFERROR(F7/G7,0) -> 0 | J7: =IFERROR(D7/サマリー!$B$7,0) -> 0 | K7: =IFERROR(E7/サマリー!$B$7,0) -> 0
A8: 6 | B8: =サマリー!$B$14-WEEKDAY(サマリー!$B$14,2)+1+(6-1)*7 -> 46174 | C8: =B8+6 -> 46180 | D8: =SUMIFS(受注ログ!$C$4:$C$5000,受注ログ!$B$4:$B$5000,">="&B8,受注ログ!$B$4:$B$5000,"<="&C8) -> 0 | E8: =SUMIFS(受注ログ!$D$4:$D$5000,受注ログ!$B$4:$B$5000,">="&B8,受注ログ!$B$4:$B$5000,"<="&C8) -> 0 | F8: =D8+E8 -> 0 | G8: =サマリー!$B$15 -> 500000 | H8: =F8-G8 -> -500000 | I8: =IFERROR(F8/G8,0) -> 0 | J8: =IFERROR(D8/サマリー!$B$7,0) -> 0 | K8: =IFERROR(E8/サマリー!$B$7,0) -> 0
A9: 7 | B9: =サマリー!$B$14-WEEKDAY(サマリー!$B$14,2)+1+(7-1)*7 -> 46181 | C9: =B9+6 -> 46187 | D9: =SUMIFS(受注ログ!$C$4:$C$5000,受注ログ!$B$4:$B$5000,">="&B9,受注ログ!$B$4:$B$5000,"<="&C9) -> 0 | E9: =SUMIFS(受注ログ!$D$4:$D$5000,受注ログ!$B$4:$B$5000,">="&B9,受注ログ!$B$4:$B$5000,"<="&C9) -> 0 | F9: =D9+E9 -> 0 | G9: =サマリー!$B$15 -> 500000 | H9: =F9-G9 -> -500000 | I9: =IFERROR(F9/G9,0) -> 0 | J9: =IFERROR(D9/サマリー!$B$7,0) -> 0 | K9: =IFERROR(E9/サマリー!$B$7,0) -> 0
A10: 8 | B10: =サマリー!$B$14-WEEKDAY(サマリー!$B$14,2)+1+(8-1)*7 -> 46188 | C10: =B10+6 -> 46194 | D10: =SUMIFS(受注ログ!$C$4:$C$5000,受注ログ!$B$4:$B$5000,">="&B10,受注ログ!$B$4:$B$5000,"<="&C10) -> 0 | E10: =SUMIFS(受注ログ!$D$4:$D$5000,受注ログ!$B$4:$B$5000,">="&B10,受注ログ!$B$4:$B$5000,"<="&C10) -> 0 | F10: =D10+E10 -> 0 | G10: =サマリー!$B$15 -> 500000 | H10: =F10-G10 -> -500000 | I10: =IFERROR(F10/G10,0) -> 0 | J10: =IFERROR(D10/サマリー!$B$7,0) -> 0 | K10: =IFERROR(E10/サマリー!$B$7,0) -> 0
A11: 9 | B11: =サマリー!$B$14-WEEKDAY(サマリー!$B$14,2)+1+(9-1)*7 -> 46195 | C11: =B11+6 -> 46201 | D11: =SUMIFS(受注ログ!$C$4:$C$5000,受注ログ!$B$4:$B$5000,">="&B11,受注ログ!$B$4:$B$5000,"<="&C11) -> 0 | E11: =SUMIFS(受注ログ!$D$4:$D$5000,受注ログ!$B$4:$B$5000,">="&B11,受注ログ!$B$4:$B$5000,"<="&C11) -> 0 | F11: =D11+E11 -> 0 | G11: =サマリー!$B$15 -> 500000 | H11: =F11-G11 -> -500000 | I11: =IFERROR(F11/G11,0) -> 0 | J11: =IFERROR(D11/サマリー!$B$7,0) -> 0 | K11: =IFERROR(E11/サマリー!$B$7,0) -> 0
A12: 10 | B12: =サマリー!$B$14-WEEKDAY(サマリー!$B$14,2)+1+(10-1)*7 -> 46202 | C12: =B12+6 -> 46208 | D12: =SUMIFS(受注ログ!$C$4:$C$5000,受注ログ!$B$4:$B$5000,">="&B12,受注ログ!$B$4:$B$5000,"<="&C12) -> 245666 | E12: =SUMIFS(受注ログ!$D$4:$D$5000,受注ログ!$B$4:$B$5000,">="&B12,受注ログ!$B$4:$B$5000,"<="&C12) -> 90837 | F12: =D12+E12 -> 336503 | G12: =サマリー!$B$15 -> 500000 | H12: =F12-G12 -> -163497 | I12: =IFERROR(F12/G12,0) -> 0.673006 | J12: =IFERROR(D12/サマリー!$B$7,0) -> 0.982664 | K12: =IFERROR(E12/サマリー!$B$7,0) -> 0.363348
A13: 11 | B13: =サマリー!$B$14-WEEKDAY(サマリー!$B$14,2)+1+(11-1)*7 -> 46209 | C13: =B13+6 -> 46215 | D13: =SUMIFS(受注ログ!$C$4:$C$5000,受注ログ!$B$4:$B$5000,">="&B13,受注ログ!$B$4:$B$5000,"<="&C13) -> 134517 | E13: =SUMIFS(受注ログ!$D$4:$D$5000,受注ログ!$B$4:$B$5000,">="&B13,受注ログ!$B$4:$B$5000,"<="&C13) -> 172580 | F13: =D13+E13 -> 307097 | G13: =サマリー!$B$15 -> 500000 | H13: =F13-G13 -> -192903 | I13: =IFERROR(F13/G13,0) -> 0.614194 | J13: =IFERROR(D13/サマリー!$B$7,0) -> 0.538068 | K13: =IFERROR(E13/サマリー!$B$7,0) -> 0.69032
A14: 12 | B14: =サマリー!$B$14-WEEKDAY(サマリー!$B$14,2)+1+(12-1)*7 -> 46216 | C14: =B14+6 -> 46222 | D14: =SUMIFS(受注ログ!$C$4:$C$5000,受注ログ!$B$4:$B$5000,">="&B14,受注ログ!$B$4:$B$5000,"<="&C14) -> 261339 | E14: =SUMIFS(受注ログ!$D$4:$D$5000,受注ログ!$B$4:$B$5000,">="&B14,受注ログ!$B$4:$B$5000,"<="&C14) -> 88808 | F14: =D14+E14 -> 350147 | G14: =サマリー!$B$15 -> 500000 | H14: =F14-G14 -> -149853 | I14: =IFERROR(F14/G14,0) -> 0.700294 | J14: =IFERROR(D14/サマリー!$B$7,0) -> 1.045356 | K14: =IFERROR(E14/サマリー!$B$7,0) -> 0.355232
A15: 13 | B15: =サマリー!$B$14-WEEKDAY(サマリー!$B$14,2)+1+(13-1)*7 -> 46223 | C15: =B15+6 -> 46229 | D15: =SUMIFS(受注ログ!$C$4:$C$5000,受注ログ!$B$4:$B$5000,">="&B15,受注ログ!$B$4:$B$5000,"<="&C15) -> 292030 | E15: =SUMIFS(受注ログ!$D$4:$D$5000,受注ログ!$B$4:$B$5000,">="&B15,受注ログ!$B$4:$B$5000,"<="&C15) -> 206335 | F15: =D15+E15 -> 498365 | G15: =サマリー!$B$15 -> 500000 | H15: =F15-G15 -> -1635 | I15: =IFERROR(F15/G15,0) -> 0.99673 | J15: =IFERROR(D15/サマリー!$B$7,0) -> 1.16812 | K15: =IFERROR(E15/サマリー!$B$7,0) -> 0.82534
A16: 14 | B16: =サマリー!$B$14-WEEKDAY(サマリー!$B$14,2)+1+(14-1)*7 -> 46230 | C16: =B16+6 -> 46236 | D16: =SUMIFS(受注ログ!$C$4:$C$5000,受注ログ!$B$4:$B$5000,">="&B16,受注ログ!$B$4:$B$5000,"<="&C16) -> 382208 | E16: =SUMIFS(受注ログ!$D$4:$D$5000,受注ログ!$B$4:$B$5000,">="&B16,受注ログ!$B$4:$B$5000,"<="&C16) -> 176366 | F16: =D16+E16 -> 558574 | G16: =サマリー!$B$15 -> 500000 | H16: =F16-G16 -> 58574 | I16: =IFERROR(F16/G16,0) -> 1.117148 | J16: =IFERROR(D16/サマリー!$B$7,0) -> 1.528832 | K16: =IFERROR(E16/サマリー!$B$7,0) -> 0.705464
A17: 15 | B17: =サマリー!$B$14-WEEKDAY(サマリー!$B$14,2)+1+(15-1)*7 -> 46237 | C17: =B17+6 -> 46243 | D17: =SUMIFS(受注ログ!$C$4:$C$5000,受注ログ!$B$4:$B$5000,">="&B17,受注ログ!$B$4:$B$5000,"<="&C17) -> 225230 | E17: =SUMIFS(受注ログ!$D$4:$D$5000,受注ログ!$B$4:$B$5000,">="&B17,受注ログ!$B$4:$B$5000,"<="&C17) -> 316208 | F17: =D17+E17 -> 541438 | G17: =サマリー!$B$15 -> 500000 | H17: =F17-G17 -> 41438 | I17: =IFERROR(F17/G17,0) -> 1.082876 | J17: =IFERROR(D17/サマリー!$B$7,0) -> 0.90092 | K17: =IFERROR(E17/サマリー!$B$7,0) -> 1.264832
A18: 16 | B18: =サマリー!$B$14-WEEKDAY(サマリー!$B$14,2)+1+(16-1)*7 -> 46244 | C18: =B18+6 -> 46250 | D18: =SUMIFS(受注ログ!$C$4:$C$5000,受注ログ!$B$4:$B$5000,">="&B18,受注ログ!$B$4:$B$5000,"<="&C18) -> 273320 | E18: =SUMIFS(受注ログ!$D$4:$D$5000,受注ログ!$B$4:$B$5000,">="&B18,受注ログ!$B$4:$B$5000,"<="&C18) -> 268854 | F18: =D18+E18 -> 542174 | G18: =サマリー!$B$15 -> 500000 | H18: =F18-G18 -> 42174 | I18: =IFERROR(F18/G18,0) -> 1.084348 | J18: =IFERROR(D18/サマリー!$B$7,0) -> 1.09328 | K18: =IFERROR(E18/サマリー!$B$7,0) -> 1.075416
A19: 17 | B19: =サマリー!$B$14-WEEKDAY(サマリー!$B$14,2)+1+(17-1)*7 -> 46251 | C19: =B19+6 -> 46257 | D19: =SUMIFS(受注ログ!$C$4:$C$5000,受注ログ!$B$4:$B$5000,">="&B19,受注ログ!$B$4:$B$5000,"<="&C19) -> 180639 | E19: =SUMIFS(受注ログ!$D$4:$D$5000,受注ログ!$B$4:$B$5000,">="&B19,受注ログ!$B$4:$B$5000,"<="&C19) -> 206145 | F19: =D19+E19 -> 386784 | G19: =サマリー!$B$15 -> 500000 | H19: =F19-G19 -> -113216 | I19: =IFERROR(F19/G19,0) -> 0.773568 | J19: =IFERROR(D19/サマリー!$B$7,0) -> 0.722556 | K19: =IFERROR(E19/サマリー!$B$7,0) -> 0.82458
A20: 18 | B20: =サマリー!$B$14-WEEKDAY(サマリー!$B$14,2)+1+(18-1)*7 -> 46258 | C20: =B20+6 -> 46264 | D20: =SUMIFS(受注ログ!$C$4:$C$5000,受注ログ!$B$4:$B$5000,">="&B20,受注ログ!$B$4:$B$5000,"<="&C20) -> 247566 | E20: =SUMIFS(受注ログ!$D$4:$D$5000,受注ログ!$B$4:$B$5000,">="&B20,受注ログ!$B$4:$B$5000,"<="&C20) -> 65130 | F20: =D20+E20 -> 312696 | G20: =サマリー!$B$15 -> 500000 | H20: =F20-G20 -> -187304 | I20: =IFERROR(F20/G20,0) -> 0.625392 | J20: =IFERROR(D20/サマリー!$B$7,0) -> 0.990264 | K20: =IFERROR(E20/サマリー!$B$7,0) -> 0.26052
A21: 19 | B21: =サマリー!$B$14-WEEKDAY(サマリー!$B$14,2)+1+(19-1)*7 -> 46265 | C21: =B21+6 -> 46271 | D21: =SUMIFS(受注ログ!$C$4:$C$5000,受注ログ!$B$4:$B$5000,">="&B21,受注ログ!$B$4:$B$5000,"<="&C21) -> 187564 | E21: =SUMIFS(受注ログ!$D$4:$D$5000,受注ログ!$B$4:$B$5000,">="&B21,受注ログ!$B$4:$B$5000,"<="&C21) -> 167415 | F21: =D21+E21 -> 354979 | G21: =サマリー!$B$15 -> 500000 | H21: =F21-G21 -> -145021 | I21: =IFERROR(F21/G21,0) -> 0.709958 | J21: =IFERROR(D21/サマリー!$B$7,0) -> 0.750256 | K21: =IFERROR(E21/サマリー!$B$7,0) -> 0.66966
A22: 20 | B22: =サマリー!$B$14-WEEKDAY(サマリー!$B$14,2)+1+(20-1)*7 -> 46272 | C22: =B22+6 -> 46278 | D22: =SUMIFS(受注ログ!$C$4:$C$5000,受注ログ!$B$4:$B$5000,">="&B22,受注ログ!$B$4:$B$5000,"<="&C22) -> 484729 | E22: =SUMIFS(受注ログ!$D$4:$D$5000,受注ログ!$B$4:$B$5000,">="&B22,受注ログ!$B$4:$B$5000,"<="&C22) -> 120860 | F22: =D22+E22 -> 605589 | G22: =サマリー!$B$15 -> 500000 | H22: =F22-G22 -> 105589 | I22: =IFERROR(F22/G22,0) -> 1.211178 | J22: =IFERROR(D22/サマリー!$B$7,0) -> 1.938916 | K22: =IFERROR(E22/サマリー!$B$7,0) -> 0.48344
A23: 21 | B23: =サマリー!$B$14-WEEKDAY(サマリー!$B$14,2)+1+(21-1)*7 -> 46279 | C23: =B23+6 -> 46285 | D23: =SUMIFS(受注ログ!$C$4:$C$5000,受注ログ!$B$4:$B$5000,">="&B23,受注ログ!$B$4:$B$5000,"<="&C23) -> 177253 | E23: =SUMIFS(受注ログ!$D$4:$D$5000,受注ログ!$B$4:$B$5000,">="&B23,受注ログ!$B$4:$B$5000,"<="&C23) -> 263644 | F23: =D23+E23 -> 440897 | G23: =サマリー!$B$15 -> 500000 | H23: =F23-G23 -> -59103 | I23: =IFERROR(F23/G23,0) -> 0.881794 | J23: =IFERROR(D23/サマリー!$B$7,0) -> 0.709012 | K23: =IFERROR(E23/サマリー!$B$7,0) -> 1.054576
A24: 22 | B24: =サマリー!$B$14-WEEKDAY(サマリー!$B$14,2)+1+(22-1)*7 -> 46286 | C24: =B24+6 -> 46292 | D24: =SUMIFS(受注ログ!$C$4:$C$5000,受注ログ!$B$4:$B$5000,">="&B24,受注ログ!$B$4:$B$5000,"<="&C24) -> 387801 | E24: =SUMIFS(受注ログ!$D$4:$D$5000,受注ログ!$B$4:$B$5000,">="&B24,受注ログ!$B$4:$B$5000,"<="&C24) -> 22829 | F24: =D24+E24 -> 410630 | G24: =サマリー!$B$15 -> 500000 | H24: =F24-G24 -> -89370 | I24: =IFERROR(F24/G24,0) -> 0.82126 | J24: =IFERROR(D24/サマリー!$B$7,0) -> 1.551204 | K24: =IFERROR(E24/サマリー!$B$7,0) -> 0.091316
A25: 23 | B25: =サマリー!$B$14-WEEKDAY(サマリー!$B$14,2)+1+(23-1)*7 -> 46293 | C25: =B25+6 -> 46299 | D25: =SUMIFS(受注ログ!$C$4:$C$5000,受注ログ!$B$4:$B$5000,">="&B25,受注ログ!$B$4:$B$5000,"<="&C25) -> 0 | E25: =SUMIFS(受注ログ!$D$4:$D$5000,受注ログ!$B$4:$B$5000,">="&B25,受注ログ!$B$4:$B$5000,"<="&C25) -> 0 | F25: =D25+E25 -> 0 | G25: =サマリー!$B$15 -> 500000 | H25: =F25-G25 -> -500000 | I25: =IFERROR(F25/G25,0) -> 0 | J25: =IFERROR(D25/サマリー!$B$7,0) -> 0 | K25: =IFERROR(E25/サマリー!$B$7,0) -> 0
A26: 24 | B26: =サマリー!$B$14-WEEKDAY(サマリー!$B$14,2)+1+(24-1)*7 -> 46300 | C26: =B26+6 -> 46306 | D26: =SUMIFS(受注ログ!$C$4:$C$5000,受注ログ!$B$4:$B$5000,">="&B26,受注ログ!$B$4:$B$5000,"<="&C26) -> 0 | E26: =SUMIFS(受注ログ!$D$4:$D$5000,受注ログ!$B$4:$B$5000,">="&B26,受注ログ!$B$4:$B$5000,"<="&C26) -> 0 | F26: =D26+E26 -> 0 | G26: =サマリー!$B$15 -> 500000 | H26: =F26-G26 -> -500000 | I26: =IFERROR(F26/G26,0) -> 0 | J26: =IFERROR(D26/サマリー!$B$7,0) -> 0 | K26: =IFERROR(E26/サマリー!$B$7,0) -> 0
A27: 25 | B27: =サマリー!$B$14-WEEKDAY(サマリー!$B$14,2)+1+(25-1)*7 -> 46307 | C27: =B27+6 -> 46313 | D27: =SUMIFS(受注ログ!$C$4:$C$5000,受注ログ!$B$4:$B$5000,">="&B27,受注ログ!$B$4:$B$5000,"<="&C27) -> 0 | E27: =SUMIFS(受注ログ!$D$4:$D$5000,受注ログ!$B$4:$B$5000,">="&B27,受注ログ!$B$4:$B$5000,"<="&C27) -> 0 | F27: =D27+E27 -> 0 | G27: =サマリー!$B$15 -> 500000 | H27: =F27-G27 -> -500000 | I27: =IFERROR(F27/G27,0) -> 0 | J27: =IFERROR(D27/サマリー!$B$7,0) -> 0 | K27: =IFERROR(E27/サマリー!$B$7,0) -> 0
A28: 26 | B28: =サマリー!$B$14-WEEKDAY(サマリー!$B$14,2)+1+(26-1)*7 -> 46314 | C28: =B28+6 -> 46320 | D28: =SUMIFS(受注ログ!$C$4:$C$5000,受注ログ!$B$4:$B$5000,">="&B28,受注ログ!$B$4:$B$5000,"<="&C28) -> 0 | E28: =SUMIFS(受注ログ!$D$4:$D$5000,受注ログ!$B$4:$B$5000,">="&B28,受注ログ!$B$4:$B$5000,"<="&C28) -> 0 | F28: =D28+E28 -> 0 | G28: =サマリー!$B$15 -> 500000 | H28: =F28-G28 -> -500000 | I28: =IFERROR(F28/G28,0) -> 0 | J28: =IFERROR(D28/サマリー!$B$7,0) -> 0 | K28: =IFERROR(E28/サマリー!$B$7,0) -> 0
A29: 27 | B29: =サマリー!$B$14-WEEKDAY(サマリー!$B$14,2)+1+(27-1)*7 -> 46321 | C29: =B29+6 -> 46327 | D29: =SUMIFS(受注ログ!$C$4:$C$5000,受注ログ!$B$4:$B$5000,">="&B29,受注ログ!$B$4:$B$5000,"<="&C29) -> 0 | E29: =SUMIFS(受注ログ!$D$4:$D$5000,受注ログ!$B$4:$B$5000,">="&B29,受注ログ!$B$4:$B$5000,"<="&C29) -> 0 | F29: =D29+E29 -> 0 | G29: =サマリー!$B$15 -> 500000 | H29: =F29-G29 -> -500000 | I29: =IFERROR(F29/G29,0) -> 0 | J29: =IFERROR(D29/サマリー!$B$7,0) -> 0 | K29: =IFERROR(E29/サマリー!$B$7,0) -> 0
A30: 28 | B30: =サマリー!$B$14-WEEKDAY(サマリー!$B$14,2)+1+(28-1)*7 -> 46328 | C30: =B30+6 -> 46334 | D30: =SUMIFS(受注ログ!$C$4:$C$5000,受注ログ!$B$4:$B$5000,">="&B30,受注ログ!$B$4:$B$5000,"<="&C30) -> 0 | E30: =SUMIFS(受注ログ!$D$4:$D$5000,受注ログ!$B$4:$B$5000,">="&B30,受注ログ!$B$4:$B$5000,"<="&C30) -> 0 | F30: =D30+E30 -> 0 | G30: =サマリー!$B$15 -> 500000 | H30: =F30-G30 -> -500000 | I30: =IFERROR(F30/G30,0) -> 0 | J30: =IFERROR(D30/サマリー!$B$7,0) -> 0 | K30: =IFERROR(E30/サマリー!$B$7,0) -> 0
A31: 29 | B31: =サマリー!$B$14-WEEKDAY(サマリー!$B$14,2)+1+(29-1)*7 -> 46335 | C31: =B31+6 -> 46341 | D31: =SUMIFS(受注ログ!$C$4:$C$5000,受注ログ!$B$4:$B$5000,">="&B31,受注ログ!$B$4:$B$5000,"<="&C31) -> 0 | E31: =SUMIFS(受注ログ!$D$4:$D$5000,受注ログ!$B$4:$B$5000,">="&B31,受注ログ!$B$4:$B$5000,"<="&C31) -> 0 | F31: =D31+E31 -> 0 | G31: =サマリー!$B$15 -> 500000 | H31: =F31-G31 -> -500000 | I31: =IFERROR(F31/G31,0) -> 0 | J31: =IFERROR(D31/サマリー!$B$7,0) -> 0 | K31: =IFERROR(E31/サマリー!$B$7,0) -> 0
A32: 30 | B32: =サマリー!$B$14-WEEKDAY(サマリー!$B$14,2)+1+(30-1)*7 -> 46342 | C32: =B32+6 -> 46348 | D32: =SUMIFS(受注ログ!$C$4:$C$5000,受注ログ!$B$4:$B$5000,">="&B32,受注ログ!$B$4:$B$5000,"<="&C32) -> 0 | E32: =SUMIFS(受注ログ!$D$4:$D$5000,受注ログ!$B$4:$B$5000,">="&B32,受注ログ!$B$4:$B$5000,"<="&C32) -> 0 | F32: =D32+E32 -> 0 | G32: =サマリー!$B$15 -> 500000 | H32: =F32-G32 -> -500000 | I32: =IFERROR(F32/G32,0) -> 0 | J32: =IFERROR(D32/サマリー!$B$7,0) -> 0 | K32: =IFERROR(E32/サマリー!$B$7,0) -> 0
A33: 31 | B33: =サマリー!$B$14-WEEKDAY(サマリー!$B$14,2)+1+(31-1)*7 -> 46349 | C33: =B33+6 -> 46355 | D33: =SUMIFS(受注ログ!$C$4:$C$5000,受注ログ!$B$4:$B$5000,">="&B33,受注ログ!$B$4:$B$5000,"<="&C33) -> 0 | E33: =SUMIFS(受注ログ!$D$4:$D$5000,受注ログ!$B$4:$B$5000,">="&B33,受注ログ!$B$4:$B$5000,"<="&C33) -> 0 | F33: =D33+E33 -> 0 | G33: =サマリー!$B$15 -> 500000 | H33: =F33-G33 -> -500000 | I33: =IFERROR(F33/G33,0) -> 0 | J33: =IFERROR(D33/サマリー!$B$7,0) -> 0 | K33: =IFERROR(E33/サマリー!$B$7,0) -> 0
A34: 32 | B34: =サマリー!$B$14-WEEKDAY(サマリー!$B$14,2)+1+(32-1)*7 -> 46356 | C34: =B34+6 -> 46362 | D34: =SUMIFS(受注ログ!$C$4:$C$5000,受注ログ!$B$4:$B$5000,">="&B34,受注ログ!$B$4:$B$5000,"<="&C34) -> 0 | E34: =SUMIFS(受注ログ!$D$4:$D$5000,受注ログ!$B$4:$B$5000,">="&B34,受注ログ!$B$4:$B$5000,"<="&C34) -> 0 | F34: =D34+E34 -> 0 | G34: =サマリー!$B$15 -> 500000 | H34: =F34-G34 -> -500000 | I34: =IFERROR(F34/G34,0) -> 0 | J34: =IFERROR(D34/サマリー!$B$7,0) -> 0 | K34: =IFERROR(E34/サマリー!$B$7,0) -> 0
A35: 33 | B35: =サマリー!$B$14-WEEKDAY(サマリー!$B$14,2)+1+(33-1)*7 -> 46363 | C35: =B35+6 -> 46369 | D35: =SUMIFS(受注ログ!$C$4:$C$5000,受注ログ!$B$4:$B$5000,">="&B35,受注ログ!$B$4:$B$5000,"<="&C35) -> 0 | E35: =SUMIFS(受注ログ!$D$4:$D$5000,受注ログ!$B$4:$B$5000,">="&B35,受注ログ!$B$4:$B$5000,"<="&C35) -> 0 | F35: =D35+E35 -> 0 | G35: =サマリー!$B$15 -> 500000 | H35: =F35-G35 -> -500000 | I35: =IFERROR(F35/G35,0) -> 0 | J35: =IFERROR(D35/サマリー!$B$7,0) -> 0 | K35: =IFERROR(E35/サマリー!$B$7,0) -> 0
A36: 34 | B36: =サマリー!$B$14-WEEKDAY(サマリー!$B$14,2)+1+(34-1)*7 -> 46370 | C36: =B36+6 -> 46376 | D36: =SUMIFS(受注ログ!$C$4:$C$5000,受注ログ!$B$4:$B$5000,">="&B36,受注ログ!$B$4:$B$5000,"<="&C36) -> 0 | E36: =SUMIFS(受注ログ!$D$4:$D$5000,受注ログ!$B$4:$B$5000,">="&B36,受注ログ!$B$4:$B$5000,"<="&C36) -> 0 | F36: =D36+E36 -> 0 | G36: =サマリー!$B$15 -> 500000 | H36: =F36-G36 -> -500000 | I36: =IFERROR(F36/G36,0) -> 0 | J36: =IFERROR(D36/サマリー!$B$7,0) -> 0 | K36: =IFERROR(E36/サマリー!$B$7,0) -> 0
A37: 35 | B37: =サマリー!$B$14-WEEKDAY(サマリー!$B$14,2)+1+(35-1)*7 -> 46377 | C37: =B37+6 -> 46383 | D37: =SUMIFS(受注ログ!$C$4:$C$5000,受注ログ!$B$4:$B$5000,">="&B37,受注ログ!$B$4:$B$5000,"<="&C37) -> 0 | E37: =SUMIFS(受注ログ!$D$4:$D$5000,受注ログ!$B$4:$B$5000,">="&B37,受注ログ!$B$4:$B$5000,"<="&C37) -> 0 | F37: =D37+E37 -> 0 | G37: =サマリー!$B$15 -> 500000 | H37: =F37-G37 -> -500000 | I37: =IFERROR(F37/G37,0) -> 0 | J37: =IFERROR(D37/サマリー!$B$7,0) -> 0 | K37: =IFERROR(E37/サマリー!$B$7,0) -> 0
A38: 36 | B38: =サマリー!$B$14-WEEKDAY(サマリー!$B$14,2)+1+(36-1)*7 -> 46384 | C38: =B38+6 -> 46390 | D38: =SUMIFS(受注ログ!$C$4:$C$5000,受注ログ!$B$4:$B$5000,">="&B38,受注ログ!$B$4:$B$5000,"<="&C38) -> 0 | E38: =SUMIFS(受注ログ!$D$4:$D$5000,受注ログ!$B$4:$B$5000,">="&B38,受注ログ!$B$4:$B$5000,"<="&C38) -> 0 | F38: =D38+E38 -> 0 | G38: =サマリー!$B$15 -> 500000 | H38: =F38-G38 -> -500000 | I38: =IFERROR(F38/G38,0) -> 0 | J38: =IFERROR(D38/サマリー!$B$7,0) -> 0 | K38: =IFERROR(E38/サマリー!$B$7,0) -> 0
A39: 37 | B39: =サマリー!$B$14-WEEKDAY(サマリー!$B$14,2)+1+(37-1)*7 -> 46391 | C39: =B39+6 -> 46397 | D39: =SUMIFS(受注ログ!$C$4:$C$5000,受注ログ!$B$4:$B$5000,">="&B39,受注ログ!$B$4:$B$5000,"<="&C39) -> 0 | E39: =SUMIFS(受注ログ!$D$4:$D$5000,受注ログ!$B$4:$B$5000,">="&B39,受注ログ!$B$4:$B$5000,"<="&C39) -> 0 | F39: =D39+E39 -> 0 | G39: =サマリー!$B$15 -> 500000 | H39: =F39-G39 -> -500000 | I39: =IFERROR(F39/G39,0) -> 0 | J39: =IFERROR(D39/サマリー!$B$7,0) -> 0 | K39: =IFERROR(E39/サマリー!$B$7,0) -> 0
A40: 38 | B40: =サマリー!$B$14-WEEKDAY(サマリー!$B$14,2)+1+(38-1)*7 -> 46398 | C40: =B40+6 -> 46404 | D40: =SUMIFS(受注ログ!$C$4:$C$5000,受注ログ!$B$4:$B$5000,">="&B40,受注ログ!$B$4:$B$5000,"<="&C40) -> 0 | E40: =SUMIFS(受注ログ!$D$4:$D$5000,受注ログ!$B$4:$B$5000,">="&B40,受注ログ!$B$4:$B$5000,"<="&C40) -> 0 | F40: =D40+E40 -> 0 | G40: =サマリー!$B$15 -> 500000 | H40: =F40-G40 -> -500000 | I40: =IFERROR(F40/G40,0) -> 0 | J40: =IFERROR(D40/サマリー!$B$7,0) -> 0 | K40: =IFERROR(E40/サマリー!$B$7,0) -> 0
...

Sheet 月次集計
A1: 月次集計（個人月予算100万円×2＝チーム200万円）
A2: 月番号 | B2: 開始日 | C2: 終了日 | D2: 小原実績 | E2: 前園実績 | F2: チーム計 | G2: チーム月予算 | H2: 差異 | I2: 達成率 | J2: 小原達成率 | K2: 前園達成率
A3: 1 | B3: =EDATE(サマリー!$B$14,1-1) -> 46143 | C3: =EOMONTH(B3,0) -> 46173 | D3: =SUMIFS(受注ログ!$C$4:$C$5000,受注ログ!$B$4:$B$5000,">="&B3,受注ログ!$B$4:$B$5000,"<="&C3) -> 0 | E3: =SUMIFS(受注ログ!$D$4:$D$5000,受注ログ!$B$4:$B$5000,">="&B3,受注ログ!$B$4:$B$5000,"<="&C3) -> 0 | F3: =D3+E3 -> 0 | G3: =サマリー!$B$16 -> 2000000 | H3: =F3-G3 -> -2000000 | I3: =IFERROR(F3/G3,0) -> 0 | J3: =IFERROR(D3/サマリー!$B$8,0) -> 0 | K3: =IFERROR(E3/サマリー!$B$8,0) -> 0
A4: 2 | B4: =EDATE(サマリー!$B$14,2-1) -> 46174 | C4: =EOMONTH(B4,0) -> 46203 | D4: =SUMIFS(受注ログ!$C$4:$C$5000,受注ログ!$B$4:$B$5000,">="&B4,受注ログ!$B$4:$B$5000,"<="&C4) -> 91004 | E4: =SUMIFS(受注ログ!$D$4:$D$5000,受注ログ!$B$4:$B$5000,">="&B4,受注ログ!$B$4:$B$5000,"<="&C4) -> 27872 | F4: =D4+E4 -> 118876 | G4: =サマリー!$B$16 -> 2000000 | H4: =F4-G4 -> -1881124 | I4: =IFERROR(F4/G4,0) -> 0.059438 | J4: =IFERROR(D4/サマリー!$B$8,0) -> 0.091004 | K4: =IFERROR(E4/サマリー!$B$8,0) -> 0.027872
A5: 3 | B5: =EDATE(サマリー!$B$14,3-1) -> 46204 | C5: =EOMONTH(B5,0) -> 46234 | D5: =SUMIFS(受注ログ!$C$4:$C$5000,受注ログ!$B$4:$B$5000,">="&B5,受注ログ!$B$4:$B$5000,"<="&C5) -> 1056778 | E5: =SUMIFS(受注ログ!$D$4:$D$5000,受注ログ!$B$4:$B$5000,">="&B5,受注ログ!$B$4:$B$5000,"<="&C5) -> 639108 | F5: =D5+E5 -> 1695886 | G5: =サマリー!$B$16 -> 2000000 | H5: =F5-G5 -> -304114 | I5: =IFERROR(F5/G5,0) -> 0.847943 | J5: =IFERROR(D5/サマリー!$B$8,0) -> 1.056778 | K5: =IFERROR(E5/サマリー!$B$8,0) -> 0.639108
A6: 4 | B6: =EDATE(サマリー!$B$14,4-1) -> 46235 | C6: =EOMONTH(B6,0) -> 46265 | D6: =SUMIFS(受注ログ!$C$4:$C$5000,受注ログ!$B$4:$B$5000,">="&B6,受注ログ!$B$4:$B$5000,"<="&C6) -> 1102988 | E6: =SUMIFS(受注ログ!$D$4:$D$5000,受注ログ!$B$4:$B$5000,">="&B6,受注ログ!$B$4:$B$5000,"<="&C6) -> 957083 | F6: =D6+E6 -> 2060071 | G6: =サマリー!$B$16 -> 2000000 | H6: =F6-G6 -> 60071 | I6: =IFERROR(F6/G6,0) -> 1.0300355 | J6: =IFERROR(D6/サマリー!$B$8,0) -> 1.102988 | K6: =IFERROR(E6/サマリー!$B$8,0) -> 0.957083
A7: 5 | B7: =EDATE(サマリー!$B$14,5-1) -> 46266 | C7: =EOMONTH(B7,0) -> 46295 | D7: =SUMIFS(受注ログ!$C$4:$C$5000,受注ログ!$B$4:$B$5000,">="&B7,受注ログ!$B$4:$B$5000,"<="&C7) -> 1229092 | E7: =SUMIFS(受注ログ!$D$4:$D$5000,受注ログ!$B$4:$B$5000,">="&B7,受注ログ!$B$4:$B$5000,"<="&C7) -> 541948 | F7: =D7+E7 -> 1771040 | G7: =サマリー!$B$16 -> 2000000 | H7: =F7-G7 -> -228960 | I7: =IFERROR(F7/G7,0) -> 0.88552 | J7: =IFERROR(D7/サマリー!$B$8,0) -> 1.229092 | K7: =IFERROR(E7/サマリー!$B$8,0) -> 0.541948
A8: 6 | B8: =EDATE(サマリー!$B$14,6-1) -> 46296 | C8: =EOMONTH(B8,0) -> 46326 | D8: =SUMIFS(受注ログ!$C$4:$C$5000,受注ログ!$B$4:$B$5000,">="&B8,受注ログ!$B$4:$B$5000,"<="&C8) -> 0 | E8: =SUMIFS(受注ログ!$D$4:$D$5000,受注ログ!$B$4:$B$5000,">="&B8,受注ログ!$B$4:$B$5000,"<="&C8) -> 0 | F8: =D8+E8 -> 0 | G8: =サマリー!$B$16 -> 2000000 | H8: =F8-G8 -> -2000000 | I8: =IFERROR(F8/G8,0) -> 0 | J8: =IFERROR(D8/サマリー!$B$8,0) -> 0 | K8: =IFERROR(E8/サマリー!$B$8,0) -> 0
A9: 7 | B9: =EDATE(サマリー!$B$14,7-1) -> 46327 | C9: =EOMONTH(B9,0) -> 46356 | D9: =SUMIFS(受注ログ!$C$4:$C$5000,受注ログ!$B$4:$B$5000,">="&B9,受注ログ!$B$4:$B$5000,"<="&C9) -> 0 | E9: =SUMIFS(受注ログ!$D$4:$D$5000,受注ログ!$B$4:$B$5000,">="&B9,受注ログ!$B$4:$B$5000,"<="&C9) -> 0 | F9: =D9+E9 -> 0 | G9: =サマリー!$B$16 -> 2000000 | H9: =F9-G9 -> -2000000 | I9: =IFERROR(F9/G9,0) -> 0 | J9: =IFERROR(D9/サマリー!$B$8,0) -> 0 | K9: =IFERROR(E9/サマリー!$B$8,0) -> 0
A10: 8 | B10: =EDATE(サマリー!$B$14,8-1) -> 46357 | C10: =EOMONTH(B10,0) -> 46387 | D10: =SUMIFS(受注ログ!$C$4:$C$5000,受注ログ!$B$4:$B$5000,">="&B10,受注ログ!$B$4:$B$5000,"<="&C10) -> 0 | E10: =SUMIFS(受注ログ!$D$4:$D$5000,受注ログ!$B$4:$B$5000,">="&B10,受注ログ!$B$4:$B$5000,"<="&C10) -> 0 | F10: =D10+E10 -> 0 | G10: =サマリー!$B$16 -> 2000000 | H10: =F10-G10 -> -2000000 | I10: =IFERROR(F10/G10,0) -> 0 | J10: =IFERROR(D10/サマリー!$B$8,0) -> 0 | K10: =IFERROR(E10/サマリー!$B$8,0) -> 0
A11: 9 | B11: =EDATE(サマリー!$B$14,9-1) -> 46388 | C11: =EOMONTH(B11,0) -> 46418 | D11: =SUMIFS(受注ログ!$C$4:$C$5000,受注ログ!$B$4:$B$5000,">="&B11,受注ログ!$B$4:$B$5000,"<="&C11) -> 0 | E11: =SUMIFS(受注ログ!$D$4:$D$5000,受注ログ!$B$4:$B$5000,">="&B11,受注ログ!$B$4:$B$5000,"<="&C11) -> 0 | F11: =D11+E11 -> 0 | G11: =サマリー!$B$16 -> 2000000 | H11: =F11-G11 -> -2000000 | I11: =IFERROR(F11/G11,0) -> 0 | J11: =IFERROR(D11/サマリー!$B$8,0) -> 0 | K11: =IFERROR(E11/サマリー!$B$8,0) -> 0
A12: 10 | B12: =EDATE(サマリー!$B$14,10-1) -> 46419 | C12: =EOMONTH(B12,0) -> 46446 | D12: =SUMIFS(受注ログ!$C$4:$C$5000,受注ログ!$B$4:$B$5000,">="&B12,受注ログ!$B$4:$B$5000,"<="&C12) -> 0 | E12: =SUMIFS(受注ログ!$D$4:$D$5000,受注ログ!$B$4:$B$5000,">="&B12,受注ログ!$B$4:$B$5000,"<="&C12) -> 0 | F12: =D12+E12 -> 0 | G12: =サマリー!$B$16 -> 2000000 | H12: =F12-G12 -> -2000000 | I12: =IFERROR(F12/G12,0) -> 0 | J12: =IFERROR(D12/サマリー!$B$8,0) -> 0 | K12: =IFERROR(E12/サマリー!$B$8,0) -> 0
A13: 11 | B13: =EDATE(サマリー!$B$14,11-1) -> 46447 | C13: =EOMONTH(B13,0) -> 46477 | D13: =SUMIFS(受注ログ!$C$4:$C$5000,受注ログ!$B$4:$B$5000,">="&B13,受注ログ!$B$4:$B$5000,"<="&C13) -> 0 | E13: =SUMIFS(受注ログ!$D$4:$D$5000,受注ログ!$B$4:$B$5000,">="&B13,受注ログ!$B$4:$B$5000,"<="&C13) -> 0 | F13: =D13+E13 -> 0 | G13: =サマリー!$B$16 -> 2000000 | H13: =F13-G13 -> -2000000 | I13: =IFERROR(F13/G13,0) -> 0 | J13: =IFERROR(D13/サマリー!$B$8,0) -> 0 | K13: =IFERROR(E13/サマリー!$B$8,0) -> 0
A14: 12 | B14: =EDATE(サマリー!$B$14,12-1) -> 46478 | C14: =EOMONTH(B14,0) -> 46507 | D14: =SUMIFS(受注ログ!$C$4:$C$5000,受注ログ!$B$4:$B$5000,">="&B14,受注ログ!$B$4:$B$5000,"<="&C14) -> 0 | E14: =SUMIFS(受注ログ!$D$4:$D$5000,受注ログ!$B$4:$B$5000,">="&B14,受注ログ!$B$4:$B$5000,"<="&C14) -> 0 | F14: =D14+E14 -> 0 | G14: =サマリー!$B$16 -> 2000000 | H14: =F14-G14 -> -2000000 | I14: =IFERROR(F14/G14,0) -> 0 | J14: =IFERROR(D14/サマリー!$B$8,0) -> 0 | K14: =IFERROR(E14/サマリー!$B$8,0) -> 0
A15: 13 | B15: =EDATE(サマリー!$B$14,13-1) -> 46508 | C15: =EOMONTH(B15,0) -> 46538 | D15: =SUMIFS(受注ログ!$C$4:$C$5000,受注ログ!$B$4:$B$5000,">="&B15,受注ログ!$B$4:$B$5000,"<="&C15) -> 0 | E15: =SUMIFS(受注ログ!$D$4:$D$5000,受注ログ!$B$4:$B$5000,">="&B15,受注ログ!$B$4:$B$5000,"<="&C15) -> 0 | F15: =D15+E15 -> 0 | G15: =サマリー!$B$16 -> 2000000 | H15: =F15-G15 -> -2000000 | I15: =IFERROR(F15/G15,0) -> 0 | J15: =IFERROR(D15/サマリー!$B$8,0) -> 0 | K15: =IFERROR(E15/サマリー!$B$8,0) -> 0

Sheet 半期年間集計
A1: 半期・年間集計（予算はチーム月予算からの参考換算）
A2: 区分 | B2: 開始日 | C2: 終了日 | D2: 小原実績 | E2: 前園実績 | F2: チーム計 | G2: 参考予算 | H2: 差異 | I2: 達成率
A3: 上半期 | B3: =サマリー!$B$14 -> 46143 | C3: =EOMONTH(サマリー!$B$14,5) -> 46326 | D3: =SUMIFS(受注ログ!$C$4:$C$5000,受注ログ!$B$4:$B$5000,">="&B3,受注ログ!$B$4:$B$5000,"<="&C3) -> 3479862 | E3: =SUMIFS(受注ログ!$D$4:$D$5000,受注ログ!$B$4:$B$5000,">="&B3,受注ログ!$B$4:$B$5000,"<="&C3) -> 2166011 | F3: =D3+E3 -> 5645873 | G3: =サマリー!$B$17 -> 12000000 | H3: =F3-G3 -> -6354127 | I3: =IFERROR(F3/G3,0) -> 0.47048942
A4: 下半期 | B4: =EDATE(サマリー!$B$14,6) -> 46327 | C4: =EOMONTH(サマリー!$B$14,11) -> 46507 | D4: =SUMIFS(受注ログ!$C$4:$C$5000,受注ログ!$B$4:$B$5000,">="&B4,受注ログ!$B$4:$B$5000,"<="&C4) -> 0 | E4: =SUMIFS(受注ログ!$D$4:$D$5000,受注ログ!$B$4:$B$5000,">="&B4,受注ログ!$B$4:$B$5000,"<="&C4) -> 0 | F4: =D4+E4 -> 0 | G4: =サマリー!$B$17 -> 12000000 | H4: =F4-G4 -> -12000000 | I4: =IFERROR(F4/G4,0) -> 0
A5: 年間 | B5: =サマリー!$B$14 -> 46143 | C5: =EOMONTH(サマリー!$B$14,11) -> 46507 | D5: =SUMIFS(受注ログ!$C$4:$C$5000,受注ログ!$B$4:$B$5000,">="&B5,受注ログ!$B$4:$B$5000,"<="&C5) -> 3479862 | E5: =SUMIFS(受注ログ!$D$4:$D$5000,受注ログ!$B$4:$B$5000,">="&B5,受注ログ!$B$4:$B$5000,"<="&C5) -> 2166011 | F5: =D5+E5 -> 5645873 | G5: =サマリー!$B$18 -> 24000000 | H5: =F5-G5 -> -18354127 | I5: =IFERROR(F5/G5,0) -> 0.23524471

Sheet 印刷用
A1: 店舗別 売上状況
A2: ="（"&TEXT(サマリー!$B$6,"yyyy/m/d")&" 時点）" -> （2026/9/24 時点）
A4: ■ 店舗別 売上（今週・今月）
A5: 店舗 | B5: 今週 | C5: 今月
A6: 大洲店 | B6: =SUMIFS(受注ログ!$L$6:$L$205,受注ログ!$B$6:$B$205,">="&INDEX(週次集計!$B$3:$B$56,サマリー!$B$20),受注ログ!$B$6:$B$205,"<="&INDEX(週次集計!$C$3:$C$56,サマリー!$B$20)) -> 0 | C6: =サマリー!D53 -> 0
A7: 西予店 | B7: =SUMIFS(受注ログ!$M$6:$M$205,受注ログ!$B$6:$B$205,">="&INDEX(週次集計!$B$3:$B$56,サマリー!$B$20),受注ログ!$B$6:$B$205,"<="&INDEX(週次集計!$C$3:$C$56,サマリー!$B$20)) -> 0 | C7: =サマリー!D54 -> 0
A8: 宇和島店 | B8: =SUMIFS(受注ログ!$N$6:$N$205,受注ログ!$B$6:$B$205,">="&INDEX(週次集計!$B$3:$B$56,サマリー!$B$20),受注ログ!$B$6:$B$205,"<="&INDEX(週次集計!$C$3:$C$56,サマリー!$B$20)) -> 0 | C8: =サマリー!D55 -> 26974
A9: 新居浜店 | B9: =SUMIFS(受注ログ!$V$6:$V$205,受注ログ!$B$6:$B$205,">="&INDEX(週次集計!$B$3:$B$56,サマリー!$B$20),受注ログ!$B$6:$B$205,"<="&INDEX(週次集計!$C$3:$C$56,サマリー!$B$20)) -> 0 | C9: =サマリー!D56 -> 46613
A11: ※ 個人の実績・予算は含めていません（店舗別の売上のみ表示）。
A12: ※「印刷用」シートを開いた状態でCtrl+P（印刷）を押すと、この内容だけがA4一枚で印刷されます。
